{
 "cells": [
  {
   "cell_type": "code",
   "execution_count": 1,
   "metadata": {},
   "outputs": [],
   "source": [
    "import pandas as pd\n",
    "import numpy as np"
   ]
  },
  {
   "cell_type": "code",
   "execution_count": 2,
   "metadata": {},
   "outputs": [],
   "source": [
    "df = pd.read_csv('./cl2.csv')"
   ]
  },
  {
   "cell_type": "code",
   "execution_count": 3,
   "metadata": {},
   "outputs": [
    {
     "name": "stdout",
     "output_type": "stream",
     "text": [
      "Shape of training set: (339, 31)\n",
      "Shape of test set: (85, 31)\n"
     ]
    }
   ],
   "source": [
    "from sklearn.model_selection import train_test_split\n",
    "\n",
    "# splitting data\n",
    "X_train, X_test, y_train, y_test = train_test_split(\n",
    "                df.drop('diagnosis', axis=1),\n",
    "                df['diagnosis'],\n",
    "                test_size=0.2,\n",
    "                random_state=42)\n",
    "\n",
    "print(\"Shape of training set:\", X_train.shape)\n",
    "print(\"Shape of test set:\", X_test.shape)"
   ]
  },
  {
   "cell_type": "code",
   "execution_count": 45,
   "metadata": {},
   "outputs": [
    {
     "name": "stderr",
     "output_type": "stream",
     "text": [
      "INFO flwr 2024-05-11 18:32:44,878 | 3672777454.py:44 | Reformatting data...\n",
      "INFO flwr 2024-05-11 18:32:44,881 | grpc.py:52 | Opened insecure gRPC connection (no certificates were passed)\n",
      "DEBUG flwr 2024-05-11 18:32:44,895 | connection.py:55 | ChannelConnectivity.IDLE\n",
      "DEBUG flwr 2024-05-11 18:32:44,898 | connection.py:55 | ChannelConnectivity.READY\n",
      "INFO flwr 2024-05-11 18:32:44,900 | 3672777454.py:100 | Start training at round 1\n"
     ]
    },
    {
     "name": "stdout",
     "output_type": "stream",
     "text": [
      "[0]\tvalidate-logloss:0.44173\ttrain-logloss:0.38855\n",
      "Confusion Matrix: \n",
      " [[52  2]\n",
      " [ 5 26]]\n",
      "              precision    recall  f1-score   support\n",
      "\n",
      "           0       0.91      0.96      0.94        54\n",
      "           1       0.93      0.84      0.88        31\n",
      "\n",
      "    accuracy                           0.92        85\n",
      "   macro avg       0.92      0.90      0.91        85\n",
      "weighted avg       0.92      0.92      0.92        85\n",
      "\n",
      "Confusion Matrix: \n",
      " [[49  5]\n",
      " [ 0 31]]\n",
      "              precision    recall  f1-score   support\n",
      "\n",
      "           0       1.00      0.91      0.95        54\n",
      "           1       0.86      1.00      0.93        31\n",
      "\n",
      "    accuracy                           0.94        85\n",
      "   macro avg       0.93      0.95      0.94        85\n",
      "weighted avg       0.95      0.94      0.94        85\n",
      "\n",
      "Confusion Matrix: \n",
      " [[50  4]\n",
      " [ 0 31]]\n",
      "              precision    recall  f1-score   support\n",
      "\n",
      "           0       1.00      0.93      0.96        54\n",
      "           1       0.89      1.00      0.94        31\n",
      "\n",
      "    accuracy                           0.95        85\n",
      "   macro avg       0.94      0.96      0.95        85\n",
      "weighted avg       0.96      0.95      0.95        85\n",
      "\n",
      "Confusion Matrix: \n",
      " [[50  4]\n",
      " [ 0 31]]\n",
      "              precision    recall  f1-score   support\n",
      "\n",
      "           0       1.00      0.93      0.96        54\n",
      "           1       0.89      1.00      0.94        31\n",
      "\n",
      "    accuracy                           0.95        85\n",
      "   macro avg       0.94      0.96      0.95        85\n",
      "weighted avg       0.96      0.95      0.95        85\n",
      "\n",
      "Confusion Matrix: \n",
      " [[51  3]\n",
      " [ 0 31]]\n",
      "              precision    recall  f1-score   support\n",
      "\n",
      "           0       1.00      0.94      0.97        54\n",
      "           1       0.91      1.00      0.95        31\n",
      "\n",
      "    accuracy                           0.96        85\n",
      "   macro avg       0.96      0.97      0.96        85\n",
      "weighted avg       0.97      0.96      0.97        85\n",
      "\n",
      "Confusion Matrix: \n",
      " [[50  4]\n",
      " [ 0 31]]\n",
      "              precision    recall  f1-score   support\n",
      "\n",
      "           0       1.00      0.93      0.96        54\n",
      "           1       0.89      1.00      0.94        31\n",
      "\n",
      "    accuracy                           0.95        85\n",
      "   macro avg       0.94      0.96      0.95        85\n",
      "weighted avg       0.96      0.95      0.95        85\n",
      "\n",
      "Confusion Matrix: \n",
      " [[50  4]\n",
      " [ 0 31]]\n",
      "              precision    recall  f1-score   support\n",
      "\n",
      "           0       1.00      0.93      0.96        54\n",
      "           1       0.89      1.00      0.94        31\n",
      "\n",
      "    accuracy                           0.95        85\n",
      "   macro avg       0.94      0.96      0.95        85\n",
      "weighted avg       0.96      0.95      0.95        85\n",
      "\n",
      "Confusion Matrix: \n",
      " [[50  4]\n",
      " [ 0 31]]\n",
      "              precision    recall  f1-score   support\n",
      "\n",
      "           0       1.00      0.93      0.96        54\n",
      "           1       0.89      1.00      0.94        31\n",
      "\n",
      "    accuracy                           0.95        85\n",
      "   macro avg       0.94      0.96      0.95        85\n",
      "weighted avg       0.96      0.95      0.95        85\n",
      "\n",
      "Confusion Matrix: \n",
      " [[52  2]\n",
      " [ 0 31]]\n",
      "              precision    recall  f1-score   support\n",
      "\n",
      "           0       1.00      0.96      0.98        54\n",
      "           1       0.94      1.00      0.97        31\n",
      "\n",
      "    accuracy                           0.98        85\n",
      "   macro avg       0.97      0.98      0.97        85\n",
      "weighted avg       0.98      0.98      0.98        85\n",
      "\n",
      "Confusion Matrix: \n",
      " [[53  1]\n",
      " [ 0 31]]\n",
      "              precision    recall  f1-score   support\n",
      "\n",
      "           0       1.00      0.98      0.99        54\n",
      "           1       0.97      1.00      0.98        31\n",
      "\n",
      "    accuracy                           0.99        85\n",
      "   macro avg       0.98      0.99      0.99        85\n",
      "weighted avg       0.99      0.99      0.99        85\n",
      "\n",
      "Confusion Matrix: \n",
      " [[51  3]\n",
      " [ 0 31]]\n",
      "              precision    recall  f1-score   support\n",
      "\n",
      "           0       1.00      0.94      0.97        54\n",
      "           1       0.91      1.00      0.95        31\n",
      "\n",
      "    accuracy                           0.96        85\n",
      "   macro avg       0.96      0.97      0.96        85\n",
      "weighted avg       0.97      0.96      0.97        85\n",
      "\n",
      "Confusion Matrix: \n",
      " [[52  2]\n",
      " [ 0 31]]\n",
      "              precision    recall  f1-score   support\n",
      "\n",
      "           0       1.00      0.96      0.98        54\n",
      "           1       0.94      1.00      0.97        31\n",
      "\n",
      "    accuracy                           0.98        85\n",
      "   macro avg       0.97      0.98      0.97        85\n",
      "weighted avg       0.98      0.98      0.98        85\n",
      "\n",
      "Confusion Matrix: \n",
      " [[52  2]\n",
      " [ 0 31]]\n",
      "              precision    recall  f1-score   support\n",
      "\n",
      "           0       1.00      0.96      0.98        54\n",
      "           1       0.94      1.00      0.97        31\n",
      "\n",
      "    accuracy                           0.98        85\n",
      "   macro avg       0.97      0.98      0.97        85\n",
      "weighted avg       0.98      0.98      0.98        85\n",
      "\n",
      "Confusion Matrix: \n",
      " [[52  2]\n",
      " [ 0 31]]\n",
      "              precision    recall  f1-score   support\n",
      "\n",
      "           0       1.00      0.96      0.98        54\n",
      "           1       0.94      1.00      0.97        31\n",
      "\n",
      "    accuracy                           0.98        85\n",
      "   macro avg       0.97      0.98      0.97        85\n",
      "weighted avg       0.98      0.98      0.98        85\n",
      "\n",
      "Confusion Matrix: \n",
      " [[51  3]\n",
      " [ 0 31]]\n",
      "              precision    recall  f1-score   support\n",
      "\n",
      "           0       1.00      0.94      0.97        54\n",
      "           1       0.91      1.00      0.95        31\n",
      "\n",
      "    accuracy                           0.96        85\n",
      "   macro avg       0.96      0.97      0.96        85\n",
      "weighted avg       0.97      0.96      0.97        85\n",
      "\n",
      "Confusion Matrix: \n",
      " [[52  2]\n",
      " [ 0 31]]\n",
      "              precision    recall  f1-score   support\n",
      "\n",
      "           0       1.00      0.96      0.98        54\n",
      "           1       0.94      1.00      0.97        31\n",
      "\n",
      "    accuracy                           0.98        85\n",
      "   macro avg       0.97      0.98      0.97        85\n",
      "weighted avg       0.98      0.98      0.98        85\n",
      "\n",
      "Confusion Matrix: \n",
      " [[52  2]\n",
      " [ 0 31]]\n",
      "              precision    recall  f1-score   support\n",
      "\n",
      "           0       1.00      0.96      0.98        54\n",
      "           1       0.94      1.00      0.97        31\n",
      "\n",
      "    accuracy                           0.98        85\n",
      "   macro avg       0.97      0.98      0.97        85\n",
      "weighted avg       0.98      0.98      0.98        85\n",
      "\n",
      "Confusion Matrix: \n",
      " [[52  2]\n",
      " [ 0 31]]\n",
      "              precision    recall  f1-score   support\n",
      "\n",
      "           0       1.00      0.96      0.98        54\n",
      "           1       0.94      1.00      0.97        31\n",
      "\n",
      "    accuracy                           0.98        85\n",
      "   macro avg       0.97      0.98      0.97        85\n",
      "weighted avg       0.98      0.98      0.98        85\n",
      "\n",
      "Confusion Matrix: \n",
      " [[52  2]\n",
      " [ 0 31]]\n",
      "              precision    recall  f1-score   support\n",
      "\n",
      "           0       1.00      0.96      0.98        54\n",
      "           1       0.94      1.00      0.97        31\n",
      "\n",
      "    accuracy                           0.98        85\n",
      "   macro avg       0.97      0.98      0.97        85\n",
      "weighted avg       0.98      0.98      0.98        85\n",
      "\n",
      "Confusion Matrix: \n",
      " [[52  2]\n",
      " [ 0 31]]\n",
      "              precision    recall  f1-score   support\n",
      "\n",
      "           0       1.00      0.96      0.98        54\n",
      "           1       0.94      1.00      0.97        31\n",
      "\n",
      "    accuracy                           0.98        85\n",
      "   macro avg       0.97      0.98      0.97        85\n",
      "weighted avg       0.98      0.98      0.98        85\n",
      "\n"
     ]
    },
    {
     "name": "stderr",
     "output_type": "stream",
     "text": [
      "DEBUG flwr 2024-05-11 18:32:45,553 | connection.py:220 | gRPC channel closed\n",
      "INFO flwr 2024-05-11 18:32:45,554 | app.py:398 | Disconnect and shut down\n"
     ]
    },
    {
     "name": "stderr",
     "output_type": "stream",
     "text": [
      "Exception in callback BaseSelectorEventLoop._read_from_self()\n",
      "handle: <Handle BaseSelectorEventLoop._read_from_self()>\n",
      "Traceback (most recent call last):\n",
      "  File \"c:\\Users\\fafaf\\anaconda3\\envs\\tf\\lib\\asyncio\\events.py\", line 80, in _run\n",
      "    self._context.run(self._callback, *self._args)\n",
      "  File \"c:\\Users\\fafaf\\anaconda3\\envs\\tf\\lib\\asyncio\\selector_events.py\", line 115, in _read_from_self\n",
      "    data = self._ssock.recv(4096)\n",
      "ConnectionResetError: [WinError 10054] An existing connection was forcibly closed by the remote host\n",
      "Exception in callback BaseSelectorEventLoop._read_from_self()\n",
      "handle: <Handle BaseSelectorEventLoop._read_from_self()>\n",
      "Traceback (most recent call last):\n",
      "  File \"c:\\Users\\fafaf\\anaconda3\\envs\\tf\\lib\\asyncio\\events.py\", line 80, in _run\n",
      "    self._context.run(self._callback, *self._args)\n",
      "  File \"c:\\Users\\fafaf\\anaconda3\\envs\\tf\\lib\\asyncio\\selector_events.py\", line 115, in _read_from_self\n",
      "    data = self._ssock.recv(4096)\n",
      "ConnectionResetError: [WinError 10054] An existing connection was forcibly closed by the remote host\n",
      "Exception in callback BaseSelectorEventLoop._read_from_self()\n",
      "handle: <Handle BaseSelectorEventLoop._read_from_self()>\n",
      "Traceback (most recent call last):\n",
      "  File \"c:\\Users\\fafaf\\anaconda3\\envs\\tf\\lib\\asyncio\\events.py\", line 80, in _run\n",
      "    self._context.run(self._callback, *self._args)\n",
      "  File \"c:\\Users\\fafaf\\anaconda3\\envs\\tf\\lib\\asyncio\\selector_events.py\", line 115, in _read_from_self\n",
      "    data = self._ssock.recv(4096)\n",
      "ConnectionResetError: [WinError 10054] An existing connection was forcibly closed by the remote host\n",
      "Exception in callback BaseSelectorEventLoop._read_from_self()\n",
      "handle: <Handle BaseSelectorEventLoop._read_from_self()>\n",
      "Traceback (most recent call last):\n",
      "  File \"c:\\Users\\fafaf\\anaconda3\\envs\\tf\\lib\\asyncio\\events.py\", line 80, in _run\n",
      "    self._context.run(self._callback, *self._args)\n",
      "  File \"c:\\Users\\fafaf\\anaconda3\\envs\\tf\\lib\\asyncio\\selector_events.py\", line 115, in _read_from_self\n",
      "    data = self._ssock.recv(4096)\n",
      "ConnectionResetError: [WinError 10054] An existing connection was forcibly closed by the remote host\n",
      "Exception in callback BaseSelectorEventLoop._read_from_self()\n",
      "handle: <Handle BaseSelectorEventLoop._read_from_self()>\n",
      "Traceback (most recent call last):\n",
      "  File \"c:\\Users\\fafaf\\anaconda3\\envs\\tf\\lib\\asyncio\\events.py\", line 80, in _run\n",
      "    self._context.run(self._callback, *self._args)\n",
      "  File \"c:\\Users\\fafaf\\anaconda3\\envs\\tf\\lib\\asyncio\\selector_events.py\", line 115, in _read_from_self\n",
      "    data = self._ssock.recv(4096)\n",
      "ConnectionResetError: [WinError 10054] An existing connection was forcibly closed by the remote host\n",
      "Exception in callback BaseSelectorEventLoop._read_from_self()\n",
      "handle: <Handle BaseSelectorEventLoop._read_from_self()>\n",
      "Traceback (most recent call last):\n",
      "  File \"c:\\Users\\fafaf\\anaconda3\\envs\\tf\\lib\\asyncio\\events.py\", line 80, in _run\n",
      "    self._context.run(self._callback, *self._args)\n",
      "  File \"c:\\Users\\fafaf\\anaconda3\\envs\\tf\\lib\\asyncio\\selector_events.py\", line 115, in _read_from_self\n",
      "    data = self._ssock.recv(4096)\n",
      "ConnectionResetError: [WinError 10054] An existing connection was forcibly closed by the remote host\n",
      "Exception in callback BaseSelectorEventLoop._read_from_self()\n",
      "handle: <Handle BaseSelectorEventLoop._read_from_self()>\n",
      "Traceback (most recent call last):\n",
      "  File \"c:\\Users\\fafaf\\anaconda3\\envs\\tf\\lib\\asyncio\\events.py\", line 80, in _run\n",
      "    self._context.run(self._callback, *self._args)\n",
      "  File \"c:\\Users\\fafaf\\anaconda3\\envs\\tf\\lib\\asyncio\\selector_events.py\", line 115, in _read_from_self\n",
      "    data = self._ssock.recv(4096)\n",
      "ConnectionResetError: [WinError 10054] An existing connection was forcibly closed by the remote host\n",
      "Exception in callback BaseSelectorEventLoop._read_from_self()\n",
      "handle: <Handle BaseSelectorEventLoop._read_from_self()>\n",
      "Traceback (most recent call last):\n",
      "  File \"c:\\Users\\fafaf\\anaconda3\\envs\\tf\\lib\\asyncio\\events.py\", line 80, in _run\n",
      "    self._context.run(self._callback, *self._args)\n",
      "  File \"c:\\Users\\fafaf\\anaconda3\\envs\\tf\\lib\\asyncio\\selector_events.py\", line 115, in _read_from_self\n",
      "    data = self._ssock.recv(4096)\n",
      "ConnectionResetError: [WinError 10054] An existing connection was forcibly closed by the remote host\n",
      "Exception in callback BaseSelectorEventLoop._read_from_self()\n",
      "handle: <Handle BaseSelectorEventLoop._read_from_self()>\n",
      "Traceback (most recent call last):\n",
      "  File \"c:\\Users\\fafaf\\anaconda3\\envs\\tf\\lib\\asyncio\\events.py\", line 80, in _run\n",
      "    self._context.run(self._callback, *self._args)\n",
      "  File \"c:\\Users\\fafaf\\anaconda3\\envs\\tf\\lib\\asyncio\\selector_events.py\", line 115, in _read_from_self\n",
      "    data = self._ssock.recv(4096)\n",
      "ConnectionResetError: [WinError 10054] An existing connection was forcibly closed by the remote host\n",
      "Exception in callback BaseSelectorEventLoop._read_from_self()\n",
      "handle: <Handle BaseSelectorEventLoop._read_from_self()>\n",
      "Traceback (most recent call last):\n",
      "  File \"c:\\Users\\fafaf\\anaconda3\\envs\\tf\\lib\\asyncio\\events.py\", line 80, in _run\n",
      "    self._context.run(self._callback, *self._args)\n",
      "  File \"c:\\Users\\fafaf\\anaconda3\\envs\\tf\\lib\\asyncio\\selector_events.py\", line 115, in _read_from_self\n",
      "    data = self._ssock.recv(4096)\n",
      "ConnectionResetError: [WinError 10054] An existing connection was forcibly closed by the remote host\n",
      "Exception in callback BaseSelectorEventLoop._read_from_self()\n",
      "handle: <Handle BaseSelectorEventLoop._read_from_self()>\n",
      "Traceback (most recent call last):\n",
      "  File \"c:\\Users\\fafaf\\anaconda3\\envs\\tf\\lib\\asyncio\\events.py\", line 80, in _run\n",
      "    self._context.run(self._callback, *self._args)\n",
      "  File \"c:\\Users\\fafaf\\anaconda3\\envs\\tf\\lib\\asyncio\\selector_events.py\", line 115, in _read_from_self\n",
      "    data = self._ssock.recv(4096)\n",
      "ConnectionResetError: [WinError 10054] An existing connection was forcibly closed by the remote host\n",
      "Exception in callback BaseSelectorEventLoop._read_from_self()\n",
      "handle: <Handle BaseSelectorEventLoop._read_from_self()>\n",
      "Traceback (most recent call last):\n",
      "  File \"c:\\Users\\fafaf\\anaconda3\\envs\\tf\\lib\\asyncio\\events.py\", line 80, in _run\n",
      "    self._context.run(self._callback, *self._args)\n",
      "  File \"c:\\Users\\fafaf\\anaconda3\\envs\\tf\\lib\\asyncio\\selector_events.py\", line 115, in _read_from_self\n",
      "    data = self._ssock.recv(4096)\n",
      "ConnectionResetError: [WinError 10054] An existing connection was forcibly closed by the remote host\n",
      "Exception in callback BaseSelectorEventLoop._read_from_self()\n",
      "handle: <Handle BaseSelectorEventLoop._read_from_self()>\n",
      "Traceback (most recent call last):\n",
      "  File \"c:\\Users\\fafaf\\anaconda3\\envs\\tf\\lib\\asyncio\\events.py\", line 80, in _run\n",
      "    self._context.run(self._callback, *self._args)\n",
      "  File \"c:\\Users\\fafaf\\anaconda3\\envs\\tf\\lib\\asyncio\\selector_events.py\", line 115, in _read_from_self\n",
      "    data = self._ssock.recv(4096)\n",
      "ConnectionResetError: [WinError 10054] An existing connection was forcibly closed by the remote host\n",
      "Exception in callback BaseSelectorEventLoop._read_from_self()\n",
      "handle: <Handle BaseSelectorEventLoop._read_from_self()>\n",
      "Traceback (most recent call last):\n",
      "  File \"c:\\Users\\fafaf\\anaconda3\\envs\\tf\\lib\\asyncio\\events.py\", line 80, in _run\n",
      "    self._context.run(self._callback, *self._args)\n",
      "  File \"c:\\Users\\fafaf\\anaconda3\\envs\\tf\\lib\\asyncio\\selector_events.py\", line 115, in _read_from_self\n",
      "    data = self._ssock.recv(4096)\n",
      "ConnectionResetError: [WinError 10054] An existing connection was forcibly closed by the remote host\n",
      "Exception in callback BaseSelectorEventLoop._read_from_self()\n",
      "handle: <Handle BaseSelectorEventLoop._read_from_self()>\n",
      "Traceback (most recent call last):\n",
      "  File \"c:\\Users\\fafaf\\anaconda3\\envs\\tf\\lib\\asyncio\\events.py\", line 80, in _run\n",
      "    self._context.run(self._callback, *self._args)\n",
      "  File \"c:\\Users\\fafaf\\anaconda3\\envs\\tf\\lib\\asyncio\\selector_events.py\", line 115, in _read_from_self\n",
      "    data = self._ssock.recv(4096)\n",
      "ConnectionResetError: [WinError 10054] An existing connection was forcibly closed by the remote host\n",
      "Exception in callback BaseSelectorEventLoop._read_from_self()\n",
      "handle: <Handle BaseSelectorEventLoop._read_from_self()>\n",
      "Traceback (most recent call last):\n",
      "  File \"c:\\Users\\fafaf\\anaconda3\\envs\\tf\\lib\\asyncio\\events.py\", line 80, in _run\n",
      "    self._context.run(self._callback, *self._args)\n",
      "  File \"c:\\Users\\fafaf\\anaconda3\\envs\\tf\\lib\\asyncio\\selector_events.py\", line 115, in _read_from_self\n",
      "    data = self._ssock.recv(4096)\n",
      "ConnectionResetError: [WinError 10054] An existing connection was forcibly closed by the remote host\n",
      "Exception in callback BaseSelectorEventLoop._read_from_self()\n",
      "handle: <Handle BaseSelectorEventLoop._read_from_self()>\n",
      "Traceback (most recent call last):\n",
      "  File \"c:\\Users\\fafaf\\anaconda3\\envs\\tf\\lib\\asyncio\\events.py\", line 80, in _run\n",
      "    self._context.run(self._callback, *self._args)\n",
      "  File \"c:\\Users\\fafaf\\anaconda3\\envs\\tf\\lib\\asyncio\\selector_events.py\", line 115, in _read_from_self\n",
      "    data = self._ssock.recv(4096)\n",
      "ConnectionResetError: [WinError 10054] An existing connection was forcibly closed by the remote host\n",
      "Exception in callback BaseSelectorEventLoop._read_from_self()\n",
      "handle: <Handle BaseSelectorEventLoop._read_from_self()>\n",
      "Traceback (most recent call last):\n",
      "  File \"c:\\Users\\fafaf\\anaconda3\\envs\\tf\\lib\\asyncio\\events.py\", line 80, in _run\n",
      "    self._context.run(self._callback, *self._args)\n",
      "  File \"c:\\Users\\fafaf\\anaconda3\\envs\\tf\\lib\\asyncio\\selector_events.py\", line 115, in _read_from_self\n",
      "    data = self._ssock.recv(4096)\n",
      "ConnectionResetError: [WinError 10054] An existing connection was forcibly closed by the remote host\n",
      "Exception in callback BaseSelectorEventLoop._read_from_self()\n",
      "handle: <Handle BaseSelectorEventLoop._read_from_self()>\n",
      "Traceback (most recent call last):\n",
      "  File \"c:\\Users\\fafaf\\anaconda3\\envs\\tf\\lib\\asyncio\\events.py\", line 80, in _run\n",
      "    self._context.run(self._callback, *self._args)\n",
      "  File \"c:\\Users\\fafaf\\anaconda3\\envs\\tf\\lib\\asyncio\\selector_events.py\", line 115, in _read_from_self\n",
      "    data = self._ssock.recv(4096)\n",
      "ConnectionResetError: [WinError 10054] An existing connection was forcibly closed by the remote host\n",
      "Exception in callback BaseSelectorEventLoop._read_from_self()\n",
      "handle: <Handle BaseSelectorEventLoop._read_from_self()>\n",
      "Traceback (most recent call last):\n",
      "  File \"c:\\Users\\fafaf\\anaconda3\\envs\\tf\\lib\\asyncio\\events.py\", line 80, in _run\n",
      "    self._context.run(self._callback, *self._args)\n",
      "  File \"c:\\Users\\fafaf\\anaconda3\\envs\\tf\\lib\\asyncio\\selector_events.py\", line 115, in _read_from_self\n",
      "    data = self._ssock.recv(4096)\n",
      "ConnectionResetError: [WinError 10054] An existing connection was forcibly closed by the remote host\n",
      "Exception in callback BaseSelectorEventLoop._read_from_self()\n",
      "handle: <Handle BaseSelectorEventLoop._read_from_self()>\n",
      "Traceback (most recent call last):\n",
      "  File \"c:\\Users\\fafaf\\anaconda3\\envs\\tf\\lib\\asyncio\\events.py\", line 80, in _run\n",
      "    self._context.run(self._callback, *self._args)\n",
      "  File \"c:\\Users\\fafaf\\anaconda3\\envs\\tf\\lib\\asyncio\\selector_events.py\", line 115, in _read_from_self\n",
      "    data = self._ssock.recv(4096)\n",
      "ConnectionResetError: [WinError 10054] An existing connection was forcibly closed by the remote host\n",
      "Exception in callback BaseSelectorEventLoop._read_from_self()\n",
      "handle: <Handle BaseSelectorEventLoop._read_from_self()>\n",
      "Traceback (most recent call last):\n",
      "  File \"c:\\Users\\fafaf\\anaconda3\\envs\\tf\\lib\\asyncio\\events.py\", line 80, in _run\n",
      "    self._context.run(self._callback, *self._args)\n",
      "  File \"c:\\Users\\fafaf\\anaconda3\\envs\\tf\\lib\\asyncio\\selector_events.py\", line 115, in _read_from_self\n",
      "    data = self._ssock.recv(4096)\n",
      "ConnectionResetError: [WinError 10054] An existing connection was forcibly closed by the remote host\n",
      "Exception in callback BaseSelectorEventLoop._read_from_self()\n",
      "handle: <Handle BaseSelectorEventLoop._read_from_self()>\n",
      "Traceback (most recent call last):\n",
      "  File \"c:\\Users\\fafaf\\anaconda3\\envs\\tf\\lib\\asyncio\\events.py\", line 80, in _run\n",
      "    self._context.run(self._callback, *self._args)\n",
      "  File \"c:\\Users\\fafaf\\anaconda3\\envs\\tf\\lib\\asyncio\\selector_events.py\", line 115, in _read_from_self\n",
      "    data = self._ssock.recv(4096)\n",
      "ConnectionResetError: [WinError 10054] An existing connection was forcibly closed by the remote host\n",
      "Exception in callback BaseSelectorEventLoop._read_from_self()\n",
      "handle: <Handle BaseSelectorEventLoop._read_from_self()>\n",
      "Traceback (most recent call last):\n",
      "  File \"c:\\Users\\fafaf\\anaconda3\\envs\\tf\\lib\\asyncio\\events.py\", line 80, in _run\n",
      "    self._context.run(self._callback, *self._args)\n",
      "  File \"c:\\Users\\fafaf\\anaconda3\\envs\\tf\\lib\\asyncio\\selector_events.py\", line 115, in _read_from_self\n",
      "    data = self._ssock.recv(4096)\n",
      "ConnectionResetError: [WinError 10054] An existing connection was forcibly closed by the remote host\n",
      "Exception in callback BaseSelectorEventLoop._read_from_self()\n",
      "handle: <Handle BaseSelectorEventLoop._read_from_self()>\n",
      "Traceback (most recent call last):\n",
      "  File \"c:\\Users\\fafaf\\anaconda3\\envs\\tf\\lib\\asyncio\\events.py\", line 80, in _run\n",
      "    self._context.run(self._callback, *self._args)\n",
      "  File \"c:\\Users\\fafaf\\anaconda3\\envs\\tf\\lib\\asyncio\\selector_events.py\", line 115, in _read_from_self\n",
      "    data = self._ssock.recv(4096)\n",
      "ConnectionResetError: [WinError 10054] An existing connection was forcibly closed by the remote host\n",
      "Exception in callback BaseSelectorEventLoop._read_from_self()\n",
      "handle: <Handle BaseSelectorEventLoop._read_from_self()>\n",
      "Traceback (most recent call last):\n",
      "  File \"c:\\Users\\fafaf\\anaconda3\\envs\\tf\\lib\\asyncio\\events.py\", line 80, in _run\n",
      "    self._context.run(self._callback, *self._args)\n",
      "  File \"c:\\Users\\fafaf\\anaconda3\\envs\\tf\\lib\\asyncio\\selector_events.py\", line 115, in _read_from_self\n",
      "    data = self._ssock.recv(4096)\n",
      "ConnectionResetError: [WinError 10054] An existing connection was forcibly closed by the remote host\n",
      "Exception in callback BaseSelectorEventLoop._read_from_self()\n",
      "handle: <Handle BaseSelectorEventLoop._read_from_self()>\n",
      "Traceback (most recent call last):\n",
      "  File \"c:\\Users\\fafaf\\anaconda3\\envs\\tf\\lib\\asyncio\\events.py\", line 80, in _run\n",
      "    self._context.run(self._callback, *self._args)\n",
      "  File \"c:\\Users\\fafaf\\anaconda3\\envs\\tf\\lib\\asyncio\\selector_events.py\", line 115, in _read_from_self\n",
      "    data = self._ssock.recv(4096)\n",
      "ConnectionResetError: [WinError 10054] An existing connection was forcibly closed by the remote host\n",
      "Exception in callback BaseSelectorEventLoop._read_from_self()\n",
      "handle: <Handle BaseSelectorEventLoop._read_from_self()>\n",
      "Traceback (most recent call last):\n",
      "  File \"c:\\Users\\fafaf\\anaconda3\\envs\\tf\\lib\\asyncio\\events.py\", line 80, in _run\n",
      "    self._context.run(self._callback, *self._args)\n",
      "  File \"c:\\Users\\fafaf\\anaconda3\\envs\\tf\\lib\\asyncio\\selector_events.py\", line 115, in _read_from_self\n",
      "    data = self._ssock.recv(4096)\n",
      "ConnectionResetError: [WinError 10054] An existing connection was forcibly closed by the remote host\n",
      "Exception in callback BaseSelectorEventLoop._read_from_self()\n",
      "handle: <Handle BaseSelectorEventLoop._read_from_self()>\n",
      "Traceback (most recent call last):\n",
      "  File \"c:\\Users\\fafaf\\anaconda3\\envs\\tf\\lib\\asyncio\\events.py\", line 80, in _run\n",
      "    self._context.run(self._callback, *self._args)\n",
      "  File \"c:\\Users\\fafaf\\anaconda3\\envs\\tf\\lib\\asyncio\\selector_events.py\", line 115, in _read_from_self\n",
      "    data = self._ssock.recv(4096)\n",
      "ConnectionResetError: [WinError 10054] An existing connection was forcibly closed by the remote host\n",
      "Exception in callback BaseSelectorEventLoop._read_from_self()\n",
      "handle: <Handle BaseSelectorEventLoop._read_from_self()>\n",
      "Traceback (most recent call last):\n",
      "  File \"c:\\Users\\fafaf\\anaconda3\\envs\\tf\\lib\\asyncio\\events.py\", line 80, in _run\n",
      "    self._context.run(self._callback, *self._args)\n",
      "  File \"c:\\Users\\fafaf\\anaconda3\\envs\\tf\\lib\\asyncio\\selector_events.py\", line 115, in _read_from_self\n",
      "    data = self._ssock.recv(4096)\n",
      "ConnectionResetError: [WinError 10054] An existing connection was forcibly closed by the remote host\n",
      "Exception in callback BaseSelectorEventLoop._read_from_self()\n",
      "handle: <Handle BaseSelectorEventLoop._read_from_self()>\n",
      "Traceback (most recent call last):\n",
      "  File \"c:\\Users\\fafaf\\anaconda3\\envs\\tf\\lib\\asyncio\\events.py\", line 80, in _run\n",
      "    self._context.run(self._callback, *self._args)\n",
      "  File \"c:\\Users\\fafaf\\anaconda3\\envs\\tf\\lib\\asyncio\\selector_events.py\", line 115, in _read_from_self\n",
      "    data = self._ssock.recv(4096)\n",
      "ConnectionResetError: [WinError 10054] An existing connection was forcibly closed by the remote host\n",
      "Exception in callback BaseSelectorEventLoop._read_from_self()\n",
      "handle: <Handle BaseSelectorEventLoop._read_from_self()>\n",
      "Traceback (most recent call last):\n",
      "  File \"c:\\Users\\fafaf\\anaconda3\\envs\\tf\\lib\\asyncio\\events.py\", line 80, in _run\n",
      "    self._context.run(self._callback, *self._args)\n",
      "  File \"c:\\Users\\fafaf\\anaconda3\\envs\\tf\\lib\\asyncio\\selector_events.py\", line 115, in _read_from_self\n",
      "    data = self._ssock.recv(4096)\n",
      "ConnectionResetError: [WinError 10054] An existing connection was forcibly closed by the remote host\n",
      "Exception in callback BaseSelectorEventLoop._read_from_self()\n",
      "handle: <Handle BaseSelectorEventLoop._read_from_self()>\n",
      "Traceback (most recent call last):\n",
      "  File \"c:\\Users\\fafaf\\anaconda3\\envs\\tf\\lib\\asyncio\\events.py\", line 80, in _run\n",
      "    self._context.run(self._callback, *self._args)\n",
      "  File \"c:\\Users\\fafaf\\anaconda3\\envs\\tf\\lib\\asyncio\\selector_events.py\", line 115, in _read_from_self\n",
      "    data = self._ssock.recv(4096)\n",
      "ConnectionResetError: [WinError 10054] An existing connection was forcibly closed by the remote host\n",
      "Exception in callback BaseSelectorEventLoop._read_from_self()\n",
      "handle: <Handle BaseSelectorEventLoop._read_from_self()>\n",
      "Traceback (most recent call last):\n",
      "  File \"c:\\Users\\fafaf\\anaconda3\\envs\\tf\\lib\\asyncio\\events.py\", line 80, in _run\n",
      "    self._context.run(self._callback, *self._args)\n",
      "  File \"c:\\Users\\fafaf\\anaconda3\\envs\\tf\\lib\\asyncio\\selector_events.py\", line 115, in _read_from_self\n",
      "    data = self._ssock.recv(4096)\n",
      "ConnectionResetError: [WinError 10054] An existing connection was forcibly closed by the remote host\n",
      "Exception in callback BaseSelectorEventLoop._read_from_self()\n",
      "handle: <Handle BaseSelectorEventLoop._read_from_self()>\n",
      "Traceback (most recent call last):\n",
      "  File \"c:\\Users\\fafaf\\anaconda3\\envs\\tf\\lib\\asyncio\\events.py\", line 80, in _run\n",
      "    self._context.run(self._callback, *self._args)\n",
      "  File \"c:\\Users\\fafaf\\anaconda3\\envs\\tf\\lib\\asyncio\\selector_events.py\", line 115, in _read_from_self\n",
      "    data = self._ssock.recv(4096)\n",
      "ConnectionResetError: [WinError 10054] An existing connection was forcibly closed by the remote host\n",
      "Exception in callback BaseSelectorEventLoop._read_from_self()\n",
      "handle: <Handle BaseSelectorEventLoop._read_from_self()>\n",
      "Traceback (most recent call last):\n",
      "  File \"c:\\Users\\fafaf\\anaconda3\\envs\\tf\\lib\\asyncio\\events.py\", line 80, in _run\n",
      "    self._context.run(self._callback, *self._args)\n",
      "  File \"c:\\Users\\fafaf\\anaconda3\\envs\\tf\\lib\\asyncio\\selector_events.py\", line 115, in _read_from_self\n",
      "    data = self._ssock.recv(4096)\n",
      "ConnectionResetError: [WinError 10054] An existing connection was forcibly closed by the remote host\n",
      "Exception in callback BaseSelectorEventLoop._read_from_self()\n",
      "handle: <Handle BaseSelectorEventLoop._read_from_self()>\n",
      "Traceback (most recent call last):\n",
      "  File \"c:\\Users\\fafaf\\anaconda3\\envs\\tf\\lib\\asyncio\\events.py\", line 80, in _run\n",
      "    self._context.run(self._callback, *self._args)\n",
      "  File \"c:\\Users\\fafaf\\anaconda3\\envs\\tf\\lib\\asyncio\\selector_events.py\", line 115, in _read_from_self\n",
      "    data = self._ssock.recv(4096)\n",
      "ConnectionResetError: [WinError 10054] An existing connection was forcibly closed by the remote host\n",
      "Exception in callback BaseSelectorEventLoop._read_from_self()\n",
      "handle: <Handle BaseSelectorEventLoop._read_from_self()>\n",
      "Traceback (most recent call last):\n",
      "  File \"c:\\Users\\fafaf\\anaconda3\\envs\\tf\\lib\\asyncio\\events.py\", line 80, in _run\n",
      "    self._context.run(self._callback, *self._args)\n",
      "  File \"c:\\Users\\fafaf\\anaconda3\\envs\\tf\\lib\\asyncio\\selector_events.py\", line 115, in _read_from_self\n",
      "    data = self._ssock.recv(4096)\n",
      "ConnectionResetError: [WinError 10054] An existing connection was forcibly closed by the remote host\n",
      "Exception in callback BaseSelectorEventLoop._read_from_self()\n",
      "handle: <Handle BaseSelectorEventLoop._read_from_self()>\n",
      "Traceback (most recent call last):\n",
      "  File \"c:\\Users\\fafaf\\anaconda3\\envs\\tf\\lib\\asyncio\\events.py\", line 80, in _run\n",
      "    self._context.run(self._callback, *self._args)\n",
      "  File \"c:\\Users\\fafaf\\anaconda3\\envs\\tf\\lib\\asyncio\\selector_events.py\", line 115, in _read_from_self\n",
      "    data = self._ssock.recv(4096)\n",
      "ConnectionResetError: [WinError 10054] An existing connection was forcibly closed by the remote host\n",
      "Exception in callback BaseSelectorEventLoop._read_from_self()\n",
      "handle: <Handle BaseSelectorEventLoop._read_from_self()>\n",
      "Traceback (most recent call last):\n",
      "  File \"c:\\Users\\fafaf\\anaconda3\\envs\\tf\\lib\\asyncio\\events.py\", line 80, in _run\n",
      "    self._context.run(self._callback, *self._args)\n",
      "  File \"c:\\Users\\fafaf\\anaconda3\\envs\\tf\\lib\\asyncio\\selector_events.py\", line 115, in _read_from_self\n",
      "    data = self._ssock.recv(4096)\n",
      "ConnectionResetError: [WinError 10054] An existing connection was forcibly closed by the remote host\n",
      "Exception in callback BaseSelectorEventLoop._read_from_self()\n",
      "handle: <Handle BaseSelectorEventLoop._read_from_self()>\n",
      "Traceback (most recent call last):\n",
      "  File \"c:\\Users\\fafaf\\anaconda3\\envs\\tf\\lib\\asyncio\\events.py\", line 80, in _run\n",
      "    self._context.run(self._callback, *self._args)\n",
      "  File \"c:\\Users\\fafaf\\anaconda3\\envs\\tf\\lib\\asyncio\\selector_events.py\", line 115, in _read_from_self\n",
      "    data = self._ssock.recv(4096)\n",
      "ConnectionResetError: [WinError 10054] An existing connection was forcibly closed by the remote host\n",
      "Exception in callback BaseSelectorEventLoop._read_from_self()\n",
      "handle: <Handle BaseSelectorEventLoop._read_from_self()>\n",
      "Traceback (most recent call last):\n",
      "  File \"c:\\Users\\fafaf\\anaconda3\\envs\\tf\\lib\\asyncio\\events.py\", line 80, in _run\n",
      "    self._context.run(self._callback, *self._args)\n",
      "  File \"c:\\Users\\fafaf\\anaconda3\\envs\\tf\\lib\\asyncio\\selector_events.py\", line 115, in _read_from_self\n",
      "    data = self._ssock.recv(4096)\n",
      "ConnectionResetError: [WinError 10054] An existing connection was forcibly closed by the remote host\n",
      "Exception in callback BaseSelectorEventLoop._read_from_self()\n",
      "handle: <Handle BaseSelectorEventLoop._read_from_self()>\n",
      "Traceback (most recent call last):\n",
      "  File \"c:\\Users\\fafaf\\anaconda3\\envs\\tf\\lib\\asyncio\\events.py\", line 80, in _run\n",
      "    self._context.run(self._callback, *self._args)\n",
      "  File \"c:\\Users\\fafaf\\anaconda3\\envs\\tf\\lib\\asyncio\\selector_events.py\", line 115, in _read_from_self\n",
      "    data = self._ssock.recv(4096)\n",
      "ConnectionResetError: [WinError 10054] An existing connection was forcibly closed by the remote host\n",
      "Exception in callback BaseSelectorEventLoop._read_from_self()\n",
      "handle: <Handle BaseSelectorEventLoop._read_from_self()>\n",
      "Traceback (most recent call last):\n",
      "  File \"c:\\Users\\fafaf\\anaconda3\\envs\\tf\\lib\\asyncio\\events.py\", line 80, in _run\n",
      "    self._context.run(self._callback, *self._args)\n",
      "  File \"c:\\Users\\fafaf\\anaconda3\\envs\\tf\\lib\\asyncio\\selector_events.py\", line 115, in _read_from_self\n",
      "    data = self._ssock.recv(4096)\n",
      "ConnectionResetError: [WinError 10054] An existing connection was forcibly closed by the remote host\n",
      "Exception in callback BaseSelectorEventLoop._read_from_self()\n",
      "handle: <Handle BaseSelectorEventLoop._read_from_self()>\n",
      "Traceback (most recent call last):\n",
      "  File \"c:\\Users\\fafaf\\anaconda3\\envs\\tf\\lib\\asyncio\\events.py\", line 80, in _run\n",
      "    self._context.run(self._callback, *self._args)\n",
      "  File \"c:\\Users\\fafaf\\anaconda3\\envs\\tf\\lib\\asyncio\\selector_events.py\", line 115, in _read_from_self\n",
      "    data = self._ssock.recv(4096)\n",
      "ConnectionResetError: [WinError 10054] An existing connection was forcibly closed by the remote host\n",
      "Exception in callback BaseSelectorEventLoop._read_from_self()\n",
      "handle: <Handle BaseSelectorEventLoop._read_from_self()>\n",
      "Traceback (most recent call last):\n",
      "  File \"c:\\Users\\fafaf\\anaconda3\\envs\\tf\\lib\\asyncio\\events.py\", line 80, in _run\n",
      "    self._context.run(self._callback, *self._args)\n",
      "  File \"c:\\Users\\fafaf\\anaconda3\\envs\\tf\\lib\\asyncio\\selector_events.py\", line 115, in _read_from_self\n",
      "    data = self._ssock.recv(4096)\n",
      "ConnectionResetError: [WinError 10054] An existing connection was forcibly closed by the remote host\n",
      "Exception in callback BaseSelectorEventLoop._read_from_self()\n",
      "handle: <Handle BaseSelectorEventLoop._read_from_self()>\n",
      "Traceback (most recent call last):\n",
      "  File \"c:\\Users\\fafaf\\anaconda3\\envs\\tf\\lib\\asyncio\\events.py\", line 80, in _run\n",
      "    self._context.run(self._callback, *self._args)\n",
      "  File \"c:\\Users\\fafaf\\anaconda3\\envs\\tf\\lib\\asyncio\\selector_events.py\", line 115, in _read_from_self\n",
      "    data = self._ssock.recv(4096)\n",
      "ConnectionResetError: [WinError 10054] An existing connection was forcibly closed by the remote host\n",
      "Exception in callback BaseSelectorEventLoop._read_from_self()\n",
      "handle: <Handle BaseSelectorEventLoop._read_from_self()>\n",
      "Traceback (most recent call last):\n",
      "  File \"c:\\Users\\fafaf\\anaconda3\\envs\\tf\\lib\\asyncio\\events.py\", line 80, in _run\n",
      "    self._context.run(self._callback, *self._args)\n",
      "  File \"c:\\Users\\fafaf\\anaconda3\\envs\\tf\\lib\\asyncio\\selector_events.py\", line 115, in _read_from_self\n",
      "    data = self._ssock.recv(4096)\n",
      "ConnectionResetError: [WinError 10054] An existing connection was forcibly closed by the remote host\n",
      "Exception in callback BaseSelectorEventLoop._read_from_self()\n",
      "handle: <Handle BaseSelectorEventLoop._read_from_self()>\n",
      "Traceback (most recent call last):\n",
      "  File \"c:\\Users\\fafaf\\anaconda3\\envs\\tf\\lib\\asyncio\\events.py\", line 80, in _run\n",
      "    self._context.run(self._callback, *self._args)\n",
      "  File \"c:\\Users\\fafaf\\anaconda3\\envs\\tf\\lib\\asyncio\\selector_events.py\", line 115, in _read_from_self\n",
      "    data = self._ssock.recv(4096)\n",
      "ConnectionResetError: [WinError 10054] An existing connection was forcibly closed by the remote host\n",
      "Exception in callback BaseSelectorEventLoop._read_from_self()\n",
      "handle: <Handle BaseSelectorEventLoop._read_from_self()>\n",
      "Traceback (most recent call last):\n",
      "  File \"c:\\Users\\fafaf\\anaconda3\\envs\\tf\\lib\\asyncio\\events.py\", line 80, in _run\n",
      "    self._context.run(self._callback, *self._args)\n",
      "  File \"c:\\Users\\fafaf\\anaconda3\\envs\\tf\\lib\\asyncio\\selector_events.py\", line 115, in _read_from_self\n",
      "    data = self._ssock.recv(4096)\n",
      "ConnectionResetError: [WinError 10054] An existing connection was forcibly closed by the remote host\n",
      "Exception in callback BaseSelectorEventLoop._read_from_self()\n",
      "handle: <Handle BaseSelectorEventLoop._read_from_self()>\n",
      "Traceback (most recent call last):\n",
      "  File \"c:\\Users\\fafaf\\anaconda3\\envs\\tf\\lib\\asyncio\\events.py\", line 80, in _run\n",
      "    self._context.run(self._callback, *self._args)\n",
      "  File \"c:\\Users\\fafaf\\anaconda3\\envs\\tf\\lib\\asyncio\\selector_events.py\", line 115, in _read_from_self\n",
      "    data = self._ssock.recv(4096)\n",
      "ConnectionResetError: [WinError 10054] An existing connection was forcibly closed by the remote host\n",
      "Exception in callback BaseSelectorEventLoop._read_from_self()\n",
      "handle: <Handle BaseSelectorEventLoop._read_from_self()>\n",
      "Traceback (most recent call last):\n",
      "  File \"c:\\Users\\fafaf\\anaconda3\\envs\\tf\\lib\\asyncio\\events.py\", line 80, in _run\n",
      "    self._context.run(self._callback, *self._args)\n",
      "  File \"c:\\Users\\fafaf\\anaconda3\\envs\\tf\\lib\\asyncio\\selector_events.py\", line 115, in _read_from_self\n",
      "    data = self._ssock.recv(4096)\n",
      "ConnectionResetError: [WinError 10054] An existing connection was forcibly closed by the remote host\n",
      "Exception in callback BaseSelectorEventLoop._read_from_self()\n",
      "handle: <Handle BaseSelectorEventLoop._read_from_self()>\n",
      "Traceback (most recent call last):\n",
      "  File \"c:\\Users\\fafaf\\anaconda3\\envs\\tf\\lib\\asyncio\\events.py\", line 80, in _run\n",
      "    self._context.run(self._callback, *self._args)\n",
      "  File \"c:\\Users\\fafaf\\anaconda3\\envs\\tf\\lib\\asyncio\\selector_events.py\", line 115, in _read_from_self\n",
      "    data = self._ssock.recv(4096)\n",
      "ConnectionResetError: [WinError 10054] An existing connection was forcibly closed by the remote host\n",
      "Exception in callback BaseSelectorEventLoop._read_from_self()\n",
      "handle: <Handle BaseSelectorEventLoop._read_from_self()>\n",
      "Traceback (most recent call last):\n",
      "  File \"c:\\Users\\fafaf\\anaconda3\\envs\\tf\\lib\\asyncio\\events.py\", line 80, in _run\n",
      "    self._context.run(self._callback, *self._args)\n",
      "  File \"c:\\Users\\fafaf\\anaconda3\\envs\\tf\\lib\\asyncio\\selector_events.py\", line 115, in _read_from_self\n",
      "    data = self._ssock.recv(4096)\n",
      "ConnectionResetError: [WinError 10054] An existing connection was forcibly closed by the remote host\n",
      "Exception in callback BaseSelectorEventLoop._read_from_self()\n",
      "handle: <Handle BaseSelectorEventLoop._read_from_self()>\n",
      "Traceback (most recent call last):\n",
      "  File \"c:\\Users\\fafaf\\anaconda3\\envs\\tf\\lib\\asyncio\\events.py\", line 80, in _run\n",
      "    self._context.run(self._callback, *self._args)\n",
      "  File \"c:\\Users\\fafaf\\anaconda3\\envs\\tf\\lib\\asyncio\\selector_events.py\", line 115, in _read_from_self\n",
      "    data = self._ssock.recv(4096)\n",
      "ConnectionResetError: [WinError 10054] An existing connection was forcibly closed by the remote host\n",
      "Exception in callback BaseSelectorEventLoop._read_from_self()\n",
      "handle: <Handle BaseSelectorEventLoop._read_from_self()>\n",
      "Traceback (most recent call last):\n",
      "  File \"c:\\Users\\fafaf\\anaconda3\\envs\\tf\\lib\\asyncio\\events.py\", line 80, in _run\n",
      "    self._context.run(self._callback, *self._args)\n",
      "  File \"c:\\Users\\fafaf\\anaconda3\\envs\\tf\\lib\\asyncio\\selector_events.py\", line 115, in _read_from_self\n",
      "    data = self._ssock.recv(4096)\n",
      "ConnectionResetError: [WinError 10054] An existing connection was forcibly closed by the remote host\n",
      "Exception in callback BaseSelectorEventLoop._read_from_self()\n",
      "handle: <Handle BaseSelectorEventLoop._read_from_self()>\n",
      "Traceback (most recent call last):\n",
      "  File \"c:\\Users\\fafaf\\anaconda3\\envs\\tf\\lib\\asyncio\\events.py\", line 80, in _run\n",
      "    self._context.run(self._callback, *self._args)\n",
      "  File \"c:\\Users\\fafaf\\anaconda3\\envs\\tf\\lib\\asyncio\\selector_events.py\", line 115, in _read_from_self\n",
      "    data = self._ssock.recv(4096)\n",
      "ConnectionResetError: [WinError 10054] An existing connection was forcibly closed by the remote host\n",
      "Exception in callback BaseSelectorEventLoop._read_from_self()\n",
      "handle: <Handle BaseSelectorEventLoop._read_from_self()>\n",
      "Traceback (most recent call last):\n",
      "  File \"c:\\Users\\fafaf\\anaconda3\\envs\\tf\\lib\\asyncio\\events.py\", line 80, in _run\n",
      "    self._context.run(self._callback, *self._args)\n",
      "  File \"c:\\Users\\fafaf\\anaconda3\\envs\\tf\\lib\\asyncio\\selector_events.py\", line 115, in _read_from_self\n",
      "    data = self._ssock.recv(4096)\n",
      "ConnectionResetError: [WinError 10054] An existing connection was forcibly closed by the remote host\n",
      "Exception in callback BaseSelectorEventLoop._read_from_self()\n",
      "handle: <Handle BaseSelectorEventLoop._read_from_self()>\n",
      "Traceback (most recent call last):\n",
      "  File \"c:\\Users\\fafaf\\anaconda3\\envs\\tf\\lib\\asyncio\\events.py\", line 80, in _run\n",
      "    self._context.run(self._callback, *self._args)\n",
      "  File \"c:\\Users\\fafaf\\anaconda3\\envs\\tf\\lib\\asyncio\\selector_events.py\", line 115, in _read_from_self\n",
      "    data = self._ssock.recv(4096)\n",
      "ConnectionResetError: [WinError 10054] An existing connection was forcibly closed by the remote host\n",
      "Exception in callback BaseSelectorEventLoop._read_from_self()\n",
      "handle: <Handle BaseSelectorEventLoop._read_from_self()>\n",
      "Traceback (most recent call last):\n",
      "  File \"c:\\Users\\fafaf\\anaconda3\\envs\\tf\\lib\\asyncio\\events.py\", line 80, in _run\n",
      "    self._context.run(self._callback, *self._args)\n",
      "  File \"c:\\Users\\fafaf\\anaconda3\\envs\\tf\\lib\\asyncio\\selector_events.py\", line 115, in _read_from_self\n",
      "    data = self._ssock.recv(4096)\n",
      "ConnectionResetError: [WinError 10054] An existing connection was forcibly closed by the remote host\n",
      "Exception in callback BaseSelectorEventLoop._read_from_self()\n",
      "handle: <Handle BaseSelectorEventLoop._read_from_self()>\n",
      "Traceback (most recent call last):\n",
      "  File \"c:\\Users\\fafaf\\anaconda3\\envs\\tf\\lib\\asyncio\\events.py\", line 80, in _run\n",
      "    self._context.run(self._callback, *self._args)\n",
      "  File \"c:\\Users\\fafaf\\anaconda3\\envs\\tf\\lib\\asyncio\\selector_events.py\", line 115, in _read_from_self\n",
      "    data = self._ssock.recv(4096)\n",
      "ConnectionResetError: [WinError 10054] An existing connection was forcibly closed by the remote host\n",
      "Exception in callback BaseSelectorEventLoop._read_from_self()\n",
      "handle: <Handle BaseSelectorEventLoop._read_from_self()>\n",
      "Traceback (most recent call last):\n",
      "  File \"c:\\Users\\fafaf\\anaconda3\\envs\\tf\\lib\\asyncio\\events.py\", line 80, in _run\n",
      "    self._context.run(self._callback, *self._args)\n",
      "  File \"c:\\Users\\fafaf\\anaconda3\\envs\\tf\\lib\\asyncio\\selector_events.py\", line 115, in _read_from_self\n",
      "    data = self._ssock.recv(4096)\n",
      "ConnectionResetError: [WinError 10054] An existing connection was forcibly closed by the remote host\n",
      "Exception in callback BaseSelectorEventLoop._read_from_self()\n",
      "handle: <Handle BaseSelectorEventLoop._read_from_self()>\n",
      "Traceback (most recent call last):\n",
      "  File \"c:\\Users\\fafaf\\anaconda3\\envs\\tf\\lib\\asyncio\\events.py\", line 80, in _run\n",
      "    self._context.run(self._callback, *self._args)\n",
      "  File \"c:\\Users\\fafaf\\anaconda3\\envs\\tf\\lib\\asyncio\\selector_events.py\", line 115, in _read_from_self\n",
      "    data = self._ssock.recv(4096)\n",
      "ConnectionResetError: [WinError 10054] An existing connection was forcibly closed by the remote host\n",
      "Exception in callback BaseSelectorEventLoop._read_from_self()\n",
      "handle: <Handle BaseSelectorEventLoop._read_from_self()>\n",
      "Traceback (most recent call last):\n",
      "  File \"c:\\Users\\fafaf\\anaconda3\\envs\\tf\\lib\\asyncio\\events.py\", line 80, in _run\n",
      "    self._context.run(self._callback, *self._args)\n",
      "  File \"c:\\Users\\fafaf\\anaconda3\\envs\\tf\\lib\\asyncio\\selector_events.py\", line 115, in _read_from_self\n",
      "    data = self._ssock.recv(4096)\n",
      "ConnectionResetError: [WinError 10054] An existing connection was forcibly closed by the remote host\n",
      "Exception in callback BaseSelectorEventLoop._read_from_self()\n",
      "handle: <Handle BaseSelectorEventLoop._read_from_self()>\n",
      "Traceback (most recent call last):\n",
      "  File \"c:\\Users\\fafaf\\anaconda3\\envs\\tf\\lib\\asyncio\\events.py\", line 80, in _run\n",
      "    self._context.run(self._callback, *self._args)\n",
      "  File \"c:\\Users\\fafaf\\anaconda3\\envs\\tf\\lib\\asyncio\\selector_events.py\", line 115, in _read_from_self\n",
      "    data = self._ssock.recv(4096)\n",
      "ConnectionResetError: [WinError 10054] An existing connection was forcibly closed by the remote host\n",
      "Exception in callback BaseSelectorEventLoop._read_from_self()\n",
      "handle: <Handle BaseSelectorEventLoop._read_from_self()>\n",
      "Traceback (most recent call last):\n",
      "  File \"c:\\Users\\fafaf\\anaconda3\\envs\\tf\\lib\\asyncio\\events.py\", line 80, in _run\n",
      "    self._context.run(self._callback, *self._args)\n",
      "  File \"c:\\Users\\fafaf\\anaconda3\\envs\\tf\\lib\\asyncio\\selector_events.py\", line 115, in _read_from_self\n",
      "    data = self._ssock.recv(4096)\n",
      "ConnectionResetError: [WinError 10054] An existing connection was forcibly closed by the remote host\n",
      "Exception in callback BaseSelectorEventLoop._read_from_self()\n",
      "handle: <Handle BaseSelectorEventLoop._read_from_self()>\n",
      "Traceback (most recent call last):\n",
      "  File \"c:\\Users\\fafaf\\anaconda3\\envs\\tf\\lib\\asyncio\\events.py\", line 80, in _run\n",
      "    self._context.run(self._callback, *self._args)\n",
      "  File \"c:\\Users\\fafaf\\anaconda3\\envs\\tf\\lib\\asyncio\\selector_events.py\", line 115, in _read_from_self\n",
      "    data = self._ssock.recv(4096)\n",
      "ConnectionResetError: [WinError 10054] An existing connection was forcibly closed by the remote host\n",
      "Exception in callback BaseSelectorEventLoop._read_from_self()\n",
      "handle: <Handle BaseSelectorEventLoop._read_from_self()>\n",
      "Traceback (most recent call last):\n",
      "  File \"c:\\Users\\fafaf\\anaconda3\\envs\\tf\\lib\\asyncio\\events.py\", line 80, in _run\n",
      "    self._context.run(self._callback, *self._args)\n",
      "  File \"c:\\Users\\fafaf\\anaconda3\\envs\\tf\\lib\\asyncio\\selector_events.py\", line 115, in _read_from_self\n",
      "    data = self._ssock.recv(4096)\n",
      "ConnectionResetError: [WinError 10054] An existing connection was forcibly closed by the remote host\n",
      "Exception in callback BaseSelectorEventLoop._read_from_self()\n",
      "handle: <Handle BaseSelectorEventLoop._read_from_self()>\n",
      "Traceback (most recent call last):\n",
      "  File \"c:\\Users\\fafaf\\anaconda3\\envs\\tf\\lib\\asyncio\\events.py\", line 80, in _run\n",
      "    self._context.run(self._callback, *self._args)\n",
      "  File \"c:\\Users\\fafaf\\anaconda3\\envs\\tf\\lib\\asyncio\\selector_events.py\", line 115, in _read_from_self\n",
      "    data = self._ssock.recv(4096)\n",
      "ConnectionResetError: [WinError 10054] An existing connection was forcibly closed by the remote host\n",
      "Exception in callback BaseSelectorEventLoop._read_from_self()\n",
      "handle: <Handle BaseSelectorEventLoop._read_from_self()>\n",
      "Traceback (most recent call last):\n",
      "  File \"c:\\Users\\fafaf\\anaconda3\\envs\\tf\\lib\\asyncio\\events.py\", line 80, in _run\n",
      "    self._context.run(self._callback, *self._args)\n",
      "  File \"c:\\Users\\fafaf\\anaconda3\\envs\\tf\\lib\\asyncio\\selector_events.py\", line 115, in _read_from_self\n",
      "    data = self._ssock.recv(4096)\n",
      "ConnectionResetError: [WinError 10054] An existing connection was forcibly closed by the remote host\n",
      "Exception in callback BaseSelectorEventLoop._read_from_self()\n",
      "handle: <Handle BaseSelectorEventLoop._read_from_self()>\n",
      "Traceback (most recent call last):\n",
      "  File \"c:\\Users\\fafaf\\anaconda3\\envs\\tf\\lib\\asyncio\\events.py\", line 80, in _run\n",
      "    self._context.run(self._callback, *self._args)\n",
      "  File \"c:\\Users\\fafaf\\anaconda3\\envs\\tf\\lib\\asyncio\\selector_events.py\", line 115, in _read_from_self\n",
      "    data = self._ssock.recv(4096)\n",
      "ConnectionResetError: [WinError 10054] An existing connection was forcibly closed by the remote host\n",
      "Exception in callback BaseSelectorEventLoop._read_from_self()\n",
      "handle: <Handle BaseSelectorEventLoop._read_from_self()>\n",
      "Traceback (most recent call last):\n",
      "  File \"c:\\Users\\fafaf\\anaconda3\\envs\\tf\\lib\\asyncio\\events.py\", line 80, in _run\n",
      "    self._context.run(self._callback, *self._args)\n",
      "  File \"c:\\Users\\fafaf\\anaconda3\\envs\\tf\\lib\\asyncio\\selector_events.py\", line 115, in _read_from_self\n",
      "    data = self._ssock.recv(4096)\n",
      "ConnectionResetError: [WinError 10054] An existing connection was forcibly closed by the remote host\n",
      "Exception in callback BaseSelectorEventLoop._read_from_self()\n",
      "handle: <Handle BaseSelectorEventLoop._read_from_self()>\n",
      "Traceback (most recent call last):\n",
      "  File \"c:\\Users\\fafaf\\anaconda3\\envs\\tf\\lib\\asyncio\\events.py\", line 80, in _run\n",
      "    self._context.run(self._callback, *self._args)\n",
      "  File \"c:\\Users\\fafaf\\anaconda3\\envs\\tf\\lib\\asyncio\\selector_events.py\", line 115, in _read_from_self\n",
      "    data = self._ssock.recv(4096)\n",
      "ConnectionResetError: [WinError 10054] An existing connection was forcibly closed by the remote host\n",
      "Exception in callback BaseSelectorEventLoop._read_from_self()\n",
      "handle: <Handle BaseSelectorEventLoop._read_from_self()>\n",
      "Traceback (most recent call last):\n",
      "  File \"c:\\Users\\fafaf\\anaconda3\\envs\\tf\\lib\\asyncio\\events.py\", line 80, in _run\n",
      "    self._context.run(self._callback, *self._args)\n",
      "  File \"c:\\Users\\fafaf\\anaconda3\\envs\\tf\\lib\\asyncio\\selector_events.py\", line 115, in _read_from_self\n",
      "    data = self._ssock.recv(4096)\n",
      "ConnectionResetError: [WinError 10054] An existing connection was forcibly closed by the remote host\n",
      "Exception in callback BaseSelectorEventLoop._read_from_self()\n",
      "handle: <Handle BaseSelectorEventLoop._read_from_self()>\n",
      "Traceback (most recent call last):\n",
      "  File \"c:\\Users\\fafaf\\anaconda3\\envs\\tf\\lib\\asyncio\\events.py\", line 80, in _run\n",
      "    self._context.run(self._callback, *self._args)\n",
      "  File \"c:\\Users\\fafaf\\anaconda3\\envs\\tf\\lib\\asyncio\\selector_events.py\", line 115, in _read_from_self\n",
      "    data = self._ssock.recv(4096)\n",
      "ConnectionResetError: [WinError 10054] An existing connection was forcibly closed by the remote host\n",
      "Exception in callback BaseSelectorEventLoop._read_from_self()\n",
      "handle: <Handle BaseSelectorEventLoop._read_from_self()>\n",
      "Traceback (most recent call last):\n",
      "  File \"c:\\Users\\fafaf\\anaconda3\\envs\\tf\\lib\\asyncio\\events.py\", line 80, in _run\n",
      "    self._context.run(self._callback, *self._args)\n",
      "  File \"c:\\Users\\fafaf\\anaconda3\\envs\\tf\\lib\\asyncio\\selector_events.py\", line 115, in _read_from_self\n",
      "    data = self._ssock.recv(4096)\n",
      "ConnectionResetError: [WinError 10054] An existing connection was forcibly closed by the remote host\n",
      "Exception in callback BaseSelectorEventLoop._read_from_self()\n",
      "handle: <Handle BaseSelectorEventLoop._read_from_self()>\n",
      "Traceback (most recent call last):\n",
      "  File \"c:\\Users\\fafaf\\anaconda3\\envs\\tf\\lib\\asyncio\\events.py\", line 80, in _run\n",
      "    self._context.run(self._callback, *self._args)\n",
      "  File \"c:\\Users\\fafaf\\anaconda3\\envs\\tf\\lib\\asyncio\\selector_events.py\", line 115, in _read_from_self\n",
      "    data = self._ssock.recv(4096)\n",
      "ConnectionResetError: [WinError 10054] An existing connection was forcibly closed by the remote host\n",
      "Exception in callback BaseSelectorEventLoop._read_from_self()\n",
      "handle: <Handle BaseSelectorEventLoop._read_from_self()>\n",
      "Traceback (most recent call last):\n",
      "  File \"c:\\Users\\fafaf\\anaconda3\\envs\\tf\\lib\\asyncio\\events.py\", line 80, in _run\n",
      "    self._context.run(self._callback, *self._args)\n",
      "  File \"c:\\Users\\fafaf\\anaconda3\\envs\\tf\\lib\\asyncio\\selector_events.py\", line 115, in _read_from_self\n",
      "    data = self._ssock.recv(4096)\n",
      "ConnectionResetError: [WinError 10054] An existing connection was forcibly closed by the remote host\n",
      "Exception in callback BaseSelectorEventLoop._read_from_self()\n",
      "handle: <Handle BaseSelectorEventLoop._read_from_self()>\n",
      "Traceback (most recent call last):\n",
      "  File \"c:\\Users\\fafaf\\anaconda3\\envs\\tf\\lib\\asyncio\\events.py\", line 80, in _run\n",
      "    self._context.run(self._callback, *self._args)\n",
      "  File \"c:\\Users\\fafaf\\anaconda3\\envs\\tf\\lib\\asyncio\\selector_events.py\", line 115, in _read_from_self\n",
      "    data = self._ssock.recv(4096)\n",
      "ConnectionResetError: [WinError 10054] An existing connection was forcibly closed by the remote host\n",
      "Exception in callback BaseSelectorEventLoop._read_from_self()\n",
      "handle: <Handle BaseSelectorEventLoop._read_from_self()>\n",
      "Traceback (most recent call last):\n",
      "  File \"c:\\Users\\fafaf\\anaconda3\\envs\\tf\\lib\\asyncio\\events.py\", line 80, in _run\n",
      "    self._context.run(self._callback, *self._args)\n",
      "  File \"c:\\Users\\fafaf\\anaconda3\\envs\\tf\\lib\\asyncio\\selector_events.py\", line 115, in _read_from_self\n",
      "    data = self._ssock.recv(4096)\n",
      "ConnectionResetError: [WinError 10054] An existing connection was forcibly closed by the remote host\n",
      "Exception in callback BaseSelectorEventLoop._read_from_self()\n",
      "handle: <Handle BaseSelectorEventLoop._read_from_self()>\n",
      "Traceback (most recent call last):\n",
      "  File \"c:\\Users\\fafaf\\anaconda3\\envs\\tf\\lib\\asyncio\\events.py\", line 80, in _run\n",
      "    self._context.run(self._callback, *self._args)\n",
      "  File \"c:\\Users\\fafaf\\anaconda3\\envs\\tf\\lib\\asyncio\\selector_events.py\", line 115, in _read_from_self\n",
      "    data = self._ssock.recv(4096)\n",
      "ConnectionResetError: [WinError 10054] An existing connection was forcibly closed by the remote host\n",
      "Exception in callback BaseSelectorEventLoop._read_from_self()\n",
      "handle: <Handle BaseSelectorEventLoop._read_from_self()>\n",
      "Traceback (most recent call last):\n",
      "  File \"c:\\Users\\fafaf\\anaconda3\\envs\\tf\\lib\\asyncio\\events.py\", line 80, in _run\n",
      "    self._context.run(self._callback, *self._args)\n",
      "  File \"c:\\Users\\fafaf\\anaconda3\\envs\\tf\\lib\\asyncio\\selector_events.py\", line 115, in _read_from_self\n",
      "    data = self._ssock.recv(4096)\n",
      "ConnectionResetError: [WinError 10054] An existing connection was forcibly closed by the remote host\n",
      "Exception in callback BaseSelectorEventLoop._read_from_self()\n",
      "handle: <Handle BaseSelectorEventLoop._read_from_self()>\n",
      "Traceback (most recent call last):\n",
      "  File \"c:\\Users\\fafaf\\anaconda3\\envs\\tf\\lib\\asyncio\\events.py\", line 80, in _run\n",
      "    self._context.run(self._callback, *self._args)\n",
      "  File \"c:\\Users\\fafaf\\anaconda3\\envs\\tf\\lib\\asyncio\\selector_events.py\", line 115, in _read_from_self\n",
      "    data = self._ssock.recv(4096)\n",
      "ConnectionResetError: [WinError 10054] An existing connection was forcibly closed by the remote host\n",
      "Exception in callback BaseSelectorEventLoop._read_from_self()\n",
      "handle: <Handle BaseSelectorEventLoop._read_from_self()>\n",
      "Traceback (most recent call last):\n",
      "  File \"c:\\Users\\fafaf\\anaconda3\\envs\\tf\\lib\\asyncio\\events.py\", line 80, in _run\n",
      "    self._context.run(self._callback, *self._args)\n",
      "  File \"c:\\Users\\fafaf\\anaconda3\\envs\\tf\\lib\\asyncio\\selector_events.py\", line 115, in _read_from_self\n",
      "    data = self._ssock.recv(4096)\n",
      "ConnectionResetError: [WinError 10054] An existing connection was forcibly closed by the remote host\n",
      "Exception in callback BaseSelectorEventLoop._read_from_self()\n",
      "handle: <Handle BaseSelectorEventLoop._read_from_self()>\n",
      "Traceback (most recent call last):\n",
      "  File \"c:\\Users\\fafaf\\anaconda3\\envs\\tf\\lib\\asyncio\\events.py\", line 80, in _run\n",
      "    self._context.run(self._callback, *self._args)\n",
      "  File \"c:\\Users\\fafaf\\anaconda3\\envs\\tf\\lib\\asyncio\\selector_events.py\", line 115, in _read_from_self\n",
      "    data = self._ssock.recv(4096)\n",
      "ConnectionResetError: [WinError 10054] An existing connection was forcibly closed by the remote host\n",
      "Exception in callback BaseSelectorEventLoop._read_from_self()\n",
      "handle: <Handle BaseSelectorEventLoop._read_from_self()>\n",
      "Traceback (most recent call last):\n",
      "  File \"c:\\Users\\fafaf\\anaconda3\\envs\\tf\\lib\\asyncio\\events.py\", line 80, in _run\n",
      "    self._context.run(self._callback, *self._args)\n",
      "  File \"c:\\Users\\fafaf\\anaconda3\\envs\\tf\\lib\\asyncio\\selector_events.py\", line 115, in _read_from_self\n",
      "    data = self._ssock.recv(4096)\n",
      "ConnectionResetError: [WinError 10054] An existing connection was forcibly closed by the remote host\n",
      "Exception in callback BaseSelectorEventLoop._read_from_self()\n",
      "handle: <Handle BaseSelectorEventLoop._read_from_self()>\n",
      "Traceback (most recent call last):\n",
      "  File \"c:\\Users\\fafaf\\anaconda3\\envs\\tf\\lib\\asyncio\\events.py\", line 80, in _run\n",
      "    self._context.run(self._callback, *self._args)\n",
      "  File \"c:\\Users\\fafaf\\anaconda3\\envs\\tf\\lib\\asyncio\\selector_events.py\", line 115, in _read_from_self\n",
      "    data = self._ssock.recv(4096)\n",
      "ConnectionResetError: [WinError 10054] An existing connection was forcibly closed by the remote host\n",
      "Exception in callback BaseSelectorEventLoop._read_from_self()\n",
      "handle: <Handle BaseSelectorEventLoop._read_from_self()>\n",
      "Traceback (most recent call last):\n",
      "  File \"c:\\Users\\fafaf\\anaconda3\\envs\\tf\\lib\\asyncio\\events.py\", line 80, in _run\n",
      "    self._context.run(self._callback, *self._args)\n",
      "  File \"c:\\Users\\fafaf\\anaconda3\\envs\\tf\\lib\\asyncio\\selector_events.py\", line 115, in _read_from_self\n",
      "    data = self._ssock.recv(4096)\n",
      "ConnectionResetError: [WinError 10054] An existing connection was forcibly closed by the remote host\n",
      "Exception in callback BaseSelectorEventLoop._read_from_self()\n",
      "handle: <Handle BaseSelectorEventLoop._read_from_self()>\n",
      "Traceback (most recent call last):\n",
      "  File \"c:\\Users\\fafaf\\anaconda3\\envs\\tf\\lib\\asyncio\\events.py\", line 80, in _run\n",
      "    self._context.run(self._callback, *self._args)\n",
      "  File \"c:\\Users\\fafaf\\anaconda3\\envs\\tf\\lib\\asyncio\\selector_events.py\", line 115, in _read_from_self\n",
      "    data = self._ssock.recv(4096)\n",
      "ConnectionResetError: [WinError 10054] An existing connection was forcibly closed by the remote host\n",
      "Exception in callback BaseSelectorEventLoop._read_from_self()\n",
      "handle: <Handle BaseSelectorEventLoop._read_from_self()>\n",
      "Traceback (most recent call last):\n",
      "  File \"c:\\Users\\fafaf\\anaconda3\\envs\\tf\\lib\\asyncio\\events.py\", line 80, in _run\n",
      "    self._context.run(self._callback, *self._args)\n",
      "  File \"c:\\Users\\fafaf\\anaconda3\\envs\\tf\\lib\\asyncio\\selector_events.py\", line 115, in _read_from_self\n",
      "    data = self._ssock.recv(4096)\n",
      "ConnectionResetError: [WinError 10054] An existing connection was forcibly closed by the remote host\n",
      "Exception in callback BaseSelectorEventLoop._read_from_self()\n",
      "handle: <Handle BaseSelectorEventLoop._read_from_self()>\n",
      "Traceback (most recent call last):\n",
      "  File \"c:\\Users\\fafaf\\anaconda3\\envs\\tf\\lib\\asyncio\\events.py\", line 80, in _run\n",
      "    self._context.run(self._callback, *self._args)\n",
      "  File \"c:\\Users\\fafaf\\anaconda3\\envs\\tf\\lib\\asyncio\\selector_events.py\", line 115, in _read_from_self\n",
      "    data = self._ssock.recv(4096)\n",
      "ConnectionResetError: [WinError 10054] An existing connection was forcibly closed by the remote host\n",
      "Exception in callback BaseSelectorEventLoop._read_from_self()\n",
      "handle: <Handle BaseSelectorEventLoop._read_from_self()>\n",
      "Traceback (most recent call last):\n",
      "  File \"c:\\Users\\fafaf\\anaconda3\\envs\\tf\\lib\\asyncio\\events.py\", line 80, in _run\n",
      "    self._context.run(self._callback, *self._args)\n",
      "  File \"c:\\Users\\fafaf\\anaconda3\\envs\\tf\\lib\\asyncio\\selector_events.py\", line 115, in _read_from_self\n",
      "    data = self._ssock.recv(4096)\n",
      "ConnectionResetError: [WinError 10054] An existing connection was forcibly closed by the remote host\n",
      "Exception in callback BaseSelectorEventLoop._read_from_self()\n",
      "handle: <Handle BaseSelectorEventLoop._read_from_self()>\n",
      "Traceback (most recent call last):\n",
      "  File \"c:\\Users\\fafaf\\anaconda3\\envs\\tf\\lib\\asyncio\\events.py\", line 80, in _run\n",
      "    self._context.run(self._callback, *self._args)\n",
      "  File \"c:\\Users\\fafaf\\anaconda3\\envs\\tf\\lib\\asyncio\\selector_events.py\", line 115, in _read_from_self\n",
      "    data = self._ssock.recv(4096)\n",
      "ConnectionResetError: [WinError 10054] An existing connection was forcibly closed by the remote host\n",
      "Exception in callback BaseSelectorEventLoop._read_from_self()\n",
      "handle: <Handle BaseSelectorEventLoop._read_from_self()>\n",
      "Traceback (most recent call last):\n",
      "  File \"c:\\Users\\fafaf\\anaconda3\\envs\\tf\\lib\\asyncio\\events.py\", line 80, in _run\n",
      "    self._context.run(self._callback, *self._args)\n",
      "  File \"c:\\Users\\fafaf\\anaconda3\\envs\\tf\\lib\\asyncio\\selector_events.py\", line 115, in _read_from_self\n",
      "    data = self._ssock.recv(4096)\n",
      "ConnectionResetError: [WinError 10054] An existing connection was forcibly closed by the remote host\n",
      "Exception in callback BaseSelectorEventLoop._read_from_self()\n",
      "handle: <Handle BaseSelectorEventLoop._read_from_self()>\n",
      "Traceback (most recent call last):\n",
      "  File \"c:\\Users\\fafaf\\anaconda3\\envs\\tf\\lib\\asyncio\\events.py\", line 80, in _run\n",
      "    self._context.run(self._callback, *self._args)\n",
      "  File \"c:\\Users\\fafaf\\anaconda3\\envs\\tf\\lib\\asyncio\\selector_events.py\", line 115, in _read_from_self\n",
      "    data = self._ssock.recv(4096)\n",
      "ConnectionResetError: [WinError 10054] An existing connection was forcibly closed by the remote host\n",
      "Exception in callback BaseSelectorEventLoop._read_from_self()\n",
      "handle: <Handle BaseSelectorEventLoop._read_from_self()>\n",
      "Traceback (most recent call last):\n",
      "  File \"c:\\Users\\fafaf\\anaconda3\\envs\\tf\\lib\\asyncio\\events.py\", line 80, in _run\n",
      "    self._context.run(self._callback, *self._args)\n",
      "  File \"c:\\Users\\fafaf\\anaconda3\\envs\\tf\\lib\\asyncio\\selector_events.py\", line 115, in _read_from_self\n",
      "    data = self._ssock.recv(4096)\n",
      "ConnectionResetError: [WinError 10054] An existing connection was forcibly closed by the remote host\n",
      "Exception in callback BaseSelectorEventLoop._read_from_self()\n",
      "handle: <Handle BaseSelectorEventLoop._read_from_self()>\n",
      "Traceback (most recent call last):\n",
      "  File \"c:\\Users\\fafaf\\anaconda3\\envs\\tf\\lib\\asyncio\\events.py\", line 80, in _run\n",
      "    self._context.run(self._callback, *self._args)\n",
      "  File \"c:\\Users\\fafaf\\anaconda3\\envs\\tf\\lib\\asyncio\\selector_events.py\", line 115, in _read_from_self\n",
      "    data = self._ssock.recv(4096)\n",
      "ConnectionResetError: [WinError 10054] An existing connection was forcibly closed by the remote host\n",
      "Exception in callback BaseSelectorEventLoop._read_from_self()\n",
      "handle: <Handle BaseSelectorEventLoop._read_from_self()>\n",
      "Traceback (most recent call last):\n",
      "  File \"c:\\Users\\fafaf\\anaconda3\\envs\\tf\\lib\\asyncio\\events.py\", line 80, in _run\n",
      "    self._context.run(self._callback, *self._args)\n",
      "  File \"c:\\Users\\fafaf\\anaconda3\\envs\\tf\\lib\\asyncio\\selector_events.py\", line 115, in _read_from_self\n",
      "    data = self._ssock.recv(4096)\n",
      "ConnectionResetError: [WinError 10054] An existing connection was forcibly closed by the remote host\n",
      "Exception in callback BaseSelectorEventLoop._read_from_self()\n",
      "handle: <Handle BaseSelectorEventLoop._read_from_self()>\n",
      "Traceback (most recent call last):\n",
      "  File \"c:\\Users\\fafaf\\anaconda3\\envs\\tf\\lib\\asyncio\\events.py\", line 80, in _run\n",
      "    self._context.run(self._callback, *self._args)\n",
      "  File \"c:\\Users\\fafaf\\anaconda3\\envs\\tf\\lib\\asyncio\\selector_events.py\", line 115, in _read_from_self\n",
      "    data = self._ssock.recv(4096)\n",
      "ConnectionResetError: [WinError 10054] An existing connection was forcibly closed by the remote host\n",
      "Exception in callback BaseSelectorEventLoop._read_from_self()\n",
      "handle: <Handle BaseSelectorEventLoop._read_from_self()>\n",
      "Traceback (most recent call last):\n",
      "  File \"c:\\Users\\fafaf\\anaconda3\\envs\\tf\\lib\\asyncio\\events.py\", line 80, in _run\n",
      "    self._context.run(self._callback, *self._args)\n",
      "  File \"c:\\Users\\fafaf\\anaconda3\\envs\\tf\\lib\\asyncio\\selector_events.py\", line 115, in _read_from_self\n",
      "    data = self._ssock.recv(4096)\n",
      "ConnectionResetError: [WinError 10054] An existing connection was forcibly closed by the remote host\n",
      "Exception in callback BaseSelectorEventLoop._read_from_self()\n",
      "handle: <Handle BaseSelectorEventLoop._read_from_self()>\n",
      "Traceback (most recent call last):\n",
      "  File \"c:\\Users\\fafaf\\anaconda3\\envs\\tf\\lib\\asyncio\\events.py\", line 80, in _run\n",
      "    self._context.run(self._callback, *self._args)\n",
      "  File \"c:\\Users\\fafaf\\anaconda3\\envs\\tf\\lib\\asyncio\\selector_events.py\", line 115, in _read_from_self\n",
      "    data = self._ssock.recv(4096)\n",
      "ConnectionResetError: [WinError 10054] An existing connection was forcibly closed by the remote host\n",
      "Exception in callback BaseSelectorEventLoop._read_from_self()\n",
      "handle: <Handle BaseSelectorEventLoop._read_from_self()>\n",
      "Traceback (most recent call last):\n",
      "  File \"c:\\Users\\fafaf\\anaconda3\\envs\\tf\\lib\\asyncio\\events.py\", line 80, in _run\n",
      "    self._context.run(self._callback, *self._args)\n",
      "  File \"c:\\Users\\fafaf\\anaconda3\\envs\\tf\\lib\\asyncio\\selector_events.py\", line 115, in _read_from_self\n",
      "    data = self._ssock.recv(4096)\n",
      "ConnectionResetError: [WinError 10054] An existing connection was forcibly closed by the remote host\n",
      "Exception in callback BaseSelectorEventLoop._read_from_self()\n",
      "handle: <Handle BaseSelectorEventLoop._read_from_self()>\n",
      "Traceback (most recent call last):\n",
      "  File \"c:\\Users\\fafaf\\anaconda3\\envs\\tf\\lib\\asyncio\\events.py\", line 80, in _run\n",
      "    self._context.run(self._callback, *self._args)\n",
      "  File \"c:\\Users\\fafaf\\anaconda3\\envs\\tf\\lib\\asyncio\\selector_events.py\", line 115, in _read_from_self\n",
      "    data = self._ssock.recv(4096)\n",
      "ConnectionResetError: [WinError 10054] An existing connection was forcibly closed by the remote host\n",
      "Exception in callback BaseSelectorEventLoop._read_from_self()\n",
      "handle: <Handle BaseSelectorEventLoop._read_from_self()>\n",
      "Traceback (most recent call last):\n",
      "  File \"c:\\Users\\fafaf\\anaconda3\\envs\\tf\\lib\\asyncio\\events.py\", line 80, in _run\n",
      "    self._context.run(self._callback, *self._args)\n",
      "  File \"c:\\Users\\fafaf\\anaconda3\\envs\\tf\\lib\\asyncio\\selector_events.py\", line 115, in _read_from_self\n",
      "    data = self._ssock.recv(4096)\n",
      "ConnectionResetError: [WinError 10054] An existing connection was forcibly closed by the remote host\n",
      "Exception in callback BaseSelectorEventLoop._read_from_self()\n",
      "handle: <Handle BaseSelectorEventLoop._read_from_self()>\n",
      "Traceback (most recent call last):\n",
      "  File \"c:\\Users\\fafaf\\anaconda3\\envs\\tf\\lib\\asyncio\\events.py\", line 80, in _run\n",
      "    self._context.run(self._callback, *self._args)\n",
      "  File \"c:\\Users\\fafaf\\anaconda3\\envs\\tf\\lib\\asyncio\\selector_events.py\", line 115, in _read_from_self\n",
      "    data = self._ssock.recv(4096)\n",
      "ConnectionResetError: [WinError 10054] An existing connection was forcibly closed by the remote host\n",
      "Exception in callback BaseSelectorEventLoop._read_from_self()\n",
      "handle: <Handle BaseSelectorEventLoop._read_from_self()>\n",
      "Traceback (most recent call last):\n",
      "  File \"c:\\Users\\fafaf\\anaconda3\\envs\\tf\\lib\\asyncio\\events.py\", line 80, in _run\n",
      "    self._context.run(self._callback, *self._args)\n",
      "  File \"c:\\Users\\fafaf\\anaconda3\\envs\\tf\\lib\\asyncio\\selector_events.py\", line 115, in _read_from_self\n",
      "    data = self._ssock.recv(4096)\n",
      "ConnectionResetError: [WinError 10054] An existing connection was forcibly closed by the remote host\n",
      "Exception in callback BaseSelectorEventLoop._read_from_self()\n",
      "handle: <Handle BaseSelectorEventLoop._read_from_self()>\n",
      "Traceback (most recent call last):\n",
      "  File \"c:\\Users\\fafaf\\anaconda3\\envs\\tf\\lib\\asyncio\\events.py\", line 80, in _run\n",
      "    self._context.run(self._callback, *self._args)\n",
      "  File \"c:\\Users\\fafaf\\anaconda3\\envs\\tf\\lib\\asyncio\\selector_events.py\", line 115, in _read_from_self\n",
      "    data = self._ssock.recv(4096)\n",
      "ConnectionResetError: [WinError 10054] An existing connection was forcibly closed by the remote host\n",
      "Exception in callback BaseSelectorEventLoop._read_from_self()\n",
      "handle: <Handle BaseSelectorEventLoop._read_from_self()>\n",
      "Traceback (most recent call last):\n",
      "  File \"c:\\Users\\fafaf\\anaconda3\\envs\\tf\\lib\\asyncio\\events.py\", line 80, in _run\n",
      "    self._context.run(self._callback, *self._args)\n",
      "  File \"c:\\Users\\fafaf\\anaconda3\\envs\\tf\\lib\\asyncio\\selector_events.py\", line 115, in _read_from_self\n",
      "    data = self._ssock.recv(4096)\n",
      "ConnectionResetError: [WinError 10054] An existing connection was forcibly closed by the remote host\n",
      "Exception in callback BaseSelectorEventLoop._read_from_self()\n",
      "handle: <Handle BaseSelectorEventLoop._read_from_self()>\n",
      "Traceback (most recent call last):\n",
      "  File \"c:\\Users\\fafaf\\anaconda3\\envs\\tf\\lib\\asyncio\\events.py\", line 80, in _run\n",
      "    self._context.run(self._callback, *self._args)\n",
      "  File \"c:\\Users\\fafaf\\anaconda3\\envs\\tf\\lib\\asyncio\\selector_events.py\", line 115, in _read_from_self\n",
      "    data = self._ssock.recv(4096)\n",
      "ConnectionResetError: [WinError 10054] An existing connection was forcibly closed by the remote host\n",
      "Exception in callback BaseSelectorEventLoop._read_from_self()\n",
      "handle: <Handle BaseSelectorEventLoop._read_from_self()>\n",
      "Traceback (most recent call last):\n",
      "  File \"c:\\Users\\fafaf\\anaconda3\\envs\\tf\\lib\\asyncio\\events.py\", line 80, in _run\n",
      "    self._context.run(self._callback, *self._args)\n",
      "  File \"c:\\Users\\fafaf\\anaconda3\\envs\\tf\\lib\\asyncio\\selector_events.py\", line 115, in _read_from_self\n",
      "    data = self._ssock.recv(4096)\n",
      "ConnectionResetError: [WinError 10054] An existing connection was forcibly closed by the remote host\n",
      "Exception in callback BaseSelectorEventLoop._read_from_self()\n",
      "handle: <Handle BaseSelectorEventLoop._read_from_self()>\n",
      "Traceback (most recent call last):\n",
      "  File \"c:\\Users\\fafaf\\anaconda3\\envs\\tf\\lib\\asyncio\\events.py\", line 80, in _run\n",
      "    self._context.run(self._callback, *self._args)\n",
      "  File \"c:\\Users\\fafaf\\anaconda3\\envs\\tf\\lib\\asyncio\\selector_events.py\", line 115, in _read_from_self\n",
      "    data = self._ssock.recv(4096)\n",
      "ConnectionResetError: [WinError 10054] An existing connection was forcibly closed by the remote host\n",
      "Exception in callback BaseSelectorEventLoop._read_from_self()\n",
      "handle: <Handle BaseSelectorEventLoop._read_from_self()>\n",
      "Traceback (most recent call last):\n",
      "  File \"c:\\Users\\fafaf\\anaconda3\\envs\\tf\\lib\\asyncio\\events.py\", line 80, in _run\n",
      "    self._context.run(self._callback, *self._args)\n",
      "  File \"c:\\Users\\fafaf\\anaconda3\\envs\\tf\\lib\\asyncio\\selector_events.py\", line 115, in _read_from_self\n",
      "    data = self._ssock.recv(4096)\n",
      "ConnectionResetError: [WinError 10054] An existing connection was forcibly closed by the remote host\n",
      "Exception in callback BaseSelectorEventLoop._read_from_self()\n",
      "handle: <Handle BaseSelectorEventLoop._read_from_self()>\n",
      "Traceback (most recent call last):\n",
      "  File \"c:\\Users\\fafaf\\anaconda3\\envs\\tf\\lib\\asyncio\\events.py\", line 80, in _run\n",
      "    self._context.run(self._callback, *self._args)\n",
      "  File \"c:\\Users\\fafaf\\anaconda3\\envs\\tf\\lib\\asyncio\\selector_events.py\", line 115, in _read_from_self\n",
      "    data = self._ssock.recv(4096)\n",
      "ConnectionResetError: [WinError 10054] An existing connection was forcibly closed by the remote host\n",
      "Exception in callback BaseSelectorEventLoop._read_from_self()\n",
      "handle: <Handle BaseSelectorEventLoop._read_from_self()>\n",
      "Traceback (most recent call last):\n",
      "  File \"c:\\Users\\fafaf\\anaconda3\\envs\\tf\\lib\\asyncio\\events.py\", line 80, in _run\n",
      "    self._context.run(self._callback, *self._args)\n",
      "  File \"c:\\Users\\fafaf\\anaconda3\\envs\\tf\\lib\\asyncio\\selector_events.py\", line 115, in _read_from_self\n",
      "    data = self._ssock.recv(4096)\n",
      "ConnectionResetError: [WinError 10054] An existing connection was forcibly closed by the remote host\n",
      "Exception in callback BaseSelectorEventLoop._read_from_self()\n",
      "handle: <Handle BaseSelectorEventLoop._read_from_self()>\n",
      "Traceback (most recent call last):\n",
      "  File \"c:\\Users\\fafaf\\anaconda3\\envs\\tf\\lib\\asyncio\\events.py\", line 80, in _run\n",
      "    self._context.run(self._callback, *self._args)\n",
      "  File \"c:\\Users\\fafaf\\anaconda3\\envs\\tf\\lib\\asyncio\\selector_events.py\", line 115, in _read_from_self\n",
      "    data = self._ssock.recv(4096)\n",
      "ConnectionResetError: [WinError 10054] An existing connection was forcibly closed by the remote host\n",
      "Exception in callback BaseSelectorEventLoop._read_from_self()\n",
      "handle: <Handle BaseSelectorEventLoop._read_from_self()>\n",
      "Traceback (most recent call last):\n",
      "  File \"c:\\Users\\fafaf\\anaconda3\\envs\\tf\\lib\\asyncio\\events.py\", line 80, in _run\n",
      "    self._context.run(self._callback, *self._args)\n",
      "  File \"c:\\Users\\fafaf\\anaconda3\\envs\\tf\\lib\\asyncio\\selector_events.py\", line 115, in _read_from_self\n",
      "    data = self._ssock.recv(4096)\n",
      "ConnectionResetError: [WinError 10054] An existing connection was forcibly closed by the remote host\n",
      "Exception in callback BaseSelectorEventLoop._read_from_self()\n",
      "handle: <Handle BaseSelectorEventLoop._read_from_self()>\n",
      "Traceback (most recent call last):\n",
      "  File \"c:\\Users\\fafaf\\anaconda3\\envs\\tf\\lib\\asyncio\\events.py\", line 80, in _run\n",
      "    self._context.run(self._callback, *self._args)\n",
      "  File \"c:\\Users\\fafaf\\anaconda3\\envs\\tf\\lib\\asyncio\\selector_events.py\", line 115, in _read_from_self\n",
      "    data = self._ssock.recv(4096)\n",
      "ConnectionResetError: [WinError 10054] An existing connection was forcibly closed by the remote host\n",
      "Exception in callback BaseSelectorEventLoop._read_from_self()\n",
      "handle: <Handle BaseSelectorEventLoop._read_from_self()>\n",
      "Traceback (most recent call last):\n",
      "  File \"c:\\Users\\fafaf\\anaconda3\\envs\\tf\\lib\\asyncio\\events.py\", line 80, in _run\n",
      "    self._context.run(self._callback, *self._args)\n",
      "  File \"c:\\Users\\fafaf\\anaconda3\\envs\\tf\\lib\\asyncio\\selector_events.py\", line 115, in _read_from_self\n",
      "    data = self._ssock.recv(4096)\n",
      "ConnectionResetError: [WinError 10054] An existing connection was forcibly closed by the remote host\n",
      "Exception in callback BaseSelectorEventLoop._read_from_self()\n",
      "handle: <Handle BaseSelectorEventLoop._read_from_self()>\n",
      "Traceback (most recent call last):\n",
      "  File \"c:\\Users\\fafaf\\anaconda3\\envs\\tf\\lib\\asyncio\\events.py\", line 80, in _run\n",
      "    self._context.run(self._callback, *self._args)\n",
      "  File \"c:\\Users\\fafaf\\anaconda3\\envs\\tf\\lib\\asyncio\\selector_events.py\", line 115, in _read_from_self\n",
      "    data = self._ssock.recv(4096)\n",
      "ConnectionResetError: [WinError 10054] An existing connection was forcibly closed by the remote host\n",
      "Exception in callback BaseSelectorEventLoop._read_from_self()\n",
      "handle: <Handle BaseSelectorEventLoop._read_from_self()>\n",
      "Traceback (most recent call last):\n",
      "  File \"c:\\Users\\fafaf\\anaconda3\\envs\\tf\\lib\\asyncio\\events.py\", line 80, in _run\n",
      "    self._context.run(self._callback, *self._args)\n",
      "  File \"c:\\Users\\fafaf\\anaconda3\\envs\\tf\\lib\\asyncio\\selector_events.py\", line 115, in _read_from_self\n",
      "    data = self._ssock.recv(4096)\n",
      "ConnectionResetError: [WinError 10054] An existing connection was forcibly closed by the remote host\n",
      "Exception in callback BaseSelectorEventLoop._read_from_self()\n",
      "handle: <Handle BaseSelectorEventLoop._read_from_self()>\n",
      "Traceback (most recent call last):\n",
      "  File \"c:\\Users\\fafaf\\anaconda3\\envs\\tf\\lib\\asyncio\\events.py\", line 80, in _run\n",
      "    self._context.run(self._callback, *self._args)\n",
      "  File \"c:\\Users\\fafaf\\anaconda3\\envs\\tf\\lib\\asyncio\\selector_events.py\", line 115, in _read_from_self\n",
      "    data = self._ssock.recv(4096)\n",
      "ConnectionResetError: [WinError 10054] An existing connection was forcibly closed by the remote host\n",
      "Exception in callback BaseSelectorEventLoop._read_from_self()\n",
      "handle: <Handle BaseSelectorEventLoop._read_from_self()>\n",
      "Traceback (most recent call last):\n",
      "  File \"c:\\Users\\fafaf\\anaconda3\\envs\\tf\\lib\\asyncio\\events.py\", line 80, in _run\n",
      "    self._context.run(self._callback, *self._args)\n",
      "  File \"c:\\Users\\fafaf\\anaconda3\\envs\\tf\\lib\\asyncio\\selector_events.py\", line 115, in _read_from_self\n",
      "    data = self._ssock.recv(4096)\n",
      "ConnectionResetError: [WinError 10054] An existing connection was forcibly closed by the remote host\n",
      "Exception in callback BaseSelectorEventLoop._read_from_self()\n",
      "handle: <Handle BaseSelectorEventLoop._read_from_self()>\n",
      "Traceback (most recent call last):\n",
      "  File \"c:\\Users\\fafaf\\anaconda3\\envs\\tf\\lib\\asyncio\\events.py\", line 80, in _run\n",
      "    self._context.run(self._callback, *self._args)\n",
      "  File \"c:\\Users\\fafaf\\anaconda3\\envs\\tf\\lib\\asyncio\\selector_events.py\", line 115, in _read_from_self\n",
      "    data = self._ssock.recv(4096)\n",
      "ConnectionResetError: [WinError 10054] An existing connection was forcibly closed by the remote host\n",
      "Exception in callback BaseSelectorEventLoop._read_from_self()\n",
      "handle: <Handle BaseSelectorEventLoop._read_from_self()>\n",
      "Traceback (most recent call last):\n",
      "  File \"c:\\Users\\fafaf\\anaconda3\\envs\\tf\\lib\\asyncio\\events.py\", line 80, in _run\n",
      "    self._context.run(self._callback, *self._args)\n",
      "  File \"c:\\Users\\fafaf\\anaconda3\\envs\\tf\\lib\\asyncio\\selector_events.py\", line 115, in _read_from_self\n",
      "    data = self._ssock.recv(4096)\n",
      "ConnectionResetError: [WinError 10054] An existing connection was forcibly closed by the remote host\n",
      "Exception in callback BaseSelectorEventLoop._read_from_self()\n",
      "handle: <Handle BaseSelectorEventLoop._read_from_self()>\n",
      "Traceback (most recent call last):\n",
      "  File \"c:\\Users\\fafaf\\anaconda3\\envs\\tf\\lib\\asyncio\\events.py\", line 80, in _run\n",
      "    self._context.run(self._callback, *self._args)\n",
      "  File \"c:\\Users\\fafaf\\anaconda3\\envs\\tf\\lib\\asyncio\\selector_events.py\", line 115, in _read_from_self\n",
      "    data = self._ssock.recv(4096)\n",
      "ConnectionResetError: [WinError 10054] An existing connection was forcibly closed by the remote host\n",
      "Exception in callback BaseSelectorEventLoop._read_from_self()\n",
      "handle: <Handle BaseSelectorEventLoop._read_from_self()>\n",
      "Traceback (most recent call last):\n",
      "  File \"c:\\Users\\fafaf\\anaconda3\\envs\\tf\\lib\\asyncio\\events.py\", line 80, in _run\n",
      "    self._context.run(self._callback, *self._args)\n",
      "  File \"c:\\Users\\fafaf\\anaconda3\\envs\\tf\\lib\\asyncio\\selector_events.py\", line 115, in _read_from_self\n",
      "    data = self._ssock.recv(4096)\n",
      "ConnectionResetError: [WinError 10054] An existing connection was forcibly closed by the remote host\n",
      "Exception in callback BaseSelectorEventLoop._read_from_self()\n",
      "handle: <Handle BaseSelectorEventLoop._read_from_self()>\n",
      "Traceback (most recent call last):\n",
      "  File \"c:\\Users\\fafaf\\anaconda3\\envs\\tf\\lib\\asyncio\\events.py\", line 80, in _run\n",
      "    self._context.run(self._callback, *self._args)\n",
      "  File \"c:\\Users\\fafaf\\anaconda3\\envs\\tf\\lib\\asyncio\\selector_events.py\", line 115, in _read_from_self\n",
      "    data = self._ssock.recv(4096)\n",
      "ConnectionResetError: [WinError 10054] An existing connection was forcibly closed by the remote host\n",
      "Exception in callback BaseSelectorEventLoop._read_from_self()\n",
      "handle: <Handle BaseSelectorEventLoop._read_from_self()>\n",
      "Traceback (most recent call last):\n",
      "  File \"c:\\Users\\fafaf\\anaconda3\\envs\\tf\\lib\\asyncio\\events.py\", line 80, in _run\n",
      "    self._context.run(self._callback, *self._args)\n",
      "  File \"c:\\Users\\fafaf\\anaconda3\\envs\\tf\\lib\\asyncio\\selector_events.py\", line 115, in _read_from_self\n",
      "    data = self._ssock.recv(4096)\n",
      "ConnectionResetError: [WinError 10054] An existing connection was forcibly closed by the remote host\n",
      "Exception in callback BaseSelectorEventLoop._read_from_self()\n",
      "handle: <Handle BaseSelectorEventLoop._read_from_self()>\n",
      "Traceback (most recent call last):\n",
      "  File \"c:\\Users\\fafaf\\anaconda3\\envs\\tf\\lib\\asyncio\\events.py\", line 80, in _run\n",
      "    self._context.run(self._callback, *self._args)\n",
      "  File \"c:\\Users\\fafaf\\anaconda3\\envs\\tf\\lib\\asyncio\\selector_events.py\", line 115, in _read_from_self\n",
      "    data = self._ssock.recv(4096)\n",
      "ConnectionResetError: [WinError 10054] An existing connection was forcibly closed by the remote host\n",
      "Exception in callback BaseSelectorEventLoop._read_from_self()\n",
      "handle: <Handle BaseSelectorEventLoop._read_from_self()>\n",
      "Traceback (most recent call last):\n",
      "  File \"c:\\Users\\fafaf\\anaconda3\\envs\\tf\\lib\\asyncio\\events.py\", line 80, in _run\n",
      "    self._context.run(self._callback, *self._args)\n",
      "  File \"c:\\Users\\fafaf\\anaconda3\\envs\\tf\\lib\\asyncio\\selector_events.py\", line 115, in _read_from_self\n",
      "    data = self._ssock.recv(4096)\n",
      "ConnectionResetError: [WinError 10054] An existing connection was forcibly closed by the remote host\n",
      "Exception in callback BaseSelectorEventLoop._read_from_self()\n",
      "handle: <Handle BaseSelectorEventLoop._read_from_self()>\n",
      "Traceback (most recent call last):\n",
      "  File \"c:\\Users\\fafaf\\anaconda3\\envs\\tf\\lib\\asyncio\\events.py\", line 80, in _run\n",
      "    self._context.run(self._callback, *self._args)\n",
      "  File \"c:\\Users\\fafaf\\anaconda3\\envs\\tf\\lib\\asyncio\\selector_events.py\", line 115, in _read_from_self\n",
      "    data = self._ssock.recv(4096)\n",
      "ConnectionResetError: [WinError 10054] An existing connection was forcibly closed by the remote host\n",
      "Exception in callback BaseSelectorEventLoop._read_from_self()\n",
      "handle: <Handle BaseSelectorEventLoop._read_from_self()>\n",
      "Traceback (most recent call last):\n",
      "  File \"c:\\Users\\fafaf\\anaconda3\\envs\\tf\\lib\\asyncio\\events.py\", line 80, in _run\n",
      "    self._context.run(self._callback, *self._args)\n",
      "  File \"c:\\Users\\fafaf\\anaconda3\\envs\\tf\\lib\\asyncio\\selector_events.py\", line 115, in _read_from_self\n",
      "    data = self._ssock.recv(4096)\n",
      "ConnectionResetError: [WinError 10054] An existing connection was forcibly closed by the remote host\n",
      "Exception in callback BaseSelectorEventLoop._read_from_self()\n",
      "handle: <Handle BaseSelectorEventLoop._read_from_self()>\n",
      "Traceback (most recent call last):\n",
      "  File \"c:\\Users\\fafaf\\anaconda3\\envs\\tf\\lib\\asyncio\\events.py\", line 80, in _run\n",
      "    self._context.run(self._callback, *self._args)\n",
      "  File \"c:\\Users\\fafaf\\anaconda3\\envs\\tf\\lib\\asyncio\\selector_events.py\", line 115, in _read_from_self\n",
      "    data = self._ssock.recv(4096)\n",
      "ConnectionResetError: [WinError 10054] An existing connection was forcibly closed by the remote host\n",
      "Exception in callback BaseSelectorEventLoop._read_from_self()\n",
      "handle: <Handle BaseSelectorEventLoop._read_from_self()>\n",
      "Traceback (most recent call last):\n",
      "  File \"c:\\Users\\fafaf\\anaconda3\\envs\\tf\\lib\\asyncio\\events.py\", line 80, in _run\n",
      "    self._context.run(self._callback, *self._args)\n",
      "  File \"c:\\Users\\fafaf\\anaconda3\\envs\\tf\\lib\\asyncio\\selector_events.py\", line 115, in _read_from_self\n",
      "    data = self._ssock.recv(4096)\n",
      "ConnectionResetError: [WinError 10054] An existing connection was forcibly closed by the remote host\n",
      "Exception in callback BaseSelectorEventLoop._read_from_self()\n",
      "handle: <Handle BaseSelectorEventLoop._read_from_self()>\n",
      "Traceback (most recent call last):\n",
      "  File \"c:\\Users\\fafaf\\anaconda3\\envs\\tf\\lib\\asyncio\\events.py\", line 80, in _run\n",
      "    self._context.run(self._callback, *self._args)\n",
      "  File \"c:\\Users\\fafaf\\anaconda3\\envs\\tf\\lib\\asyncio\\selector_events.py\", line 115, in _read_from_self\n",
      "    data = self._ssock.recv(4096)\n",
      "ConnectionResetError: [WinError 10054] An existing connection was forcibly closed by the remote host\n",
      "Exception in callback BaseSelectorEventLoop._read_from_self()\n",
      "handle: <Handle BaseSelectorEventLoop._read_from_self()>\n",
      "Traceback (most recent call last):\n",
      "  File \"c:\\Users\\fafaf\\anaconda3\\envs\\tf\\lib\\asyncio\\events.py\", line 80, in _run\n",
      "    self._context.run(self._callback, *self._args)\n",
      "  File \"c:\\Users\\fafaf\\anaconda3\\envs\\tf\\lib\\asyncio\\selector_events.py\", line 115, in _read_from_self\n",
      "    data = self._ssock.recv(4096)\n",
      "ConnectionResetError: [WinError 10054] An existing connection was forcibly closed by the remote host\n",
      "Exception in callback BaseSelectorEventLoop._read_from_self()\n",
      "handle: <Handle BaseSelectorEventLoop._read_from_self()>\n",
      "Traceback (most recent call last):\n",
      "  File \"c:\\Users\\fafaf\\anaconda3\\envs\\tf\\lib\\asyncio\\events.py\", line 80, in _run\n",
      "    self._context.run(self._callback, *self._args)\n",
      "  File \"c:\\Users\\fafaf\\anaconda3\\envs\\tf\\lib\\asyncio\\selector_events.py\", line 115, in _read_from_self\n",
      "    data = self._ssock.recv(4096)\n",
      "ConnectionResetError: [WinError 10054] An existing connection was forcibly closed by the remote host\n",
      "Exception in callback BaseSelectorEventLoop._read_from_self()\n",
      "handle: <Handle BaseSelectorEventLoop._read_from_self()>\n",
      "Traceback (most recent call last):\n",
      "  File \"c:\\Users\\fafaf\\anaconda3\\envs\\tf\\lib\\asyncio\\events.py\", line 80, in _run\n",
      "    self._context.run(self._callback, *self._args)\n",
      "  File \"c:\\Users\\fafaf\\anaconda3\\envs\\tf\\lib\\asyncio\\selector_events.py\", line 115, in _read_from_self\n",
      "    data = self._ssock.recv(4096)\n",
      "ConnectionResetError: [WinError 10054] An existing connection was forcibly closed by the remote host\n",
      "Exception in callback BaseSelectorEventLoop._read_from_self()\n",
      "handle: <Handle BaseSelectorEventLoop._read_from_self()>\n",
      "Traceback (most recent call last):\n",
      "  File \"c:\\Users\\fafaf\\anaconda3\\envs\\tf\\lib\\asyncio\\events.py\", line 80, in _run\n",
      "    self._context.run(self._callback, *self._args)\n",
      "  File \"c:\\Users\\fafaf\\anaconda3\\envs\\tf\\lib\\asyncio\\selector_events.py\", line 115, in _read_from_self\n",
      "    data = self._ssock.recv(4096)\n",
      "ConnectionResetError: [WinError 10054] An existing connection was forcibly closed by the remote host\n",
      "Exception in callback BaseSelectorEventLoop._read_from_self()\n",
      "handle: <Handle BaseSelectorEventLoop._read_from_self()>\n",
      "Traceback (most recent call last):\n",
      "  File \"c:\\Users\\fafaf\\anaconda3\\envs\\tf\\lib\\asyncio\\events.py\", line 80, in _run\n",
      "    self._context.run(self._callback, *self._args)\n",
      "  File \"c:\\Users\\fafaf\\anaconda3\\envs\\tf\\lib\\asyncio\\selector_events.py\", line 115, in _read_from_self\n",
      "    data = self._ssock.recv(4096)\n",
      "ConnectionResetError: [WinError 10054] An existing connection was forcibly closed by the remote host\n",
      "Exception in callback BaseSelectorEventLoop._read_from_self()\n",
      "handle: <Handle BaseSelectorEventLoop._read_from_self()>\n",
      "Traceback (most recent call last):\n",
      "  File \"c:\\Users\\fafaf\\anaconda3\\envs\\tf\\lib\\asyncio\\events.py\", line 80, in _run\n",
      "    self._context.run(self._callback, *self._args)\n",
      "  File \"c:\\Users\\fafaf\\anaconda3\\envs\\tf\\lib\\asyncio\\selector_events.py\", line 115, in _read_from_self\n",
      "    data = self._ssock.recv(4096)\n",
      "ConnectionResetError: [WinError 10054] An existing connection was forcibly closed by the remote host\n",
      "Exception in callback BaseSelectorEventLoop._read_from_self()\n",
      "handle: <Handle BaseSelectorEventLoop._read_from_self()>\n",
      "Traceback (most recent call last):\n",
      "  File \"c:\\Users\\fafaf\\anaconda3\\envs\\tf\\lib\\asyncio\\events.py\", line 80, in _run\n",
      "    self._context.run(self._callback, *self._args)\n",
      "  File \"c:\\Users\\fafaf\\anaconda3\\envs\\tf\\lib\\asyncio\\selector_events.py\", line 115, in _read_from_self\n",
      "    data = self._ssock.recv(4096)\n",
      "ConnectionResetError: [WinError 10054] An existing connection was forcibly closed by the remote host\n",
      "Exception in callback BaseSelectorEventLoop._read_from_self()\n",
      "handle: <Handle BaseSelectorEventLoop._read_from_self()>\n",
      "Traceback (most recent call last):\n",
      "  File \"c:\\Users\\fafaf\\anaconda3\\envs\\tf\\lib\\asyncio\\events.py\", line 80, in _run\n",
      "    self._context.run(self._callback, *self._args)\n",
      "  File \"c:\\Users\\fafaf\\anaconda3\\envs\\tf\\lib\\asyncio\\selector_events.py\", line 115, in _read_from_self\n",
      "    data = self._ssock.recv(4096)\n",
      "ConnectionResetError: [WinError 10054] An existing connection was forcibly closed by the remote host\n",
      "Exception in callback BaseSelectorEventLoop._read_from_self()\n",
      "handle: <Handle BaseSelectorEventLoop._read_from_self()>\n",
      "Traceback (most recent call last):\n",
      "  File \"c:\\Users\\fafaf\\anaconda3\\envs\\tf\\lib\\asyncio\\events.py\", line 80, in _run\n",
      "    self._context.run(self._callback, *self._args)\n",
      "  File \"c:\\Users\\fafaf\\anaconda3\\envs\\tf\\lib\\asyncio\\selector_events.py\", line 115, in _read_from_self\n",
      "    data = self._ssock.recv(4096)\n",
      "ConnectionResetError: [WinError 10054] An existing connection was forcibly closed by the remote host\n",
      "Exception in callback BaseSelectorEventLoop._read_from_self()\n",
      "handle: <Handle BaseSelectorEventLoop._read_from_self()>\n",
      "Traceback (most recent call last):\n",
      "  File \"c:\\Users\\fafaf\\anaconda3\\envs\\tf\\lib\\asyncio\\events.py\", line 80, in _run\n",
      "    self._context.run(self._callback, *self._args)\n",
      "  File \"c:\\Users\\fafaf\\anaconda3\\envs\\tf\\lib\\asyncio\\selector_events.py\", line 115, in _read_from_self\n",
      "    data = self._ssock.recv(4096)\n",
      "ConnectionResetError: [WinError 10054] An existing connection was forcibly closed by the remote host\n",
      "Exception in callback BaseSelectorEventLoop._read_from_self()\n",
      "handle: <Handle BaseSelectorEventLoop._read_from_self()>\n",
      "Traceback (most recent call last):\n",
      "  File \"c:\\Users\\fafaf\\anaconda3\\envs\\tf\\lib\\asyncio\\events.py\", line 80, in _run\n",
      "    self._context.run(self._callback, *self._args)\n",
      "  File \"c:\\Users\\fafaf\\anaconda3\\envs\\tf\\lib\\asyncio\\selector_events.py\", line 115, in _read_from_self\n",
      "    data = self._ssock.recv(4096)\n",
      "ConnectionResetError: [WinError 10054] An existing connection was forcibly closed by the remote host\n",
      "Exception in callback BaseSelectorEventLoop._read_from_self()\n",
      "handle: <Handle BaseSelectorEventLoop._read_from_self()>\n",
      "Traceback (most recent call last):\n",
      "  File \"c:\\Users\\fafaf\\anaconda3\\envs\\tf\\lib\\asyncio\\events.py\", line 80, in _run\n",
      "    self._context.run(self._callback, *self._args)\n",
      "  File \"c:\\Users\\fafaf\\anaconda3\\envs\\tf\\lib\\asyncio\\selector_events.py\", line 115, in _read_from_self\n",
      "    data = self._ssock.recv(4096)\n",
      "ConnectionResetError: [WinError 10054] An existing connection was forcibly closed by the remote host\n",
      "Exception in callback BaseSelectorEventLoop._read_from_self()\n",
      "handle: <Handle BaseSelectorEventLoop._read_from_self()>\n",
      "Traceback (most recent call last):\n",
      "  File \"c:\\Users\\fafaf\\anaconda3\\envs\\tf\\lib\\asyncio\\events.py\", line 80, in _run\n",
      "    self._context.run(self._callback, *self._args)\n",
      "  File \"c:\\Users\\fafaf\\anaconda3\\envs\\tf\\lib\\asyncio\\selector_events.py\", line 115, in _read_from_self\n",
      "    data = self._ssock.recv(4096)\n",
      "ConnectionResetError: [WinError 10054] An existing connection was forcibly closed by the remote host\n",
      "Exception in callback BaseSelectorEventLoop._read_from_self()\n",
      "handle: <Handle BaseSelectorEventLoop._read_from_self()>\n",
      "Traceback (most recent call last):\n",
      "  File \"c:\\Users\\fafaf\\anaconda3\\envs\\tf\\lib\\asyncio\\events.py\", line 80, in _run\n",
      "    self._context.run(self._callback, *self._args)\n",
      "  File \"c:\\Users\\fafaf\\anaconda3\\envs\\tf\\lib\\asyncio\\selector_events.py\", line 115, in _read_from_self\n",
      "    data = self._ssock.recv(4096)\n",
      "ConnectionResetError: [WinError 10054] An existing connection was forcibly closed by the remote host\n",
      "Exception in callback BaseSelectorEventLoop._read_from_self()\n",
      "handle: <Handle BaseSelectorEventLoop._read_from_self()>\n",
      "Traceback (most recent call last):\n",
      "  File \"c:\\Users\\fafaf\\anaconda3\\envs\\tf\\lib\\asyncio\\events.py\", line 80, in _run\n",
      "    self._context.run(self._callback, *self._args)\n",
      "  File \"c:\\Users\\fafaf\\anaconda3\\envs\\tf\\lib\\asyncio\\selector_events.py\", line 115, in _read_from_self\n",
      "    data = self._ssock.recv(4096)\n",
      "ConnectionResetError: [WinError 10054] An existing connection was forcibly closed by the remote host\n",
      "Exception in callback BaseSelectorEventLoop._read_from_self()\n",
      "handle: <Handle BaseSelectorEventLoop._read_from_self()>\n",
      "Traceback (most recent call last):\n",
      "  File \"c:\\Users\\fafaf\\anaconda3\\envs\\tf\\lib\\asyncio\\events.py\", line 80, in _run\n",
      "    self._context.run(self._callback, *self._args)\n",
      "  File \"c:\\Users\\fafaf\\anaconda3\\envs\\tf\\lib\\asyncio\\selector_events.py\", line 115, in _read_from_self\n",
      "    data = self._ssock.recv(4096)\n",
      "ConnectionResetError: [WinError 10054] An existing connection was forcibly closed by the remote host\n",
      "Exception in callback BaseSelectorEventLoop._read_from_self()\n",
      "handle: <Handle BaseSelectorEventLoop._read_from_self()>\n",
      "Traceback (most recent call last):\n",
      "  File \"c:\\Users\\fafaf\\anaconda3\\envs\\tf\\lib\\asyncio\\events.py\", line 80, in _run\n",
      "    self._context.run(self._callback, *self._args)\n",
      "  File \"c:\\Users\\fafaf\\anaconda3\\envs\\tf\\lib\\asyncio\\selector_events.py\", line 115, in _read_from_self\n",
      "    data = self._ssock.recv(4096)\n",
      "ConnectionResetError: [WinError 10054] An existing connection was forcibly closed by the remote host\n",
      "Exception in callback BaseSelectorEventLoop._read_from_self()\n",
      "handle: <Handle BaseSelectorEventLoop._read_from_self()>\n",
      "Traceback (most recent call last):\n",
      "  File \"c:\\Users\\fafaf\\anaconda3\\envs\\tf\\lib\\asyncio\\events.py\", line 80, in _run\n",
      "    self._context.run(self._callback, *self._args)\n",
      "  File \"c:\\Users\\fafaf\\anaconda3\\envs\\tf\\lib\\asyncio\\selector_events.py\", line 115, in _read_from_self\n",
      "    data = self._ssock.recv(4096)\n",
      "ConnectionResetError: [WinError 10054] An existing connection was forcibly closed by the remote host\n",
      "Exception in callback BaseSelectorEventLoop._read_from_self()\n",
      "handle: <Handle BaseSelectorEventLoop._read_from_self()>\n",
      "Traceback (most recent call last):\n",
      "  File \"c:\\Users\\fafaf\\anaconda3\\envs\\tf\\lib\\asyncio\\events.py\", line 80, in _run\n",
      "    self._context.run(self._callback, *self._args)\n",
      "  File \"c:\\Users\\fafaf\\anaconda3\\envs\\tf\\lib\\asyncio\\selector_events.py\", line 115, in _read_from_self\n",
      "    data = self._ssock.recv(4096)\n",
      "ConnectionResetError: [WinError 10054] An existing connection was forcibly closed by the remote host\n",
      "Exception in callback BaseSelectorEventLoop._read_from_self()\n",
      "handle: <Handle BaseSelectorEventLoop._read_from_self()>\n",
      "Traceback (most recent call last):\n",
      "  File \"c:\\Users\\fafaf\\anaconda3\\envs\\tf\\lib\\asyncio\\events.py\", line 80, in _run\n",
      "    self._context.run(self._callback, *self._args)\n",
      "  File \"c:\\Users\\fafaf\\anaconda3\\envs\\tf\\lib\\asyncio\\selector_events.py\", line 115, in _read_from_self\n",
      "    data = self._ssock.recv(4096)\n",
      "ConnectionResetError: [WinError 10054] An existing connection was forcibly closed by the remote host\n",
      "Exception in callback BaseSelectorEventLoop._read_from_self()\n",
      "handle: <Handle BaseSelectorEventLoop._read_from_self()>\n",
      "Traceback (most recent call last):\n",
      "  File \"c:\\Users\\fafaf\\anaconda3\\envs\\tf\\lib\\asyncio\\events.py\", line 80, in _run\n",
      "    self._context.run(self._callback, *self._args)\n",
      "  File \"c:\\Users\\fafaf\\anaconda3\\envs\\tf\\lib\\asyncio\\selector_events.py\", line 115, in _read_from_self\n",
      "    data = self._ssock.recv(4096)\n",
      "ConnectionResetError: [WinError 10054] An existing connection was forcibly closed by the remote host\n",
      "Exception in callback BaseSelectorEventLoop._read_from_self()\n",
      "handle: <Handle BaseSelectorEventLoop._read_from_self()>\n",
      "Traceback (most recent call last):\n",
      "  File \"c:\\Users\\fafaf\\anaconda3\\envs\\tf\\lib\\asyncio\\events.py\", line 80, in _run\n",
      "    self._context.run(self._callback, *self._args)\n",
      "  File \"c:\\Users\\fafaf\\anaconda3\\envs\\tf\\lib\\asyncio\\selector_events.py\", line 115, in _read_from_self\n",
      "    data = self._ssock.recv(4096)\n",
      "ConnectionResetError: [WinError 10054] An existing connection was forcibly closed by the remote host\n",
      "Exception in callback BaseSelectorEventLoop._read_from_self()\n",
      "handle: <Handle BaseSelectorEventLoop._read_from_self()>\n",
      "Traceback (most recent call last):\n",
      "  File \"c:\\Users\\fafaf\\anaconda3\\envs\\tf\\lib\\asyncio\\events.py\", line 80, in _run\n",
      "    self._context.run(self._callback, *self._args)\n",
      "  File \"c:\\Users\\fafaf\\anaconda3\\envs\\tf\\lib\\asyncio\\selector_events.py\", line 115, in _read_from_self\n",
      "    data = self._ssock.recv(4096)\n",
      "ConnectionResetError: [WinError 10054] An existing connection was forcibly closed by the remote host\n",
      "Exception in callback BaseSelectorEventLoop._read_from_self()\n",
      "handle: <Handle BaseSelectorEventLoop._read_from_self()>\n",
      "Traceback (most recent call last):\n",
      "  File \"c:\\Users\\fafaf\\anaconda3\\envs\\tf\\lib\\asyncio\\events.py\", line 80, in _run\n",
      "    self._context.run(self._callback, *self._args)\n",
      "  File \"c:\\Users\\fafaf\\anaconda3\\envs\\tf\\lib\\asyncio\\selector_events.py\", line 115, in _read_from_self\n",
      "    data = self._ssock.recv(4096)\n",
      "ConnectionResetError: [WinError 10054] An existing connection was forcibly closed by the remote host\n",
      "Exception in callback BaseSelectorEventLoop._read_from_self()\n",
      "handle: <Handle BaseSelectorEventLoop._read_from_self()>\n",
      "Traceback (most recent call last):\n",
      "  File \"c:\\Users\\fafaf\\anaconda3\\envs\\tf\\lib\\asyncio\\events.py\", line 80, in _run\n",
      "    self._context.run(self._callback, *self._args)\n",
      "  File \"c:\\Users\\fafaf\\anaconda3\\envs\\tf\\lib\\asyncio\\selector_events.py\", line 115, in _read_from_self\n",
      "    data = self._ssock.recv(4096)\n",
      "ConnectionResetError: [WinError 10054] An existing connection was forcibly closed by the remote host\n",
      "Exception in callback BaseSelectorEventLoop._read_from_self()\n",
      "handle: <Handle BaseSelectorEventLoop._read_from_self()>\n",
      "Traceback (most recent call last):\n",
      "  File \"c:\\Users\\fafaf\\anaconda3\\envs\\tf\\lib\\asyncio\\events.py\", line 80, in _run\n",
      "    self._context.run(self._callback, *self._args)\n",
      "  File \"c:\\Users\\fafaf\\anaconda3\\envs\\tf\\lib\\asyncio\\selector_events.py\", line 115, in _read_from_self\n",
      "    data = self._ssock.recv(4096)\n",
      "ConnectionResetError: [WinError 10054] An existing connection was forcibly closed by the remote host\n",
      "Exception in callback BaseSelectorEventLoop._read_from_self()\n",
      "handle: <Handle BaseSelectorEventLoop._read_from_self()>\n",
      "Traceback (most recent call last):\n",
      "  File \"c:\\Users\\fafaf\\anaconda3\\envs\\tf\\lib\\asyncio\\events.py\", line 80, in _run\n",
      "    self._context.run(self._callback, *self._args)\n",
      "  File \"c:\\Users\\fafaf\\anaconda3\\envs\\tf\\lib\\asyncio\\selector_events.py\", line 115, in _read_from_self\n",
      "    data = self._ssock.recv(4096)\n",
      "ConnectionResetError: [WinError 10054] An existing connection was forcibly closed by the remote host\n",
      "Exception in callback BaseSelectorEventLoop._read_from_self()\n",
      "handle: <Handle BaseSelectorEventLoop._read_from_self()>\n",
      "Traceback (most recent call last):\n",
      "  File \"c:\\Users\\fafaf\\anaconda3\\envs\\tf\\lib\\asyncio\\events.py\", line 80, in _run\n",
      "    self._context.run(self._callback, *self._args)\n",
      "  File \"c:\\Users\\fafaf\\anaconda3\\envs\\tf\\lib\\asyncio\\selector_events.py\", line 115, in _read_from_self\n",
      "    data = self._ssock.recv(4096)\n",
      "ConnectionResetError: [WinError 10054] An existing connection was forcibly closed by the remote host\n",
      "Exception in callback BaseSelectorEventLoop._read_from_self()\n",
      "handle: <Handle BaseSelectorEventLoop._read_from_self()>\n",
      "Traceback (most recent call last):\n",
      "  File \"c:\\Users\\fafaf\\anaconda3\\envs\\tf\\lib\\asyncio\\events.py\", line 80, in _run\n",
      "    self._context.run(self._callback, *self._args)\n",
      "  File \"c:\\Users\\fafaf\\anaconda3\\envs\\tf\\lib\\asyncio\\selector_events.py\", line 115, in _read_from_self\n",
      "    data = self._ssock.recv(4096)\n",
      "ConnectionResetError: [WinError 10054] An existing connection was forcibly closed by the remote host\n",
      "Exception in callback BaseSelectorEventLoop._read_from_self()\n",
      "handle: <Handle BaseSelectorEventLoop._read_from_self()>\n",
      "Traceback (most recent call last):\n",
      "  File \"c:\\Users\\fafaf\\anaconda3\\envs\\tf\\lib\\asyncio\\events.py\", line 80, in _run\n",
      "    self._context.run(self._callback, *self._args)\n",
      "  File \"c:\\Users\\fafaf\\anaconda3\\envs\\tf\\lib\\asyncio\\selector_events.py\", line 115, in _read_from_self\n",
      "    data = self._ssock.recv(4096)\n",
      "ConnectionResetError: [WinError 10054] An existing connection was forcibly closed by the remote host\n",
      "Exception in callback BaseSelectorEventLoop._read_from_self()\n",
      "handle: <Handle BaseSelectorEventLoop._read_from_self()>\n",
      "Traceback (most recent call last):\n",
      "  File \"c:\\Users\\fafaf\\anaconda3\\envs\\tf\\lib\\asyncio\\events.py\", line 80, in _run\n",
      "    self._context.run(self._callback, *self._args)\n",
      "  File \"c:\\Users\\fafaf\\anaconda3\\envs\\tf\\lib\\asyncio\\selector_events.py\", line 115, in _read_from_self\n",
      "    data = self._ssock.recv(4096)\n",
      "ConnectionResetError: [WinError 10054] An existing connection was forcibly closed by the remote host\n",
      "Exception in callback BaseSelectorEventLoop._read_from_self()\n",
      "handle: <Handle BaseSelectorEventLoop._read_from_self()>\n",
      "Traceback (most recent call last):\n",
      "  File \"c:\\Users\\fafaf\\anaconda3\\envs\\tf\\lib\\asyncio\\events.py\", line 80, in _run\n",
      "    self._context.run(self._callback, *self._args)\n",
      "  File \"c:\\Users\\fafaf\\anaconda3\\envs\\tf\\lib\\asyncio\\selector_events.py\", line 115, in _read_from_self\n",
      "    data = self._ssock.recv(4096)\n",
      "ConnectionResetError: [WinError 10054] An existing connection was forcibly closed by the remote host\n",
      "Exception in callback BaseSelectorEventLoop._read_from_self()\n",
      "handle: <Handle BaseSelectorEventLoop._read_from_self()>\n",
      "Traceback (most recent call last):\n",
      "  File \"c:\\Users\\fafaf\\anaconda3\\envs\\tf\\lib\\asyncio\\events.py\", line 80, in _run\n",
      "    self._context.run(self._callback, *self._args)\n",
      "  File \"c:\\Users\\fafaf\\anaconda3\\envs\\tf\\lib\\asyncio\\selector_events.py\", line 115, in _read_from_self\n",
      "    data = self._ssock.recv(4096)\n",
      "ConnectionResetError: [WinError 10054] An existing connection was forcibly closed by the remote host\n",
      "Exception in callback BaseSelectorEventLoop._read_from_self()\n",
      "handle: <Handle BaseSelectorEventLoop._read_from_self()>\n",
      "Traceback (most recent call last):\n",
      "  File \"c:\\Users\\fafaf\\anaconda3\\envs\\tf\\lib\\asyncio\\events.py\", line 80, in _run\n",
      "    self._context.run(self._callback, *self._args)\n",
      "  File \"c:\\Users\\fafaf\\anaconda3\\envs\\tf\\lib\\asyncio\\selector_events.py\", line 115, in _read_from_self\n",
      "    data = self._ssock.recv(4096)\n",
      "ConnectionResetError: [WinError 10054] An existing connection was forcibly closed by the remote host\n",
      "Exception in callback BaseSelectorEventLoop._read_from_self()\n",
      "handle: <Handle BaseSelectorEventLoop._read_from_self()>\n",
      "Traceback (most recent call last):\n",
      "  File \"c:\\Users\\fafaf\\anaconda3\\envs\\tf\\lib\\asyncio\\events.py\", line 80, in _run\n",
      "    self._context.run(self._callback, *self._args)\n",
      "  File \"c:\\Users\\fafaf\\anaconda3\\envs\\tf\\lib\\asyncio\\selector_events.py\", line 115, in _read_from_self\n",
      "    data = self._ssock.recv(4096)\n",
      "ConnectionResetError: [WinError 10054] An existing connection was forcibly closed by the remote host\n",
      "Exception in callback BaseSelectorEventLoop._read_from_self()\n",
      "handle: <Handle BaseSelectorEventLoop._read_from_self()>\n",
      "Traceback (most recent call last):\n",
      "  File \"c:\\Users\\fafaf\\anaconda3\\envs\\tf\\lib\\asyncio\\events.py\", line 80, in _run\n",
      "    self._context.run(self._callback, *self._args)\n",
      "  File \"c:\\Users\\fafaf\\anaconda3\\envs\\tf\\lib\\asyncio\\selector_events.py\", line 115, in _read_from_self\n",
      "    data = self._ssock.recv(4096)\n",
      "ConnectionResetError: [WinError 10054] An existing connection was forcibly closed by the remote host\n",
      "Exception in callback BaseSelectorEventLoop._read_from_self()\n",
      "handle: <Handle BaseSelectorEventLoop._read_from_self()>\n",
      "Traceback (most recent call last):\n",
      "  File \"c:\\Users\\fafaf\\anaconda3\\envs\\tf\\lib\\asyncio\\events.py\", line 80, in _run\n",
      "    self._context.run(self._callback, *self._args)\n",
      "  File \"c:\\Users\\fafaf\\anaconda3\\envs\\tf\\lib\\asyncio\\selector_events.py\", line 115, in _read_from_self\n",
      "    data = self._ssock.recv(4096)\n",
      "ConnectionResetError: [WinError 10054] An existing connection was forcibly closed by the remote host\n",
      "Exception in callback BaseSelectorEventLoop._read_from_self()\n",
      "handle: <Handle BaseSelectorEventLoop._read_from_self()>\n",
      "Traceback (most recent call last):\n",
      "  File \"c:\\Users\\fafaf\\anaconda3\\envs\\tf\\lib\\asyncio\\events.py\", line 80, in _run\n",
      "    self._context.run(self._callback, *self._args)\n",
      "  File \"c:\\Users\\fafaf\\anaconda3\\envs\\tf\\lib\\asyncio\\selector_events.py\", line 115, in _read_from_self\n",
      "    data = self._ssock.recv(4096)\n",
      "ConnectionResetError: [WinError 10054] An existing connection was forcibly closed by the remote host\n",
      "Exception in callback BaseSelectorEventLoop._read_from_self()\n",
      "handle: <Handle BaseSelectorEventLoop._read_from_self()>\n",
      "Traceback (most recent call last):\n",
      "  File \"c:\\Users\\fafaf\\anaconda3\\envs\\tf\\lib\\asyncio\\events.py\", line 80, in _run\n",
      "    self._context.run(self._callback, *self._args)\n",
      "  File \"c:\\Users\\fafaf\\anaconda3\\envs\\tf\\lib\\asyncio\\selector_events.py\", line 115, in _read_from_self\n",
      "    data = self._ssock.recv(4096)\n",
      "ConnectionResetError: [WinError 10054] An existing connection was forcibly closed by the remote host\n",
      "Exception in callback BaseSelectorEventLoop._read_from_self()\n",
      "handle: <Handle BaseSelectorEventLoop._read_from_self()>\n",
      "Traceback (most recent call last):\n",
      "  File \"c:\\Users\\fafaf\\anaconda3\\envs\\tf\\lib\\asyncio\\events.py\", line 80, in _run\n",
      "    self._context.run(self._callback, *self._args)\n",
      "  File \"c:\\Users\\fafaf\\anaconda3\\envs\\tf\\lib\\asyncio\\selector_events.py\", line 115, in _read_from_self\n",
      "    data = self._ssock.recv(4096)\n",
      "ConnectionResetError: [WinError 10054] An existing connection was forcibly closed by the remote host\n",
      "Exception in callback BaseSelectorEventLoop._read_from_self()\n",
      "handle: <Handle BaseSelectorEventLoop._read_from_self()>\n",
      "Traceback (most recent call last):\n",
      "  File \"c:\\Users\\fafaf\\anaconda3\\envs\\tf\\lib\\asyncio\\events.py\", line 80, in _run\n",
      "    self._context.run(self._callback, *self._args)\n",
      "  File \"c:\\Users\\fafaf\\anaconda3\\envs\\tf\\lib\\asyncio\\selector_events.py\", line 115, in _read_from_self\n",
      "    data = self._ssock.recv(4096)\n",
      "ConnectionResetError: [WinError 10054] An existing connection was forcibly closed by the remote host\n",
      "Exception in callback BaseSelectorEventLoop._read_from_self()\n",
      "handle: <Handle BaseSelectorEventLoop._read_from_self()>\n",
      "Traceback (most recent call last):\n",
      "  File \"c:\\Users\\fafaf\\anaconda3\\envs\\tf\\lib\\asyncio\\events.py\", line 80, in _run\n",
      "    self._context.run(self._callback, *self._args)\n",
      "  File \"c:\\Users\\fafaf\\anaconda3\\envs\\tf\\lib\\asyncio\\selector_events.py\", line 115, in _read_from_self\n",
      "    data = self._ssock.recv(4096)\n",
      "ConnectionResetError: [WinError 10054] An existing connection was forcibly closed by the remote host\n",
      "Exception in callback BaseSelectorEventLoop._read_from_self()\n",
      "handle: <Handle BaseSelectorEventLoop._read_from_self()>\n",
      "Traceback (most recent call last):\n",
      "  File \"c:\\Users\\fafaf\\anaconda3\\envs\\tf\\lib\\asyncio\\events.py\", line 80, in _run\n",
      "    self._context.run(self._callback, *self._args)\n",
      "  File \"c:\\Users\\fafaf\\anaconda3\\envs\\tf\\lib\\asyncio\\selector_events.py\", line 115, in _read_from_self\n",
      "    data = self._ssock.recv(4096)\n",
      "ConnectionResetError: [WinError 10054] An existing connection was forcibly closed by the remote host\n",
      "Exception in callback BaseSelectorEventLoop._read_from_self()\n",
      "handle: <Handle BaseSelectorEventLoop._read_from_self()>\n",
      "Traceback (most recent call last):\n",
      "  File \"c:\\Users\\fafaf\\anaconda3\\envs\\tf\\lib\\asyncio\\events.py\", line 80, in _run\n",
      "    self._context.run(self._callback, *self._args)\n",
      "  File \"c:\\Users\\fafaf\\anaconda3\\envs\\tf\\lib\\asyncio\\selector_events.py\", line 115, in _read_from_self\n",
      "    data = self._ssock.recv(4096)\n",
      "ConnectionResetError: [WinError 10054] An existing connection was forcibly closed by the remote host\n",
      "Exception in callback BaseSelectorEventLoop._read_from_self()\n",
      "handle: <Handle BaseSelectorEventLoop._read_from_self()>\n",
      "Traceback (most recent call last):\n",
      "  File \"c:\\Users\\fafaf\\anaconda3\\envs\\tf\\lib\\asyncio\\events.py\", line 80, in _run\n",
      "    self._context.run(self._callback, *self._args)\n",
      "  File \"c:\\Users\\fafaf\\anaconda3\\envs\\tf\\lib\\asyncio\\selector_events.py\", line 115, in _read_from_self\n",
      "    data = self._ssock.recv(4096)\n",
      "ConnectionResetError: [WinError 10054] An existing connection was forcibly closed by the remote host\n",
      "Exception in callback BaseSelectorEventLoop._read_from_self()\n",
      "handle: <Handle BaseSelectorEventLoop._read_from_self()>\n",
      "Traceback (most recent call last):\n",
      "  File \"c:\\Users\\fafaf\\anaconda3\\envs\\tf\\lib\\asyncio\\events.py\", line 80, in _run\n",
      "    self._context.run(self._callback, *self._args)\n",
      "  File \"c:\\Users\\fafaf\\anaconda3\\envs\\tf\\lib\\asyncio\\selector_events.py\", line 115, in _read_from_self\n",
      "    data = self._ssock.recv(4096)\n",
      "ConnectionResetError: [WinError 10054] An existing connection was forcibly closed by the remote host\n",
      "Exception in callback BaseSelectorEventLoop._read_from_self()\n",
      "handle: <Handle BaseSelectorEventLoop._read_from_self()>\n",
      "Traceback (most recent call last):\n",
      "  File \"c:\\Users\\fafaf\\anaconda3\\envs\\tf\\lib\\asyncio\\events.py\", line 80, in _run\n",
      "    self._context.run(self._callback, *self._args)\n",
      "  File \"c:\\Users\\fafaf\\anaconda3\\envs\\tf\\lib\\asyncio\\selector_events.py\", line 115, in _read_from_self\n",
      "    data = self._ssock.recv(4096)\n",
      "ConnectionResetError: [WinError 10054] An existing connection was forcibly closed by the remote host\n",
      "Exception in callback BaseSelectorEventLoop._read_from_self()\n",
      "handle: <Handle BaseSelectorEventLoop._read_from_self()>\n",
      "Traceback (most recent call last):\n",
      "  File \"c:\\Users\\fafaf\\anaconda3\\envs\\tf\\lib\\asyncio\\events.py\", line 80, in _run\n",
      "    self._context.run(self._callback, *self._args)\n",
      "  File \"c:\\Users\\fafaf\\anaconda3\\envs\\tf\\lib\\asyncio\\selector_events.py\", line 115, in _read_from_self\n",
      "    data = self._ssock.recv(4096)\n",
      "ConnectionResetError: [WinError 10054] An existing connection was forcibly closed by the remote host\n",
      "Exception in callback BaseSelectorEventLoop._read_from_self()\n",
      "handle: <Handle BaseSelectorEventLoop._read_from_self()>\n",
      "Traceback (most recent call last):\n",
      "  File \"c:\\Users\\fafaf\\anaconda3\\envs\\tf\\lib\\asyncio\\events.py\", line 80, in _run\n",
      "    self._context.run(self._callback, *self._args)\n",
      "  File \"c:\\Users\\fafaf\\anaconda3\\envs\\tf\\lib\\asyncio\\selector_events.py\", line 115, in _read_from_self\n",
      "    data = self._ssock.recv(4096)\n",
      "ConnectionResetError: [WinError 10054] An existing connection was forcibly closed by the remote host\n",
      "Exception in callback BaseSelectorEventLoop._read_from_self()\n",
      "handle: <Handle BaseSelectorEventLoop._read_from_self()>\n",
      "Traceback (most recent call last):\n",
      "  File \"c:\\Users\\fafaf\\anaconda3\\envs\\tf\\lib\\asyncio\\events.py\", line 80, in _run\n",
      "    self._context.run(self._callback, *self._args)\n",
      "  File \"c:\\Users\\fafaf\\anaconda3\\envs\\tf\\lib\\asyncio\\selector_events.py\", line 115, in _read_from_self\n",
      "    data = self._ssock.recv(4096)\n",
      "ConnectionResetError: [WinError 10054] An existing connection was forcibly closed by the remote host\n",
      "Exception in callback BaseSelectorEventLoop._read_from_self()\n",
      "handle: <Handle BaseSelectorEventLoop._read_from_self()>\n",
      "Traceback (most recent call last):\n",
      "  File \"c:\\Users\\fafaf\\anaconda3\\envs\\tf\\lib\\asyncio\\events.py\", line 80, in _run\n",
      "    self._context.run(self._callback, *self._args)\n",
      "  File \"c:\\Users\\fafaf\\anaconda3\\envs\\tf\\lib\\asyncio\\selector_events.py\", line 115, in _read_from_self\n",
      "    data = self._ssock.recv(4096)\n",
      "ConnectionResetError: [WinError 10054] An existing connection was forcibly closed by the remote host\n",
      "Exception in callback BaseSelectorEventLoop._read_from_self()\n",
      "handle: <Handle BaseSelectorEventLoop._read_from_self()>\n",
      "Traceback (most recent call last):\n",
      "  File \"c:\\Users\\fafaf\\anaconda3\\envs\\tf\\lib\\asyncio\\events.py\", line 80, in _run\n",
      "    self._context.run(self._callback, *self._args)\n",
      "  File \"c:\\Users\\fafaf\\anaconda3\\envs\\tf\\lib\\asyncio\\selector_events.py\", line 115, in _read_from_self\n",
      "    data = self._ssock.recv(4096)\n",
      "ConnectionResetError: [WinError 10054] An existing connection was forcibly closed by the remote host\n",
      "Exception in callback BaseSelectorEventLoop._read_from_self()\n",
      "handle: <Handle BaseSelectorEventLoop._read_from_self()>\n",
      "Traceback (most recent call last):\n",
      "  File \"c:\\Users\\fafaf\\anaconda3\\envs\\tf\\lib\\asyncio\\events.py\", line 80, in _run\n",
      "    self._context.run(self._callback, *self._args)\n",
      "  File \"c:\\Users\\fafaf\\anaconda3\\envs\\tf\\lib\\asyncio\\selector_events.py\", line 115, in _read_from_self\n",
      "    data = self._ssock.recv(4096)\n",
      "ConnectionResetError: [WinError 10054] An existing connection was forcibly closed by the remote host\n",
      "Exception in callback BaseSelectorEventLoop._read_from_self()\n",
      "handle: <Handle BaseSelectorEventLoop._read_from_self()>\n",
      "Traceback (most recent call last):\n",
      "  File \"c:\\Users\\fafaf\\anaconda3\\envs\\tf\\lib\\asyncio\\events.py\", line 80, in _run\n",
      "    self._context.run(self._callback, *self._args)\n",
      "  File \"c:\\Users\\fafaf\\anaconda3\\envs\\tf\\lib\\asyncio\\selector_events.py\", line 115, in _read_from_self\n",
      "    data = self._ssock.recv(4096)\n",
      "ConnectionResetError: [WinError 10054] An existing connection was forcibly closed by the remote host\n",
      "Exception in callback BaseSelectorEventLoop._read_from_self()\n",
      "handle: <Handle BaseSelectorEventLoop._read_from_self()>\n",
      "Traceback (most recent call last):\n",
      "  File \"c:\\Users\\fafaf\\anaconda3\\envs\\tf\\lib\\asyncio\\events.py\", line 80, in _run\n",
      "    self._context.run(self._callback, *self._args)\n",
      "  File \"c:\\Users\\fafaf\\anaconda3\\envs\\tf\\lib\\asyncio\\selector_events.py\", line 115, in _read_from_self\n",
      "    data = self._ssock.recv(4096)\n",
      "ConnectionResetError: [WinError 10054] An existing connection was forcibly closed by the remote host\n",
      "Exception in callback BaseSelectorEventLoop._read_from_self()\n",
      "handle: <Handle BaseSelectorEventLoop._read_from_self()>\n",
      "Traceback (most recent call last):\n",
      "  File \"c:\\Users\\fafaf\\anaconda3\\envs\\tf\\lib\\asyncio\\events.py\", line 80, in _run\n",
      "    self._context.run(self._callback, *self._args)\n",
      "  File \"c:\\Users\\fafaf\\anaconda3\\envs\\tf\\lib\\asyncio\\selector_events.py\", line 115, in _read_from_self\n",
      "    data = self._ssock.recv(4096)\n",
      "ConnectionResetError: [WinError 10054] An existing connection was forcibly closed by the remote host\n",
      "Exception in callback BaseSelectorEventLoop._read_from_self()\n",
      "handle: <Handle BaseSelectorEventLoop._read_from_self()>\n",
      "Traceback (most recent call last):\n",
      "  File \"c:\\Users\\fafaf\\anaconda3\\envs\\tf\\lib\\asyncio\\events.py\", line 80, in _run\n",
      "    self._context.run(self._callback, *self._args)\n",
      "  File \"c:\\Users\\fafaf\\anaconda3\\envs\\tf\\lib\\asyncio\\selector_events.py\", line 115, in _read_from_self\n",
      "    data = self._ssock.recv(4096)\n",
      "ConnectionResetError: [WinError 10054] An existing connection was forcibly closed by the remote host\n",
      "Exception in callback BaseSelectorEventLoop._read_from_self()\n",
      "handle: <Handle BaseSelectorEventLoop._read_from_self()>\n",
      "Traceback (most recent call last):\n",
      "  File \"c:\\Users\\fafaf\\anaconda3\\envs\\tf\\lib\\asyncio\\events.py\", line 80, in _run\n",
      "    self._context.run(self._callback, *self._args)\n",
      "  File \"c:\\Users\\fafaf\\anaconda3\\envs\\tf\\lib\\asyncio\\selector_events.py\", line 115, in _read_from_self\n",
      "    data = self._ssock.recv(4096)\n",
      "ConnectionResetError: [WinError 10054] An existing connection was forcibly closed by the remote host\n",
      "Exception in callback BaseSelectorEventLoop._read_from_self()\n",
      "handle: <Handle BaseSelectorEventLoop._read_from_self()>\n",
      "Traceback (most recent call last):\n",
      "  File \"c:\\Users\\fafaf\\anaconda3\\envs\\tf\\lib\\asyncio\\events.py\", line 80, in _run\n",
      "    self._context.run(self._callback, *self._args)\n",
      "  File \"c:\\Users\\fafaf\\anaconda3\\envs\\tf\\lib\\asyncio\\selector_events.py\", line 115, in _read_from_self\n",
      "    data = self._ssock.recv(4096)\n",
      "ConnectionResetError: [WinError 10054] An existing connection was forcibly closed by the remote host\n",
      "Exception in callback BaseSelectorEventLoop._read_from_self()\n",
      "handle: <Handle BaseSelectorEventLoop._read_from_self()>\n",
      "Traceback (most recent call last):\n",
      "  File \"c:\\Users\\fafaf\\anaconda3\\envs\\tf\\lib\\asyncio\\events.py\", line 80, in _run\n",
      "    self._context.run(self._callback, *self._args)\n",
      "  File \"c:\\Users\\fafaf\\anaconda3\\envs\\tf\\lib\\asyncio\\selector_events.py\", line 115, in _read_from_self\n",
      "    data = self._ssock.recv(4096)\n",
      "ConnectionResetError: [WinError 10054] An existing connection was forcibly closed by the remote host\n",
      "Exception in callback BaseSelectorEventLoop._read_from_self()\n",
      "handle: <Handle BaseSelectorEventLoop._read_from_self()>\n",
      "Traceback (most recent call last):\n",
      "  File \"c:\\Users\\fafaf\\anaconda3\\envs\\tf\\lib\\asyncio\\events.py\", line 80, in _run\n",
      "    self._context.run(self._callback, *self._args)\n",
      "  File \"c:\\Users\\fafaf\\anaconda3\\envs\\tf\\lib\\asyncio\\selector_events.py\", line 115, in _read_from_self\n",
      "    data = self._ssock.recv(4096)\n",
      "ConnectionResetError: [WinError 10054] An existing connection was forcibly closed by the remote host\n",
      "Exception in callback BaseSelectorEventLoop._read_from_self()\n",
      "handle: <Handle BaseSelectorEventLoop._read_from_self()>\n",
      "Traceback (most recent call last):\n",
      "  File \"c:\\Users\\fafaf\\anaconda3\\envs\\tf\\lib\\asyncio\\events.py\", line 80, in _run\n",
      "    self._context.run(self._callback, *self._args)\n",
      "  File \"c:\\Users\\fafaf\\anaconda3\\envs\\tf\\lib\\asyncio\\selector_events.py\", line 115, in _read_from_self\n",
      "    data = self._ssock.recv(4096)\n",
      "ConnectionResetError: [WinError 10054] An existing connection was forcibly closed by the remote host\n",
      "Exception in callback BaseSelectorEventLoop._read_from_self()\n",
      "handle: <Handle BaseSelectorEventLoop._read_from_self()>\n",
      "Traceback (most recent call last):\n",
      "  File \"c:\\Users\\fafaf\\anaconda3\\envs\\tf\\lib\\asyncio\\events.py\", line 80, in _run\n",
      "    self._context.run(self._callback, *self._args)\n",
      "  File \"c:\\Users\\fafaf\\anaconda3\\envs\\tf\\lib\\asyncio\\selector_events.py\", line 115, in _read_from_self\n",
      "    data = self._ssock.recv(4096)\n",
      "ConnectionResetError: [WinError 10054] An existing connection was forcibly closed by the remote host\n",
      "Exception in callback BaseSelectorEventLoop._read_from_self()\n",
      "handle: <Handle BaseSelectorEventLoop._read_from_self()>\n",
      "Traceback (most recent call last):\n",
      "  File \"c:\\Users\\fafaf\\anaconda3\\envs\\tf\\lib\\asyncio\\events.py\", line 80, in _run\n",
      "    self._context.run(self._callback, *self._args)\n",
      "  File \"c:\\Users\\fafaf\\anaconda3\\envs\\tf\\lib\\asyncio\\selector_events.py\", line 115, in _read_from_self\n",
      "    data = self._ssock.recv(4096)\n",
      "ConnectionResetError: [WinError 10054] An existing connection was forcibly closed by the remote host\n",
      "Exception in callback BaseSelectorEventLoop._read_from_self()\n",
      "handle: <Handle BaseSelectorEventLoop._read_from_self()>\n",
      "Traceback (most recent call last):\n",
      "  File \"c:\\Users\\fafaf\\anaconda3\\envs\\tf\\lib\\asyncio\\events.py\", line 80, in _run\n",
      "    self._context.run(self._callback, *self._args)\n",
      "  File \"c:\\Users\\fafaf\\anaconda3\\envs\\tf\\lib\\asyncio\\selector_events.py\", line 115, in _read_from_self\n",
      "    data = self._ssock.recv(4096)\n",
      "ConnectionResetError: [WinError 10054] An existing connection was forcibly closed by the remote host\n",
      "Exception in callback BaseSelectorEventLoop._read_from_self()\n",
      "handle: <Handle BaseSelectorEventLoop._read_from_self()>\n",
      "Traceback (most recent call last):\n",
      "  File \"c:\\Users\\fafaf\\anaconda3\\envs\\tf\\lib\\asyncio\\events.py\", line 80, in _run\n",
      "    self._context.run(self._callback, *self._args)\n",
      "  File \"c:\\Users\\fafaf\\anaconda3\\envs\\tf\\lib\\asyncio\\selector_events.py\", line 115, in _read_from_self\n",
      "    data = self._ssock.recv(4096)\n",
      "ConnectionResetError: [WinError 10054] An existing connection was forcibly closed by the remote host\n",
      "Exception in callback BaseSelectorEventLoop._read_from_self()\n",
      "handle: <Handle BaseSelectorEventLoop._read_from_self()>\n",
      "Traceback (most recent call last):\n",
      "  File \"c:\\Users\\fafaf\\anaconda3\\envs\\tf\\lib\\asyncio\\events.py\", line 80, in _run\n",
      "    self._context.run(self._callback, *self._args)\n",
      "  File \"c:\\Users\\fafaf\\anaconda3\\envs\\tf\\lib\\asyncio\\selector_events.py\", line 115, in _read_from_self\n",
      "    data = self._ssock.recv(4096)\n",
      "ConnectionResetError: [WinError 10054] An existing connection was forcibly closed by the remote host\n",
      "Exception in callback BaseSelectorEventLoop._read_from_self()\n",
      "handle: <Handle BaseSelectorEventLoop._read_from_self()>\n",
      "Traceback (most recent call last):\n",
      "  File \"c:\\Users\\fafaf\\anaconda3\\envs\\tf\\lib\\asyncio\\events.py\", line 80, in _run\n",
      "    self._context.run(self._callback, *self._args)\n",
      "  File \"c:\\Users\\fafaf\\anaconda3\\envs\\tf\\lib\\asyncio\\selector_events.py\", line 115, in _read_from_self\n",
      "    data = self._ssock.recv(4096)\n",
      "ConnectionResetError: [WinError 10054] An existing connection was forcibly closed by the remote host\n",
      "Exception in callback BaseSelectorEventLoop._read_from_self()\n",
      "handle: <Handle BaseSelectorEventLoop._read_from_self()>\n",
      "Traceback (most recent call last):\n",
      "  File \"c:\\Users\\fafaf\\anaconda3\\envs\\tf\\lib\\asyncio\\events.py\", line 80, in _run\n",
      "    self._context.run(self._callback, *self._args)\n",
      "  File \"c:\\Users\\fafaf\\anaconda3\\envs\\tf\\lib\\asyncio\\selector_events.py\", line 115, in _read_from_self\n",
      "    data = self._ssock.recv(4096)\n",
      "ConnectionResetError: [WinError 10054] An existing connection was forcibly closed by the remote host\n",
      "Exception in callback BaseSelectorEventLoop._read_from_self()\n",
      "handle: <Handle BaseSelectorEventLoop._read_from_self()>\n",
      "Traceback (most recent call last):\n",
      "  File \"c:\\Users\\fafaf\\anaconda3\\envs\\tf\\lib\\asyncio\\events.py\", line 80, in _run\n",
      "    self._context.run(self._callback, *self._args)\n",
      "  File \"c:\\Users\\fafaf\\anaconda3\\envs\\tf\\lib\\asyncio\\selector_events.py\", line 115, in _read_from_self\n",
      "    data = self._ssock.recv(4096)\n",
      "ConnectionResetError: [WinError 10054] An existing connection was forcibly closed by the remote host\n",
      "Exception in callback BaseSelectorEventLoop._read_from_self()\n",
      "handle: <Handle BaseSelectorEventLoop._read_from_self()>\n",
      "Traceback (most recent call last):\n",
      "  File \"c:\\Users\\fafaf\\anaconda3\\envs\\tf\\lib\\asyncio\\events.py\", line 80, in _run\n",
      "    self._context.run(self._callback, *self._args)\n",
      "  File \"c:\\Users\\fafaf\\anaconda3\\envs\\tf\\lib\\asyncio\\selector_events.py\", line 115, in _read_from_self\n",
      "    data = self._ssock.recv(4096)\n",
      "ConnectionResetError: [WinError 10054] An existing connection was forcibly closed by the remote host\n",
      "Exception in callback BaseSelectorEventLoop._read_from_self()\n",
      "handle: <Handle BaseSelectorEventLoop._read_from_self()>\n",
      "Traceback (most recent call last):\n",
      "  File \"c:\\Users\\fafaf\\anaconda3\\envs\\tf\\lib\\asyncio\\events.py\", line 80, in _run\n",
      "    self._context.run(self._callback, *self._args)\n",
      "  File \"c:\\Users\\fafaf\\anaconda3\\envs\\tf\\lib\\asyncio\\selector_events.py\", line 115, in _read_from_self\n",
      "    data = self._ssock.recv(4096)\n",
      "ConnectionResetError: [WinError 10054] An existing connection was forcibly closed by the remote host\n",
      "Exception in callback BaseSelectorEventLoop._read_from_self()\n",
      "handle: <Handle BaseSelectorEventLoop._read_from_self()>\n",
      "Traceback (most recent call last):\n",
      "  File \"c:\\Users\\fafaf\\anaconda3\\envs\\tf\\lib\\asyncio\\events.py\", line 80, in _run\n",
      "    self._context.run(self._callback, *self._args)\n",
      "  File \"c:\\Users\\fafaf\\anaconda3\\envs\\tf\\lib\\asyncio\\selector_events.py\", line 115, in _read_from_self\n",
      "    data = self._ssock.recv(4096)\n",
      "ConnectionResetError: [WinError 10054] An existing connection was forcibly closed by the remote host\n",
      "Exception in callback BaseSelectorEventLoop._read_from_self()\n",
      "handle: <Handle BaseSelectorEventLoop._read_from_self()>\n",
      "Traceback (most recent call last):\n",
      "  File \"c:\\Users\\fafaf\\anaconda3\\envs\\tf\\lib\\asyncio\\events.py\", line 80, in _run\n",
      "    self._context.run(self._callback, *self._args)\n",
      "  File \"c:\\Users\\fafaf\\anaconda3\\envs\\tf\\lib\\asyncio\\selector_events.py\", line 115, in _read_from_self\n",
      "    data = self._ssock.recv(4096)\n",
      "ConnectionResetError: [WinError 10054] An existing connection was forcibly closed by the remote host\n",
      "Exception in callback BaseSelectorEventLoop._read_from_self()\n",
      "handle: <Handle BaseSelectorEventLoop._read_from_self()>\n",
      "Traceback (most recent call last):\n",
      "  File \"c:\\Users\\fafaf\\anaconda3\\envs\\tf\\lib\\asyncio\\events.py\", line 80, in _run\n",
      "    self._context.run(self._callback, *self._args)\n",
      "  File \"c:\\Users\\fafaf\\anaconda3\\envs\\tf\\lib\\asyncio\\selector_events.py\", line 115, in _read_from_self\n",
      "    data = self._ssock.recv(4096)\n",
      "ConnectionResetError: [WinError 10054] An existing connection was forcibly closed by the remote host\n",
      "Exception in callback BaseSelectorEventLoop._read_from_self()\n",
      "handle: <Handle BaseSelectorEventLoop._read_from_self()>\n",
      "Traceback (most recent call last):\n",
      "  File \"c:\\Users\\fafaf\\anaconda3\\envs\\tf\\lib\\asyncio\\events.py\", line 80, in _run\n",
      "    self._context.run(self._callback, *self._args)\n",
      "  File \"c:\\Users\\fafaf\\anaconda3\\envs\\tf\\lib\\asyncio\\selector_events.py\", line 115, in _read_from_self\n",
      "    data = self._ssock.recv(4096)\n",
      "ConnectionResetError: [WinError 10054] An existing connection was forcibly closed by the remote host\n",
      "Exception in callback BaseSelectorEventLoop._read_from_self()\n",
      "handle: <Handle BaseSelectorEventLoop._read_from_self()>\n",
      "Traceback (most recent call last):\n",
      "  File \"c:\\Users\\fafaf\\anaconda3\\envs\\tf\\lib\\asyncio\\events.py\", line 80, in _run\n",
      "    self._context.run(self._callback, *self._args)\n",
      "  File \"c:\\Users\\fafaf\\anaconda3\\envs\\tf\\lib\\asyncio\\selector_events.py\", line 115, in _read_from_self\n",
      "    data = self._ssock.recv(4096)\n",
      "ConnectionResetError: [WinError 10054] An existing connection was forcibly closed by the remote host\n",
      "Exception in callback BaseSelectorEventLoop._read_from_self()\n",
      "handle: <Handle BaseSelectorEventLoop._read_from_self()>\n",
      "Traceback (most recent call last):\n",
      "  File \"c:\\Users\\fafaf\\anaconda3\\envs\\tf\\lib\\asyncio\\events.py\", line 80, in _run\n",
      "    self._context.run(self._callback, *self._args)\n",
      "  File \"c:\\Users\\fafaf\\anaconda3\\envs\\tf\\lib\\asyncio\\selector_events.py\", line 115, in _read_from_self\n",
      "    data = self._ssock.recv(4096)\n",
      "ConnectionResetError: [WinError 10054] An existing connection was forcibly closed by the remote host\n",
      "Exception in callback BaseSelectorEventLoop._read_from_self()\n",
      "handle: <Handle BaseSelectorEventLoop._read_from_self()>\n",
      "Traceback (most recent call last):\n",
      "  File \"c:\\Users\\fafaf\\anaconda3\\envs\\tf\\lib\\asyncio\\events.py\", line 80, in _run\n",
      "    self._context.run(self._callback, *self._args)\n",
      "  File \"c:\\Users\\fafaf\\anaconda3\\envs\\tf\\lib\\asyncio\\selector_events.py\", line 115, in _read_from_self\n",
      "    data = self._ssock.recv(4096)\n",
      "ConnectionResetError: [WinError 10054] An existing connection was forcibly closed by the remote host\n",
      "Exception in callback BaseSelectorEventLoop._read_from_self()\n",
      "handle: <Handle BaseSelectorEventLoop._read_from_self()>\n",
      "Traceback (most recent call last):\n",
      "  File \"c:\\Users\\fafaf\\anaconda3\\envs\\tf\\lib\\asyncio\\events.py\", line 80, in _run\n",
      "    self._context.run(self._callback, *self._args)\n",
      "  File \"c:\\Users\\fafaf\\anaconda3\\envs\\tf\\lib\\asyncio\\selector_events.py\", line 115, in _read_from_self\n",
      "    data = self._ssock.recv(4096)\n",
      "ConnectionResetError: [WinError 10054] An existing connection was forcibly closed by the remote host\n",
      "Exception in callback BaseSelectorEventLoop._read_from_self()\n",
      "handle: <Handle BaseSelectorEventLoop._read_from_self()>\n",
      "Traceback (most recent call last):\n",
      "  File \"c:\\Users\\fafaf\\anaconda3\\envs\\tf\\lib\\asyncio\\events.py\", line 80, in _run\n",
      "    self._context.run(self._callback, *self._args)\n",
      "  File \"c:\\Users\\fafaf\\anaconda3\\envs\\tf\\lib\\asyncio\\selector_events.py\", line 115, in _read_from_self\n",
      "    data = self._ssock.recv(4096)\n",
      "ConnectionResetError: [WinError 10054] An existing connection was forcibly closed by the remote host\n",
      "Exception in callback BaseSelectorEventLoop._read_from_self()\n",
      "handle: <Handle BaseSelectorEventLoop._read_from_self()>\n",
      "Traceback (most recent call last):\n",
      "  File \"c:\\Users\\fafaf\\anaconda3\\envs\\tf\\lib\\asyncio\\events.py\", line 80, in _run\n",
      "    self._context.run(self._callback, *self._args)\n",
      "  File \"c:\\Users\\fafaf\\anaconda3\\envs\\tf\\lib\\asyncio\\selector_events.py\", line 115, in _read_from_self\n",
      "    data = self._ssock.recv(4096)\n",
      "ConnectionResetError: [WinError 10054] An existing connection was forcibly closed by the remote host\n",
      "Exception in callback BaseSelectorEventLoop._read_from_self()\n",
      "handle: <Handle BaseSelectorEventLoop._read_from_self()>\n",
      "Traceback (most recent call last):\n",
      "  File \"c:\\Users\\fafaf\\anaconda3\\envs\\tf\\lib\\asyncio\\events.py\", line 80, in _run\n",
      "    self._context.run(self._callback, *self._args)\n",
      "  File \"c:\\Users\\fafaf\\anaconda3\\envs\\tf\\lib\\asyncio\\selector_events.py\", line 115, in _read_from_self\n",
      "    data = self._ssock.recv(4096)\n",
      "ConnectionResetError: [WinError 10054] An existing connection was forcibly closed by the remote host\n",
      "Exception in callback BaseSelectorEventLoop._read_from_self()\n",
      "handle: <Handle BaseSelectorEventLoop._read_from_self()>\n",
      "Traceback (most recent call last):\n",
      "  File \"c:\\Users\\fafaf\\anaconda3\\envs\\tf\\lib\\asyncio\\events.py\", line 80, in _run\n",
      "    self._context.run(self._callback, *self._args)\n",
      "  File \"c:\\Users\\fafaf\\anaconda3\\envs\\tf\\lib\\asyncio\\selector_events.py\", line 115, in _read_from_self\n",
      "    data = self._ssock.recv(4096)\n",
      "ConnectionResetError: [WinError 10054] An existing connection was forcibly closed by the remote host\n",
      "Exception in callback BaseSelectorEventLoop._read_from_self()\n",
      "handle: <Handle BaseSelectorEventLoop._read_from_self()>\n",
      "Traceback (most recent call last):\n",
      "  File \"c:\\Users\\fafaf\\anaconda3\\envs\\tf\\lib\\asyncio\\events.py\", line 80, in _run\n",
      "    self._context.run(self._callback, *self._args)\n",
      "  File \"c:\\Users\\fafaf\\anaconda3\\envs\\tf\\lib\\asyncio\\selector_events.py\", line 115, in _read_from_self\n",
      "    data = self._ssock.recv(4096)\n",
      "ConnectionResetError: [WinError 10054] An existing connection was forcibly closed by the remote host\n",
      "Exception in callback BaseSelectorEventLoop._read_from_self()\n",
      "handle: <Handle BaseSelectorEventLoop._read_from_self()>\n",
      "Traceback (most recent call last):\n",
      "  File \"c:\\Users\\fafaf\\anaconda3\\envs\\tf\\lib\\asyncio\\events.py\", line 80, in _run\n",
      "    self._context.run(self._callback, *self._args)\n",
      "  File \"c:\\Users\\fafaf\\anaconda3\\envs\\tf\\lib\\asyncio\\selector_events.py\", line 115, in _read_from_self\n",
      "    data = self._ssock.recv(4096)\n",
      "ConnectionResetError: [WinError 10054] An existing connection was forcibly closed by the remote host\n",
      "Exception in callback BaseSelectorEventLoop._read_from_self()\n",
      "handle: <Handle BaseSelectorEventLoop._read_from_self()>\n",
      "Traceback (most recent call last):\n",
      "  File \"c:\\Users\\fafaf\\anaconda3\\envs\\tf\\lib\\asyncio\\events.py\", line 80, in _run\n",
      "    self._context.run(self._callback, *self._args)\n",
      "  File \"c:\\Users\\fafaf\\anaconda3\\envs\\tf\\lib\\asyncio\\selector_events.py\", line 115, in _read_from_self\n",
      "    data = self._ssock.recv(4096)\n",
      "ConnectionResetError: [WinError 10054] An existing connection was forcibly closed by the remote host\n",
      "Exception in callback BaseSelectorEventLoop._read_from_self()\n",
      "handle: <Handle BaseSelectorEventLoop._read_from_self()>\n",
      "Traceback (most recent call last):\n",
      "  File \"c:\\Users\\fafaf\\anaconda3\\envs\\tf\\lib\\asyncio\\events.py\", line 80, in _run\n",
      "    self._context.run(self._callback, *self._args)\n",
      "  File \"c:\\Users\\fafaf\\anaconda3\\envs\\tf\\lib\\asyncio\\selector_events.py\", line 115, in _read_from_self\n",
      "    data = self._ssock.recv(4096)\n",
      "ConnectionResetError: [WinError 10054] An existing connection was forcibly closed by the remote host\n",
      "Exception in callback BaseSelectorEventLoop._read_from_self()\n",
      "handle: <Handle BaseSelectorEventLoop._read_from_self()>\n",
      "Traceback (most recent call last):\n",
      "  File \"c:\\Users\\fafaf\\anaconda3\\envs\\tf\\lib\\asyncio\\events.py\", line 80, in _run\n",
      "    self._context.run(self._callback, *self._args)\n",
      "  File \"c:\\Users\\fafaf\\anaconda3\\envs\\tf\\lib\\asyncio\\selector_events.py\", line 115, in _read_from_self\n",
      "    data = self._ssock.recv(4096)\n",
      "ConnectionResetError: [WinError 10054] An existing connection was forcibly closed by the remote host\n",
      "Exception in callback BaseSelectorEventLoop._read_from_self()\n",
      "handle: <Handle BaseSelectorEventLoop._read_from_self()>\n",
      "Traceback (most recent call last):\n",
      "  File \"c:\\Users\\fafaf\\anaconda3\\envs\\tf\\lib\\asyncio\\events.py\", line 80, in _run\n",
      "    self._context.run(self._callback, *self._args)\n",
      "  File \"c:\\Users\\fafaf\\anaconda3\\envs\\tf\\lib\\asyncio\\selector_events.py\", line 115, in _read_from_self\n",
      "    data = self._ssock.recv(4096)\n",
      "ConnectionResetError: [WinError 10054] An existing connection was forcibly closed by the remote host\n",
      "Exception in callback BaseSelectorEventLoop._read_from_self()\n",
      "handle: <Handle BaseSelectorEventLoop._read_from_self()>\n",
      "Traceback (most recent call last):\n",
      "  File \"c:\\Users\\fafaf\\anaconda3\\envs\\tf\\lib\\asyncio\\events.py\", line 80, in _run\n",
      "    self._context.run(self._callback, *self._args)\n",
      "  File \"c:\\Users\\fafaf\\anaconda3\\envs\\tf\\lib\\asyncio\\selector_events.py\", line 115, in _read_from_self\n",
      "    data = self._ssock.recv(4096)\n",
      "ConnectionResetError: [WinError 10054] An existing connection was forcibly closed by the remote host\n",
      "Exception in callback BaseSelectorEventLoop._read_from_self()\n",
      "handle: <Handle BaseSelectorEventLoop._read_from_self()>\n",
      "Traceback (most recent call last):\n",
      "  File \"c:\\Users\\fafaf\\anaconda3\\envs\\tf\\lib\\asyncio\\events.py\", line 80, in _run\n",
      "    self._context.run(self._callback, *self._args)\n",
      "  File \"c:\\Users\\fafaf\\anaconda3\\envs\\tf\\lib\\asyncio\\selector_events.py\", line 115, in _read_from_self\n",
      "    data = self._ssock.recv(4096)\n",
      "ConnectionResetError: [WinError 10054] An existing connection was forcibly closed by the remote host\n",
      "Exception in callback BaseSelectorEventLoop._read_from_self()\n",
      "handle: <Handle BaseSelectorEventLoop._read_from_self()>\n",
      "Traceback (most recent call last):\n",
      "  File \"c:\\Users\\fafaf\\anaconda3\\envs\\tf\\lib\\asyncio\\events.py\", line 80, in _run\n",
      "    self._context.run(self._callback, *self._args)\n",
      "  File \"c:\\Users\\fafaf\\anaconda3\\envs\\tf\\lib\\asyncio\\selector_events.py\", line 115, in _read_from_self\n",
      "    data = self._ssock.recv(4096)\n",
      "ConnectionResetError: [WinError 10054] An existing connection was forcibly closed by the remote host\n",
      "Exception in callback BaseSelectorEventLoop._read_from_self()\n",
      "handle: <Handle BaseSelectorEventLoop._read_from_self()>\n",
      "Traceback (most recent call last):\n",
      "  File \"c:\\Users\\fafaf\\anaconda3\\envs\\tf\\lib\\asyncio\\events.py\", line 80, in _run\n",
      "    self._context.run(self._callback, *self._args)\n",
      "  File \"c:\\Users\\fafaf\\anaconda3\\envs\\tf\\lib\\asyncio\\selector_events.py\", line 115, in _read_from_self\n",
      "    data = self._ssock.recv(4096)\n",
      "ConnectionResetError: [WinError 10054] An existing connection was forcibly closed by the remote host\n",
      "Exception in callback BaseSelectorEventLoop._read_from_self()\n",
      "handle: <Handle BaseSelectorEventLoop._read_from_self()>\n",
      "Traceback (most recent call last):\n",
      "  File \"c:\\Users\\fafaf\\anaconda3\\envs\\tf\\lib\\asyncio\\events.py\", line 80, in _run\n",
      "    self._context.run(self._callback, *self._args)\n",
      "  File \"c:\\Users\\fafaf\\anaconda3\\envs\\tf\\lib\\asyncio\\selector_events.py\", line 115, in _read_from_self\n",
      "    data = self._ssock.recv(4096)\n",
      "ConnectionResetError: [WinError 10054] An existing connection was forcibly closed by the remote host\n",
      "Exception in callback BaseSelectorEventLoop._read_from_self()\n",
      "handle: <Handle BaseSelectorEventLoop._read_from_self()>\n",
      "Traceback (most recent call last):\n",
      "  File \"c:\\Users\\fafaf\\anaconda3\\envs\\tf\\lib\\asyncio\\events.py\", line 80, in _run\n",
      "    self._context.run(self._callback, *self._args)\n",
      "  File \"c:\\Users\\fafaf\\anaconda3\\envs\\tf\\lib\\asyncio\\selector_events.py\", line 115, in _read_from_self\n",
      "    data = self._ssock.recv(4096)\n",
      "ConnectionResetError: [WinError 10054] An existing connection was forcibly closed by the remote host\n",
      "Exception in callback BaseSelectorEventLoop._read_from_self()\n",
      "handle: <Handle BaseSelectorEventLoop._read_from_self()>\n",
      "Traceback (most recent call last):\n",
      "  File \"c:\\Users\\fafaf\\anaconda3\\envs\\tf\\lib\\asyncio\\events.py\", line 80, in _run\n",
      "    self._context.run(self._callback, *self._args)\n",
      "  File \"c:\\Users\\fafaf\\anaconda3\\envs\\tf\\lib\\asyncio\\selector_events.py\", line 115, in _read_from_self\n",
      "    data = self._ssock.recv(4096)\n",
      "ConnectionResetError: [WinError 10054] An existing connection was forcibly closed by the remote host\n",
      "Exception in callback BaseSelectorEventLoop._read_from_self()\n",
      "handle: <Handle BaseSelectorEventLoop._read_from_self()>\n",
      "Traceback (most recent call last):\n",
      "  File \"c:\\Users\\fafaf\\anaconda3\\envs\\tf\\lib\\asyncio\\events.py\", line 80, in _run\n",
      "    self._context.run(self._callback, *self._args)\n",
      "  File \"c:\\Users\\fafaf\\anaconda3\\envs\\tf\\lib\\asyncio\\selector_events.py\", line 115, in _read_from_self\n",
      "    data = self._ssock.recv(4096)\n",
      "ConnectionResetError: [WinError 10054] An existing connection was forcibly closed by the remote host\n",
      "Exception in callback BaseSelectorEventLoop._read_from_self()\n",
      "handle: <Handle BaseSelectorEventLoop._read_from_self()>\n",
      "Traceback (most recent call last):\n",
      "  File \"c:\\Users\\fafaf\\anaconda3\\envs\\tf\\lib\\asyncio\\events.py\", line 80, in _run\n",
      "    self._context.run(self._callback, *self._args)\n",
      "  File \"c:\\Users\\fafaf\\anaconda3\\envs\\tf\\lib\\asyncio\\selector_events.py\", line 115, in _read_from_self\n",
      "    data = self._ssock.recv(4096)\n",
      "ConnectionResetError: [WinError 10054] An existing connection was forcibly closed by the remote host\n",
      "Exception in callback BaseSelectorEventLoop._read_from_self()\n",
      "handle: <Handle BaseSelectorEventLoop._read_from_self()>\n",
      "Traceback (most recent call last):\n",
      "  File \"c:\\Users\\fafaf\\anaconda3\\envs\\tf\\lib\\asyncio\\events.py\", line 80, in _run\n",
      "    self._context.run(self._callback, *self._args)\n",
      "  File \"c:\\Users\\fafaf\\anaconda3\\envs\\tf\\lib\\asyncio\\selector_events.py\", line 115, in _read_from_self\n",
      "    data = self._ssock.recv(4096)\n",
      "ConnectionResetError: [WinError 10054] An existing connection was forcibly closed by the remote host\n",
      "Exception in callback BaseSelectorEventLoop._read_from_self()\n",
      "handle: <Handle BaseSelectorEventLoop._read_from_self()>\n",
      "Traceback (most recent call last):\n",
      "  File \"c:\\Users\\fafaf\\anaconda3\\envs\\tf\\lib\\asyncio\\events.py\", line 80, in _run\n",
      "    self._context.run(self._callback, *self._args)\n",
      "  File \"c:\\Users\\fafaf\\anaconda3\\envs\\tf\\lib\\asyncio\\selector_events.py\", line 115, in _read_from_self\n",
      "    data = self._ssock.recv(4096)\n",
      "ConnectionResetError: [WinError 10054] An existing connection was forcibly closed by the remote host\n",
      "Exception in callback BaseSelectorEventLoop._read_from_self()\n",
      "handle: <Handle BaseSelectorEventLoop._read_from_self()>\n",
      "Traceback (most recent call last):\n",
      "  File \"c:\\Users\\fafaf\\anaconda3\\envs\\tf\\lib\\asyncio\\events.py\", line 80, in _run\n",
      "    self._context.run(self._callback, *self._args)\n",
      "  File \"c:\\Users\\fafaf\\anaconda3\\envs\\tf\\lib\\asyncio\\selector_events.py\", line 115, in _read_from_self\n",
      "    data = self._ssock.recv(4096)\n",
      "ConnectionResetError: [WinError 10054] An existing connection was forcibly closed by the remote host\n",
      "Exception in callback BaseSelectorEventLoop._read_from_self()\n",
      "handle: <Handle BaseSelectorEventLoop._read_from_self()>\n",
      "Traceback (most recent call last):\n",
      "  File \"c:\\Users\\fafaf\\anaconda3\\envs\\tf\\lib\\asyncio\\events.py\", line 80, in _run\n",
      "    self._context.run(self._callback, *self._args)\n",
      "  File \"c:\\Users\\fafaf\\anaconda3\\envs\\tf\\lib\\asyncio\\selector_events.py\", line 115, in _read_from_self\n",
      "    data = self._ssock.recv(4096)\n",
      "ConnectionResetError: [WinError 10054] An existing connection was forcibly closed by the remote host\n",
      "Exception in callback BaseSelectorEventLoop._read_from_self()\n",
      "handle: <Handle BaseSelectorEventLoop._read_from_self()>\n",
      "Traceback (most recent call last):\n",
      "  File \"c:\\Users\\fafaf\\anaconda3\\envs\\tf\\lib\\asyncio\\events.py\", line 80, in _run\n",
      "    self._context.run(self._callback, *self._args)\n",
      "  File \"c:\\Users\\fafaf\\anaconda3\\envs\\tf\\lib\\asyncio\\selector_events.py\", line 115, in _read_from_self\n",
      "    data = self._ssock.recv(4096)\n",
      "ConnectionResetError: [WinError 10054] An existing connection was forcibly closed by the remote host\n",
      "Exception in callback BaseSelectorEventLoop._read_from_self()\n",
      "handle: <Handle BaseSelectorEventLoop._read_from_self()>\n",
      "Traceback (most recent call last):\n",
      "  File \"c:\\Users\\fafaf\\anaconda3\\envs\\tf\\lib\\asyncio\\events.py\", line 80, in _run\n",
      "    self._context.run(self._callback, *self._args)\n",
      "  File \"c:\\Users\\fafaf\\anaconda3\\envs\\tf\\lib\\asyncio\\selector_events.py\", line 115, in _read_from_self\n",
      "    data = self._ssock.recv(4096)\n",
      "ConnectionResetError: [WinError 10054] An existing connection was forcibly closed by the remote host\n",
      "Exception in callback BaseSelectorEventLoop._read_from_self()\n",
      "handle: <Handle BaseSelectorEventLoop._read_from_self()>\n",
      "Traceback (most recent call last):\n",
      "  File \"c:\\Users\\fafaf\\anaconda3\\envs\\tf\\lib\\asyncio\\events.py\", line 80, in _run\n",
      "    self._context.run(self._callback, *self._args)\n",
      "  File \"c:\\Users\\fafaf\\anaconda3\\envs\\tf\\lib\\asyncio\\selector_events.py\", line 115, in _read_from_self\n",
      "    data = self._ssock.recv(4096)\n",
      "ConnectionResetError: [WinError 10054] An existing connection was forcibly closed by the remote host\n",
      "Exception in callback BaseSelectorEventLoop._read_from_self()\n",
      "handle: <Handle BaseSelectorEventLoop._read_from_self()>\n",
      "Traceback (most recent call last):\n",
      "  File \"c:\\Users\\fafaf\\anaconda3\\envs\\tf\\lib\\asyncio\\events.py\", line 80, in _run\n",
      "    self._context.run(self._callback, *self._args)\n",
      "  File \"c:\\Users\\fafaf\\anaconda3\\envs\\tf\\lib\\asyncio\\selector_events.py\", line 115, in _read_from_self\n",
      "    data = self._ssock.recv(4096)\n",
      "ConnectionResetError: [WinError 10054] An existing connection was forcibly closed by the remote host\n",
      "Exception in callback BaseSelectorEventLoop._read_from_self()\n",
      "handle: <Handle BaseSelectorEventLoop._read_from_self()>\n",
      "Traceback (most recent call last):\n",
      "  File \"c:\\Users\\fafaf\\anaconda3\\envs\\tf\\lib\\asyncio\\events.py\", line 80, in _run\n",
      "    self._context.run(self._callback, *self._args)\n",
      "  File \"c:\\Users\\fafaf\\anaconda3\\envs\\tf\\lib\\asyncio\\selector_events.py\", line 115, in _read_from_self\n",
      "    data = self._ssock.recv(4096)\n",
      "ConnectionResetError: [WinError 10054] An existing connection was forcibly closed by the remote host\n",
      "Exception in callback BaseSelectorEventLoop._read_from_self()\n",
      "handle: <Handle BaseSelectorEventLoop._read_from_self()>\n",
      "Traceback (most recent call last):\n",
      "  File \"c:\\Users\\fafaf\\anaconda3\\envs\\tf\\lib\\asyncio\\events.py\", line 80, in _run\n",
      "    self._context.run(self._callback, *self._args)\n",
      "  File \"c:\\Users\\fafaf\\anaconda3\\envs\\tf\\lib\\asyncio\\selector_events.py\", line 115, in _read_from_self\n",
      "    data = self._ssock.recv(4096)\n",
      "ConnectionResetError: [WinError 10054] An existing connection was forcibly closed by the remote host\n",
      "Exception in callback BaseSelectorEventLoop._read_from_self()\n",
      "handle: <Handle BaseSelectorEventLoop._read_from_self()>\n",
      "Traceback (most recent call last):\n",
      "  File \"c:\\Users\\fafaf\\anaconda3\\envs\\tf\\lib\\asyncio\\events.py\", line 80, in _run\n",
      "    self._context.run(self._callback, *self._args)\n",
      "  File \"c:\\Users\\fafaf\\anaconda3\\envs\\tf\\lib\\asyncio\\selector_events.py\", line 115, in _read_from_self\n",
      "    data = self._ssock.recv(4096)\n",
      "ConnectionResetError: [WinError 10054] An existing connection was forcibly closed by the remote host\n",
      "Exception in callback BaseSelectorEventLoop._read_from_self()\n",
      "handle: <Handle BaseSelectorEventLoop._read_from_self()>\n",
      "Traceback (most recent call last):\n",
      "  File \"c:\\Users\\fafaf\\anaconda3\\envs\\tf\\lib\\asyncio\\events.py\", line 80, in _run\n",
      "    self._context.run(self._callback, *self._args)\n",
      "  File \"c:\\Users\\fafaf\\anaconda3\\envs\\tf\\lib\\asyncio\\selector_events.py\", line 115, in _read_from_self\n",
      "    data = self._ssock.recv(4096)\n",
      "ConnectionResetError: [WinError 10054] An existing connection was forcibly closed by the remote host\n",
      "Exception in callback BaseSelectorEventLoop._read_from_self()\n",
      "handle: <Handle BaseSelectorEventLoop._read_from_self()>\n",
      "Traceback (most recent call last):\n",
      "  File \"c:\\Users\\fafaf\\anaconda3\\envs\\tf\\lib\\asyncio\\events.py\", line 80, in _run\n",
      "    self._context.run(self._callback, *self._args)\n",
      "  File \"c:\\Users\\fafaf\\anaconda3\\envs\\tf\\lib\\asyncio\\selector_events.py\", line 115, in _read_from_self\n",
      "    data = self._ssock.recv(4096)\n",
      "ConnectionResetError: [WinError 10054] An existing connection was forcibly closed by the remote host\n",
      "Exception in callback BaseSelectorEventLoop._read_from_self()\n",
      "handle: <Handle BaseSelectorEventLoop._read_from_self()>\n",
      "Traceback (most recent call last):\n",
      "  File \"c:\\Users\\fafaf\\anaconda3\\envs\\tf\\lib\\asyncio\\events.py\", line 80, in _run\n",
      "    self._context.run(self._callback, *self._args)\n",
      "  File \"c:\\Users\\fafaf\\anaconda3\\envs\\tf\\lib\\asyncio\\selector_events.py\", line 115, in _read_from_self\n",
      "    data = self._ssock.recv(4096)\n",
      "ConnectionResetError: [WinError 10054] An existing connection was forcibly closed by the remote host\n",
      "Exception in callback BaseSelectorEventLoop._read_from_self()\n",
      "handle: <Handle BaseSelectorEventLoop._read_from_self()>\n",
      "Traceback (most recent call last):\n",
      "  File \"c:\\Users\\fafaf\\anaconda3\\envs\\tf\\lib\\asyncio\\events.py\", line 80, in _run\n",
      "    self._context.run(self._callback, *self._args)\n",
      "  File \"c:\\Users\\fafaf\\anaconda3\\envs\\tf\\lib\\asyncio\\selector_events.py\", line 115, in _read_from_self\n",
      "    data = self._ssock.recv(4096)\n",
      "ConnectionResetError: [WinError 10054] An existing connection was forcibly closed by the remote host\n",
      "Exception in callback BaseSelectorEventLoop._read_from_self()\n",
      "handle: <Handle BaseSelectorEventLoop._read_from_self()>\n",
      "Traceback (most recent call last):\n",
      "  File \"c:\\Users\\fafaf\\anaconda3\\envs\\tf\\lib\\asyncio\\events.py\", line 80, in _run\n",
      "    self._context.run(self._callback, *self._args)\n",
      "  File \"c:\\Users\\fafaf\\anaconda3\\envs\\tf\\lib\\asyncio\\selector_events.py\", line 115, in _read_from_self\n",
      "    data = self._ssock.recv(4096)\n",
      "ConnectionResetError: [WinError 10054] An existing connection was forcibly closed by the remote host\n",
      "Exception in callback BaseSelectorEventLoop._read_from_self()\n",
      "handle: <Handle BaseSelectorEventLoop._read_from_self()>\n",
      "Traceback (most recent call last):\n",
      "  File \"c:\\Users\\fafaf\\anaconda3\\envs\\tf\\lib\\asyncio\\events.py\", line 80, in _run\n",
      "    self._context.run(self._callback, *self._args)\n",
      "  File \"c:\\Users\\fafaf\\anaconda3\\envs\\tf\\lib\\asyncio\\selector_events.py\", line 115, in _read_from_self\n",
      "    data = self._ssock.recv(4096)\n",
      "ConnectionResetError: [WinError 10054] An existing connection was forcibly closed by the remote host\n",
      "Exception in callback BaseSelectorEventLoop._read_from_self()\n",
      "handle: <Handle BaseSelectorEventLoop._read_from_self()>\n",
      "Traceback (most recent call last):\n",
      "  File \"c:\\Users\\fafaf\\anaconda3\\envs\\tf\\lib\\asyncio\\events.py\", line 80, in _run\n",
      "    self._context.run(self._callback, *self._args)\n",
      "  File \"c:\\Users\\fafaf\\anaconda3\\envs\\tf\\lib\\asyncio\\selector_events.py\", line 115, in _read_from_self\n",
      "    data = self._ssock.recv(4096)\n",
      "ConnectionResetError: [WinError 10054] An existing connection was forcibly closed by the remote host\n",
      "Exception in callback BaseSelectorEventLoop._read_from_self()\n",
      "handle: <Handle BaseSelectorEventLoop._read_from_self()>\n",
      "Traceback (most recent call last):\n",
      "  File \"c:\\Users\\fafaf\\anaconda3\\envs\\tf\\lib\\asyncio\\events.py\", line 80, in _run\n",
      "    self._context.run(self._callback, *self._args)\n",
      "  File \"c:\\Users\\fafaf\\anaconda3\\envs\\tf\\lib\\asyncio\\selector_events.py\", line 115, in _read_from_self\n",
      "    data = self._ssock.recv(4096)\n",
      "ConnectionResetError: [WinError 10054] An existing connection was forcibly closed by the remote host\n",
      "Exception in callback BaseSelectorEventLoop._read_from_self()\n",
      "handle: <Handle BaseSelectorEventLoop._read_from_self()>\n",
      "Traceback (most recent call last):\n",
      "  File \"c:\\Users\\fafaf\\anaconda3\\envs\\tf\\lib\\asyncio\\events.py\", line 80, in _run\n",
      "    self._context.run(self._callback, *self._args)\n",
      "  File \"c:\\Users\\fafaf\\anaconda3\\envs\\tf\\lib\\asyncio\\selector_events.py\", line 115, in _read_from_self\n",
      "    data = self._ssock.recv(4096)\n",
      "ConnectionResetError: [WinError 10054] An existing connection was forcibly closed by the remote host\n",
      "Exception in callback BaseSelectorEventLoop._read_from_self()\n",
      "handle: <Handle BaseSelectorEventLoop._read_from_self()>\n",
      "Traceback (most recent call last):\n",
      "  File \"c:\\Users\\fafaf\\anaconda3\\envs\\tf\\lib\\asyncio\\events.py\", line 80, in _run\n",
      "    self._context.run(self._callback, *self._args)\n",
      "  File \"c:\\Users\\fafaf\\anaconda3\\envs\\tf\\lib\\asyncio\\selector_events.py\", line 115, in _read_from_self\n",
      "    data = self._ssock.recv(4096)\n",
      "ConnectionResetError: [WinError 10054] An existing connection was forcibly closed by the remote host\n",
      "Exception in callback BaseSelectorEventLoop._read_from_self()\n",
      "handle: <Handle BaseSelectorEventLoop._read_from_self()>\n",
      "Traceback (most recent call last):\n",
      "  File \"c:\\Users\\fafaf\\anaconda3\\envs\\tf\\lib\\asyncio\\events.py\", line 80, in _run\n",
      "    self._context.run(self._callback, *self._args)\n",
      "  File \"c:\\Users\\fafaf\\anaconda3\\envs\\tf\\lib\\asyncio\\selector_events.py\", line 115, in _read_from_self\n",
      "    data = self._ssock.recv(4096)\n",
      "ConnectionResetError: [WinError 10054] An existing connection was forcibly closed by the remote host\n",
      "Exception in callback BaseSelectorEventLoop._read_from_self()\n",
      "handle: <Handle BaseSelectorEventLoop._read_from_self()>\n",
      "Traceback (most recent call last):\n",
      "  File \"c:\\Users\\fafaf\\anaconda3\\envs\\tf\\lib\\asyncio\\events.py\", line 80, in _run\n",
      "    self._context.run(self._callback, *self._args)\n",
      "  File \"c:\\Users\\fafaf\\anaconda3\\envs\\tf\\lib\\asyncio\\selector_events.py\", line 115, in _read_from_self\n",
      "    data = self._ssock.recv(4096)\n",
      "ConnectionResetError: [WinError 10054] An existing connection was forcibly closed by the remote host\n",
      "Exception in callback BaseSelectorEventLoop._read_from_self()\n",
      "handle: <Handle BaseSelectorEventLoop._read_from_self()>\n",
      "Traceback (most recent call last):\n",
      "  File \"c:\\Users\\fafaf\\anaconda3\\envs\\tf\\lib\\asyncio\\events.py\", line 80, in _run\n",
      "    self._context.run(self._callback, *self._args)\n",
      "  File \"c:\\Users\\fafaf\\anaconda3\\envs\\tf\\lib\\asyncio\\selector_events.py\", line 115, in _read_from_self\n",
      "    data = self._ssock.recv(4096)\n",
      "ConnectionResetError: [WinError 10054] An existing connection was forcibly closed by the remote host\n",
      "Exception in callback BaseSelectorEventLoop._read_from_self()\n",
      "handle: <Handle BaseSelectorEventLoop._read_from_self()>\n",
      "Traceback (most recent call last):\n",
      "  File \"c:\\Users\\fafaf\\anaconda3\\envs\\tf\\lib\\asyncio\\events.py\", line 80, in _run\n",
      "    self._context.run(self._callback, *self._args)\n",
      "  File \"c:\\Users\\fafaf\\anaconda3\\envs\\tf\\lib\\asyncio\\selector_events.py\", line 115, in _read_from_self\n",
      "    data = self._ssock.recv(4096)\n",
      "ConnectionResetError: [WinError 10054] An existing connection was forcibly closed by the remote host\n",
      "Exception in callback BaseSelectorEventLoop._read_from_self()\n",
      "handle: <Handle BaseSelectorEventLoop._read_from_self()>\n",
      "Traceback (most recent call last):\n",
      "  File \"c:\\Users\\fafaf\\anaconda3\\envs\\tf\\lib\\asyncio\\events.py\", line 80, in _run\n",
      "    self._context.run(self._callback, *self._args)\n",
      "  File \"c:\\Users\\fafaf\\anaconda3\\envs\\tf\\lib\\asyncio\\selector_events.py\", line 115, in _read_from_self\n",
      "    data = self._ssock.recv(4096)\n",
      "ConnectionResetError: [WinError 10054] An existing connection was forcibly closed by the remote host\n",
      "Exception in callback BaseSelectorEventLoop._read_from_self()\n",
      "handle: <Handle BaseSelectorEventLoop._read_from_self()>\n",
      "Traceback (most recent call last):\n",
      "  File \"c:\\Users\\fafaf\\anaconda3\\envs\\tf\\lib\\asyncio\\events.py\", line 80, in _run\n",
      "    self._context.run(self._callback, *self._args)\n",
      "  File \"c:\\Users\\fafaf\\anaconda3\\envs\\tf\\lib\\asyncio\\selector_events.py\", line 115, in _read_from_self\n",
      "    data = self._ssock.recv(4096)\n",
      "ConnectionResetError: [WinError 10054] An existing connection was forcibly closed by the remote host\n",
      "Exception in callback BaseSelectorEventLoop._read_from_self()\n",
      "handle: <Handle BaseSelectorEventLoop._read_from_self()>\n",
      "Traceback (most recent call last):\n",
      "  File \"c:\\Users\\fafaf\\anaconda3\\envs\\tf\\lib\\asyncio\\events.py\", line 80, in _run\n",
      "    self._context.run(self._callback, *self._args)\n",
      "  File \"c:\\Users\\fafaf\\anaconda3\\envs\\tf\\lib\\asyncio\\selector_events.py\", line 115, in _read_from_self\n",
      "    data = self._ssock.recv(4096)\n",
      "ConnectionResetError: [WinError 10054] An existing connection was forcibly closed by the remote host\n",
      "Exception in callback BaseSelectorEventLoop._read_from_self()\n",
      "handle: <Handle BaseSelectorEventLoop._read_from_self()>\n",
      "Traceback (most recent call last):\n",
      "  File \"c:\\Users\\fafaf\\anaconda3\\envs\\tf\\lib\\asyncio\\events.py\", line 80, in _run\n",
      "    self._context.run(self._callback, *self._args)\n",
      "  File \"c:\\Users\\fafaf\\anaconda3\\envs\\tf\\lib\\asyncio\\selector_events.py\", line 115, in _read_from_self\n",
      "    data = self._ssock.recv(4096)\n",
      "ConnectionResetError: [WinError 10054] An existing connection was forcibly closed by the remote host\n",
      "Exception in callback BaseSelectorEventLoop._read_from_self()\n",
      "handle: <Handle BaseSelectorEventLoop._read_from_self()>\n",
      "Traceback (most recent call last):\n",
      "  File \"c:\\Users\\fafaf\\anaconda3\\envs\\tf\\lib\\asyncio\\events.py\", line 80, in _run\n",
      "    self._context.run(self._callback, *self._args)\n",
      "  File \"c:\\Users\\fafaf\\anaconda3\\envs\\tf\\lib\\asyncio\\selector_events.py\", line 115, in _read_from_self\n",
      "    data = self._ssock.recv(4096)\n",
      "ConnectionResetError: [WinError 10054] An existing connection was forcibly closed by the remote host\n",
      "Exception in callback BaseSelectorEventLoop._read_from_self()\n",
      "handle: <Handle BaseSelectorEventLoop._read_from_self()>\n",
      "Traceback (most recent call last):\n",
      "  File \"c:\\Users\\fafaf\\anaconda3\\envs\\tf\\lib\\asyncio\\events.py\", line 80, in _run\n",
      "    self._context.run(self._callback, *self._args)\n",
      "  File \"c:\\Users\\fafaf\\anaconda3\\envs\\tf\\lib\\asyncio\\selector_events.py\", line 115, in _read_from_self\n",
      "    data = self._ssock.recv(4096)\n",
      "ConnectionResetError: [WinError 10054] An existing connection was forcibly closed by the remote host\n",
      "Exception in callback BaseSelectorEventLoop._read_from_self()\n",
      "handle: <Handle BaseSelectorEventLoop._read_from_self()>\n",
      "Traceback (most recent call last):\n",
      "  File \"c:\\Users\\fafaf\\anaconda3\\envs\\tf\\lib\\asyncio\\events.py\", line 80, in _run\n",
      "    self._context.run(self._callback, *self._args)\n",
      "  File \"c:\\Users\\fafaf\\anaconda3\\envs\\tf\\lib\\asyncio\\selector_events.py\", line 115, in _read_from_self\n",
      "    data = self._ssock.recv(4096)\n",
      "ConnectionResetError: [WinError 10054] An existing connection was forcibly closed by the remote host\n",
      "Exception in callback BaseSelectorEventLoop._read_from_self()\n",
      "handle: <Handle BaseSelectorEventLoop._read_from_self()>\n",
      "Traceback (most recent call last):\n",
      "  File \"c:\\Users\\fafaf\\anaconda3\\envs\\tf\\lib\\asyncio\\events.py\", line 80, in _run\n",
      "    self._context.run(self._callback, *self._args)\n",
      "  File \"c:\\Users\\fafaf\\anaconda3\\envs\\tf\\lib\\asyncio\\selector_events.py\", line 115, in _read_from_self\n",
      "    data = self._ssock.recv(4096)\n",
      "ConnectionResetError: [WinError 10054] An existing connection was forcibly closed by the remote host\n",
      "Exception in callback BaseSelectorEventLoop._read_from_self()\n",
      "handle: <Handle BaseSelectorEventLoop._read_from_self()>\n",
      "Traceback (most recent call last):\n",
      "  File \"c:\\Users\\fafaf\\anaconda3\\envs\\tf\\lib\\asyncio\\events.py\", line 80, in _run\n",
      "    self._context.run(self._callback, *self._args)\n",
      "  File \"c:\\Users\\fafaf\\anaconda3\\envs\\tf\\lib\\asyncio\\selector_events.py\", line 115, in _read_from_self\n",
      "    data = self._ssock.recv(4096)\n",
      "ConnectionResetError: [WinError 10054] An existing connection was forcibly closed by the remote host\n",
      "Exception in callback BaseSelectorEventLoop._read_from_self()\n",
      "handle: <Handle BaseSelectorEventLoop._read_from_self()>\n",
      "Traceback (most recent call last):\n",
      "  File \"c:\\Users\\fafaf\\anaconda3\\envs\\tf\\lib\\asyncio\\events.py\", line 80, in _run\n",
      "    self._context.run(self._callback, *self._args)\n",
      "  File \"c:\\Users\\fafaf\\anaconda3\\envs\\tf\\lib\\asyncio\\selector_events.py\", line 115, in _read_from_self\n",
      "    data = self._ssock.recv(4096)\n",
      "ConnectionResetError: [WinError 10054] An existing connection was forcibly closed by the remote host\n",
      "Exception in callback BaseSelectorEventLoop._read_from_self()\n",
      "handle: <Handle BaseSelectorEventLoop._read_from_self()>\n",
      "Traceback (most recent call last):\n",
      "  File \"c:\\Users\\fafaf\\anaconda3\\envs\\tf\\lib\\asyncio\\events.py\", line 80, in _run\n",
      "    self._context.run(self._callback, *self._args)\n",
      "  File \"c:\\Users\\fafaf\\anaconda3\\envs\\tf\\lib\\asyncio\\selector_events.py\", line 115, in _read_from_self\n",
      "    data = self._ssock.recv(4096)\n",
      "ConnectionResetError: [WinError 10054] An existing connection was forcibly closed by the remote host\n",
      "Exception in callback BaseSelectorEventLoop._read_from_self()\n",
      "handle: <Handle BaseSelectorEventLoop._read_from_self()>\n",
      "Traceback (most recent call last):\n",
      "  File \"c:\\Users\\fafaf\\anaconda3\\envs\\tf\\lib\\asyncio\\events.py\", line 80, in _run\n",
      "    self._context.run(self._callback, *self._args)\n",
      "  File \"c:\\Users\\fafaf\\anaconda3\\envs\\tf\\lib\\asyncio\\selector_events.py\", line 115, in _read_from_self\n",
      "    data = self._ssock.recv(4096)\n",
      "ConnectionResetError: [WinError 10054] An existing connection was forcibly closed by the remote host\n",
      "Exception in callback BaseSelectorEventLoop._read_from_self()\n",
      "handle: <Handle BaseSelectorEventLoop._read_from_self()>\n",
      "Traceback (most recent call last):\n",
      "  File \"c:\\Users\\fafaf\\anaconda3\\envs\\tf\\lib\\asyncio\\events.py\", line 80, in _run\n",
      "    self._context.run(self._callback, *self._args)\n",
      "  File \"c:\\Users\\fafaf\\anaconda3\\envs\\tf\\lib\\asyncio\\selector_events.py\", line 115, in _read_from_self\n",
      "    data = self._ssock.recv(4096)\n",
      "ConnectionResetError: [WinError 10054] An existing connection was forcibly closed by the remote host\n"
     ]
    }
   ],
   "source": [
    "import argparse\n",
    "import warnings\n",
    "from typing import Union\n",
    "from logging import INFO\n",
    "from datasets import Dataset, DatasetDict\n",
    "import xgboost as xgb\n",
    "\n",
    "import flwr as fl\n",
    "from flwr_datasets import FederatedDataset\n",
    "from flwr.common.logger import log\n",
    "from flwr.common import (\n",
    "    Code,\n",
    "    EvaluateIns,\n",
    "    EvaluateRes,\n",
    "    FitIns,\n",
    "    FitRes,\n",
    "    GetParametersIns,\n",
    "    GetParametersRes,\n",
    "    Parameters,\n",
    "    Status,\n",
    ")\n",
    "from flwr_datasets.partitioner import IidPartitioner\n",
    "\n",
    "\n",
    "warnings.filterwarnings(\"ignore\", category=UserWarning)\n",
    "\n",
    "num_train = 339\n",
    "num_val = 85\n",
    "\n",
    "\n",
    "xgb_train = xgb.DMatrix(X_train, y_train, enable_categorical=True)\n",
    "xgb_test = xgb.DMatrix(X_test, y_test, enable_categorical=True)\n",
    "\n",
    "# Reformat data to DMatrix for xgboost\n",
    "log(INFO, \"Reformatting data...\")\n",
    "train_dmatrix = xgb_train\n",
    "valid_dmatrix = xgb_test\n",
    "\n",
    "from sklearn import metrics\n",
    "from sklearn.metrics import confusion_matrix, classification_report\n",
    "\n",
    "\n",
    "# Hyper-parameters for xgboost training\n",
    "num_local_round = 1\n",
    "params = {\n",
    "    \"objective\": \"binary:logistic\",\n",
    "    # \"eta\": 0.5,  # Learning rate\n",
    "    # \"max_depth\": 8,\n",
    "    # \"eval_metric\": \"error\",\n",
    "    # \"nthread\": 16,\n",
    "    # \"num_parallel_tree\": 1,\n",
    "    # \"subsample\": 1,\n",
    "    # \"tree_method\": \"hist\",\n",
    "}\n",
    "\n",
    "\n",
    "# Define Flower client\n",
    "class XgbClient(fl.client.Client):\n",
    "    def __init__(self):\n",
    "        self.bst = None\n",
    "        self.config = None\n",
    "\n",
    "    def get_parameters(self, ins: GetParametersIns) -> GetParametersRes:\n",
    "        _ = (self, ins)\n",
    "        return GetParametersRes(\n",
    "            status=Status(\n",
    "                code=Code.OK,\n",
    "                message=\"OK\",\n",
    "            ),\n",
    "            parameters=Parameters(tensor_type=\"\", tensors=[]),\n",
    "        )\n",
    "\n",
    "    def _local_boost(self):\n",
    "        # Update trees based on local training data.\n",
    "        for i in range(num_local_round):\n",
    "            self.bst.update(train_dmatrix, self.bst.num_boosted_rounds())\n",
    "\n",
    "        # Extract the last N=num_local_round trees for sever aggregation\n",
    "        bst = self.bst[\n",
    "            self.bst.num_boosted_rounds()\n",
    "            - num_local_round : self.bst.num_boosted_rounds()\n",
    "        ]\n",
    "\n",
    "        return bst\n",
    "\n",
    "    def fit(self, ins: FitIns) -> FitRes:\n",
    "        if not self.bst:\n",
    "            # First round local training\n",
    "            log(INFO, \"Start training at round 1\")\n",
    "            bst = xgb.train(\n",
    "                params,\n",
    "                train_dmatrix,\n",
    "                num_boost_round=num_local_round,\n",
    "                evals=[(valid_dmatrix, \"validate\"), (train_dmatrix, \"train\")],\n",
    "            )\n",
    "            self.config = bst.save_config()\n",
    "            self.bst = bst\n",
    "        else:\n",
    "            for item in ins.parameters.tensors:\n",
    "                global_model = bytearray(item)\n",
    "\n",
    "            # Load global model into booster\n",
    "            self.bst.load_model(global_model)\n",
    "            self.bst.load_config(self.config)\n",
    "\n",
    "            bst = self._local_boost()\n",
    "\n",
    "        local_model = bst.save_raw(\"json\")\n",
    "        local_model_bytes = bytes(local_model)\n",
    "\n",
    "        return FitRes(\n",
    "            status=Status(\n",
    "                code=Code.OK,\n",
    "                message=\"OK\",\n",
    "            ),\n",
    "            parameters=Parameters(tensor_type=\"\", tensors=[local_model_bytes]),\n",
    "            num_examples=num_train,\n",
    "            metrics={},\n",
    "        )\n",
    "\n",
    "    def evaluate(self, ins: EvaluateIns) -> EvaluateRes:\n",
    "        eval_results = self.bst.eval_set(\n",
    "            evals=[(valid_dmatrix, \"valid\")],\n",
    "            iteration=self.bst.num_boosted_rounds() - 1,\n",
    "        )\n",
    "        auc = round(float(eval_results.split(\"\\t\")[1].split(\":\")[1]), 4)\n",
    "        \n",
    "        preds = self.bst.predict(valid_dmatrix)\n",
    "        y_pred = np.multiply(preds,100)\n",
    "        y_pred = y_pred.astype(int)\n",
    "        a = [1 if i >= 50 else 0 for i in y_pred]\n",
    "        print(\"Confusion Matrix: \\n\", confusion_matrix(y_test, a))\n",
    "        print(metrics.classification_report(y_test,a))\n",
    "        \n",
    "\n",
    "        return EvaluateRes(\n",
    "            status=Status(\n",
    "                code=Code.OK,\n",
    "                message=\"OK\",\n",
    "            ),\n",
    "            loss=0.0,\n",
    "            num_examples=num_val,\n",
    "            metrics={\"error\": auc},\n",
    "        )\n",
    "\n",
    "\n",
    "# Start Flower client\n",
    "fl.client.start_client(server_address=\"127.0.0.1:8080\", client=XgbClient().to_client())"
   ]
  },
  {
   "cell_type": "code",
   "execution_count": 11,
   "metadata": {},
   "outputs": [
    {
     "name": "stdout",
     "output_type": "stream",
     "text": [
      "\n"
     ]
    }
   ],
   "source": [
    "from xgboost import XGBClassifier \n",
    "params = {\n",
    "    \"objective\": \"binary:logistic\",\n",
    "    \"eta\": 0.5,  # Learning rate\n",
    "    \"max_depth\": 8,\n",
    "    \"eval_metric\": \"error\",\n",
    "    \"nthread\": 16,\n",
    "    \"num_parallel_tree\": 1,\n",
    "    \"subsample\": 1,\n",
    "    \"tree_method\": \"hist\",\n",
    "}\n",
    "xgb = XGBClassifier(objective = 'binary:logistic')\n",
    "\n",
    "xgb.fit(X_train, y_train)\n",
    "print()"
   ]
  },
  {
   "cell_type": "code",
   "execution_count": 8,
   "metadata": {},
   "outputs": [],
   "source": [
    "y_pred = xgb.predict(X_test)"
   ]
  },
  {
   "cell_type": "code",
   "execution_count": 9,
   "metadata": {},
   "outputs": [
    {
     "name": "stdout",
     "output_type": "stream",
     "text": [
      "1.0\n",
      "0.9764705882352941\n"
     ]
    }
   ],
   "source": [
    "# accuracy score\n",
    "from sklearn.metrics import accuracy_score, confusion_matrix, classification_report\n",
    "print(accuracy_score(y_train, xgb.predict(X_train)))\n",
    "\n",
    "xgb_acc = accuracy_score(y_test, y_pred)\n",
    "print(xgb_acc)"
   ]
  },
  {
   "cell_type": "code",
   "execution_count": 10,
   "metadata": {},
   "outputs": [
    {
     "name": "stdout",
     "output_type": "stream",
     "text": [
      "Confusion Matrix: \n",
      " [[52  2]\n",
      " [ 0 31]]\n",
      "              precision    recall  f1-score   support\n",
      "\n",
      "           0       1.00      0.96      0.98        54\n",
      "           1       0.94      1.00      0.97        31\n",
      "\n",
      "    accuracy                           0.98        85\n",
      "   macro avg       0.97      0.98      0.97        85\n",
      "weighted avg       0.98      0.98      0.98        85\n",
      "\n"
     ]
    }
   ],
   "source": [
    "print(\"Confusion Matrix: \\n\", confusion_matrix(y_test, y_pred))\n",
    "print(metrics.classification_report(y_test,y_pred))"
   ]
  }
 ],
 "metadata": {
  "kernelspec": {
   "display_name": "tf",
   "language": "python",
   "name": "python3"
  },
  "language_info": {
   "codemirror_mode": {
    "name": "ipython",
    "version": 3
   },
   "file_extension": ".py",
   "mimetype": "text/x-python",
   "name": "python",
   "nbconvert_exporter": "python",
   "pygments_lexer": "ipython3",
   "version": "3.9.17"
  }
 },
 "nbformat": 4,
 "nbformat_minor": 2
}
